File: EXPERIMENTAL/COMPRESSION/100mm_min.txt
"Specimen",1
"Specimen label",""
"Width",10.000000,"mm"
"Thickness",1.000000,"mm"
"Anvil height",100.000000,"mm"
"Diameter",10.000000,"mm"
"Inner diameter",8.000000,"mm"
"Outer diameter",10.000000,"mm"
"Wall thickness",1.000000,"mm"
"Area",0.100000,"cm^2"
"Linear density",100.000000,"tex"
"Sled weight",10.000000,"N"
"Loading span",10.000000,"mm"
"Support span",100.000000,"mm"
"Span ratio","2"
"Fixture type","4-point"
"Included"
"Final width",10.000000,"mm"
"Final thickness",1.000000,"mm"
"Final anvil height",100.000000,"mm"
"Final diameter",10.000000,"mm"
"Final Inner diameter",8.000000,"mm"
"Final outer diameter",10.000000,"mm"
"Final wall thickness",1.000000,"mm"
"Final area",0.100000,"cm^2"
"Final linear density",100.000000,"tex"
"Custom text input  1",""
"Custom text input  2",""
"Custom text input  3",""
"Custom text input  4",""
"Custom text input  5",""
"Custom text input  6",""
"Custom text input  7",""
"Custom text input  8",""
"Custom text input  9",""
"Custom text input 10",""
"Custom text input 11",""
"Custom text input 12",""
"Custom text input 13",""
"Custom text input 14",""
"Custom text input 15",""
"Custom text input 16",""
"Custom text input 17",""
"Custom text input 18",""
"Custom text input 19",""
"Custom text input 20",""
"Custom text input 21",""
"Custom text input 22",""
"Custom text input 23",""
"Custom text input 24",""
"Custom text input 25",""
"Custom text input 26",""
"Custom text input 27",""
"Custom text input 28",""
"Custom text input 29",""
"Custom text input 30",""
"Custom text input 31",""
"Custom text input 32",""
"Custom text input 33",""
"Custom text input 34",""
"Custom text input 35",""
"Custom text input 36",""
"Custom text input 37",""
"Custom text input 38",""
"Custom text input 39",""
"Custom text input 40",""
"Custom text input 41",""
"Custom text input 42",""
"Custom text input 43",""
"Custom text input 44",""
"Custom text input 45",""
"Custom text input 46",""
"Custom text input 47",""
"Custom text input 48",""
"Custom text input 49",""
"Custom text input 50",""
"Custom number input  1",0.000000,""
"Custom number input  2",0.000000,""
"Custom number input  3",0.000000,""
"Custom number input  4",0.000000,""
"Custom number input  5",0.000000,""
"Custom number input  6",0.000000,""
"Custom number input  7",0.000000,""
"Custom number input  8",0.000000,""
"Custom number input  9",0.000000,""
"Custom number input 10",0.000000,""
"Time sec","Extension mm","Load N","Compressive stress MPa","Cycle Count ","Total Cycle Count ","Repetitions Count ","Marked Data ","PIP Count ","Compressive extension mm","Compressive strain %","Compressive load N","True strain %","Corrected Position mm","True stress Pa"
"Specimen",1
"Specimen label",""
"Width",10.000000,"mm"
"Thickness",1.000000,"mm"
"Anvil height",100.000000,"mm"
"Diameter",10.000000,"mm"
"Inner diameter",8.000000,"mm"
"Outer diameter",10.000000,"mm"
"Wall thickness",1.000000,"mm"
"Area",0.100000,"cm^2"
"Linear density",100.000000,"tex"
"Sled weight",10.000000,"N"
"Loading span",10.000000,"mm"
"Support span",100.000000,"mm"
"Span ratio","2"
"Fixture type","4-point"
"Included"
"Final width",10.000000,"mm"
"Final thickness",1.000000,"mm"
"Final anvil height",100.000000,"mm"
"Final diameter",10.000000,"mm"
"Final Inner diameter",8.000000,"mm"
"Final outer diameter",10.000000,"mm"
"Final wall thickness",1.000000,"mm"
"Final area",0.100000,"cm^2"
"Final linear density",100.000000,"tex"
"Custom text input  1",""
"Custom text input  2",""
"Custom text input  3",""
"Custom text input  4",""
"Custom text input  5",""
"Custom text input  6",""
"Custom text input  7",""
"Custom text input  8",""
"Custom text input  9",""
"Custom text input 10",""
"Custom text input 11",""
"Custom text input 12",""
"Custom text input 13",""
"Custom text input 14",""
"Custom text input 15",""
"Custom text input 16",""
"Custom text input 17",""
"Custom text input 18",""
"Custom text input 19",""
"Custom text input 20",""
"Custom text input 21",""
"Custom text input 22",""
"Custom text input 23",""
"Custom text input 24",""
"Custom text input 25",""
"Custom text input 26",""
"Custom text input 27",""
"Custom text input 28",""
"Custom text input 29",""
"Custom text input 30",""
"Custom text input 31",""
"Custom text input 32",""
"Custom text input 33",""
"Custom text input 34",""
"Custom text input 35",""
"Custom text input 36",""
"Custom text input 37",""
"Custom text input 38",""
"Custom text input 39",""
"Custom text input 40",""
"Custom text input 41",""
"Custom text input 42",""
"Custom text input 43",""
"Custom text input 44",""
"Custom text input 45",""
"Custom text input 46",""
"Custom text input 47",""
"Custom text input 48",""
"Custom text input 49",""
"Custom text input 50",""
"Custom number input  1",0.000000,""
"Custom number input  2",0.000000,""
"Custom number input  3",0.000000,""
"Custom number input  4",0.000000,""
"Custom number input  5",0.000000,""
"Custom number input  6",0.000000,""
"Custom number input  7",0.000000,""
"Custom number input  8",0.000000,""
"Custom number input  9",0.000000,""
"Custom number input 10",0.000000,""
"Time sec","Extension mm","Load N","Compressive stress MPa","Cycle Count ","Total Cycle Count ","Repetitions Count ","Marked Data ","PIP Count ","Compressive extension mm","Compressive strain %","Compressive load N","True strain %","Corrected Position mm","True stress Pa"
0,-1.7544,-0.6574839,0.06574839,0,0,0,0,0,1.7544,1.7544,0.6574839,1.769972,-1.7544,64594.9
0.015,-1.769025,-3.191613,0.3191613,0,0,0,0,0,1.769025,1.769025,3.191613,1.784859,-1.769025,313515.2
0.027,-1.779075,-5.806424,0.5806423,0,0,0,0,0,1.779075,1.779075,5.806424,1.795091,-1.779075,570312.3
0.039,-1.796925,-8.445606,0.8445606,0,0,0,0,0,1.796925,1.796925,8.445605,1.813266,-1.796925,829384.4
0.051,-1.81095,-11.1369,1.11369,0,0,0,0,0,1.81095,1.81095,11.1369,1.827549,-1.81095,1093522
0.063,-1.82295,-13.81779,1.381779,0,0,0,0,0,1.82295,1.82295,13.81779,1.839771,-1.82295,1356590
0.074,-1.83915,-16.32196,1.632196,0,0,0,0,0,1.83915,1.83915,16.32196,1.856273,-1.83915,1602178
0.08400001,-1.857975,-18.82438,1.882438,0,0,0,0,0,1.857975,1.857975,18.82438,1.875452,-1.857975,1847462
0.093,-1.876275,-21.43905,2.143905,0,0,0,0,0,1.876275,1.876275,21.43904,1.8941,-1.876275,2103679
0.101,-1.89225,-24.16977,2.416977,0,0,0,0,0,1.89225,1.89225,24.16977,1.910382,-1.89225,2371242
0.108,-1.905825,-26.87938,2.687938,0,0,0,0,0,1.905825,1.905825,26.87938,1.92422,-1.905825,2636710
0.114,-1.91715,-29.39937,2.939937,0,0,0,0,0,1.91715,1.91715,29.39936,1.935766,-1.91715,2883574
0.12,-1.928025,-32.04464,3.204464,0,0,0,0,0,1.928025,1.928025,32.04464,1.946854,-1.928025,3142681
0.126,-1.938675,-34.76536,3.476536,0,0,0,0,0,1.938675,1.938675,34.76535,1.957714,-1.938675,3409137
0.132,-1.94925,-37.53936,3.753936,0,0,0,0,0,1.94925,1.94925,37.53936,1.968499,-1.94925,3680762
0.138,-1.9596,-40.34971,4.034971,0,0,0,0,0,1.9596,1.9596,40.34971,1.979055,-1.9596,3955901
0.144,-1.9698,-43.1757,4.317571,0,0,0,0,0,1.9698,1.9698,43.1757,1.989459,-1.9698,4232523
0.159,-1.99545,-40.59347,4.059347,0,0,0,0,0,1.99545,1.99545,40.59347,2.015628,-1.99545,3978345
0.162,-2.0007,-37.70229,3.770229,0,0,0,0,0,2.0007,2.0007,37.70229,2.020985,-2.0007,3694798
0.165,-2.006025,-34.53921,3.453921,0,0,0,0,0,2.006025,2.006025,34.53921,2.026419,-2.006025,3384634
0.168,-2.011275,-31.3061,3.13061,0,0,0,0,0,2.011275,2.011275,31.3061,2.031777,-2.011275,3067645
0.171,-2.0166,-28.06498,2.806498,0,0,0,0,0,2.0166,2.0166,28.06498,2.037211,-2.0166,2749902
0.174,-2.021775,-24.97584,2.497584,0,0,0,0,0,2.021775,2.021775,24.97584,2.042493,-2.021775,2447089
0.177,-2.026875,-22.10051,2.210051,0,0,0,0,0,2.026875,2.026875,22.10051,2.047698,-2.026875,2165256
0.18,-2.031975,-19.45072,1.945072,0,0,0,0,0,2.031975,2.031975,19.45072,2.052904,-2.031975,1905549
0.184,-2.03865,-16.36838,1.636838,0,0,0,0,0,2.03865,2.03865,16.36838,2.059717,-2.03865,1603469
0.188,-2.0454,-13.80556,1.380556,0,0,0,0,0,2.0454,2.0454,13.80556,2.066608,-2.0454,1352318
0.193,-2.0538,-11.2945,1.12945,0,0,0,0,0,2.0538,2.0538,11.2945,2.075184,-2.0538,1106253
0.201,-2.067075,-8.713111,0.8713111,0,0,0,0,0,2.067075,2.067075,8.713111,2.088738,-2.067075,853300.5
0.269,-2.179425,-11.2135,1.12135,0,0,0,0,0,2.179425,2.179425,11.2135,2.203525,-2.179425,1096911
0.369,-2.34735,-13.49941,1.349941,0,0,0,0,0,2.34735,2.34735,13.49941,2.375339,-2.34735,1318253
0.469,-2.513325,-14.21636,1.421636,0,0,0,0,0,2.513325,2.513325,14.21636,2.545448,-2.513325,1385906
0.522,-2.6025,-11.70988,1.170988,0,0,0,0,0,2.6025,2.6025,11.70988,2.636964,-2.6025,1140513
0.6220001,-2.767575,-11.13851,1.113851,0,0,0,0,0,2.767575,2.767575,11.13851,2.806594,-2.767575,1083025
0.625,-2.772675,-11.14795,1.114795,0,0,0,0,0,2.772675,2.772675,11.14795,2.811839,-2.772675,1083885
"Specimen",2
"Specimen label",""
"Width",10.000000,"mm"
"Thickness",1.000000,"mm"
"Anvil height",100.000000,"mm"
"Diameter",10.000000,"mm"
"Inner diameter",8.000000,"mm"
"Outer diameter",10.000000,"mm"
"Wall thickness",1.000000,"mm"
"Area",0.100000,"cm^2"
"Linear density",100.000000,"tex"
"Sled weight",10.000000,"N"
"Loading span",10.000000,"mm"
"Support span",100.000000,"mm"
"Span ratio","2"
"Fixture type","4-point"
"Included"
"Final width",10.000000,"mm"
"Final thickness",1.000000,"mm"
"Final anvil height",100.000000,"mm"
"Final diameter",10.000000,"mm"
"Final Inner diameter",8.000000,"mm"
"Final outer diameter",10.000000,"mm"
"Final wall thickness",1.000000,"mm"
"Final area",0.100000,"cm^2"
"Final linear density",100.000000,"tex"
"Custom text input  1",""
"Custom text input  2",""
"Custom text input  3",""
"Custom text input  4",""
"Custom text input  5",""
"Custom text input  6",""
"Custom text input  7",""
"Custom text input  8",""
"Custom text input  9",""
"Custom text input 10",""
"Custom text input 11",""
"Custom text input 12",""
"Custom text input 13",""
"Custom text input 14",""
"Custom text input 15",""
"Custom text input 16",""
"Custom text input 17",""
"Custom text input 18",""
"Custom text input 19",""
"Custom text input 20",""
"Custom text input 21",""
"Custom text input 22",""
"Custom text input 23",""
"Custom text input 24",""
"Custom text input 25",""
"Custom text input 26",""
"Custom text input 27",""
"Custom text input 28",""
"Custom text input 29",""
"Custom text input 30",""
"Custom text input 31",""
"Custom text input 32",""
"Custom text input 33",""
"Custom text input 34",""
"Custom text input 35",""
"Custom text input 36",""
"Custom text input 37",""
"Custom text input 38",""
"Custom text input 39",""
"Custom text input 40",""
"Custom text input 41",""
"Custom text input 42",""
"Custom text input 43",""
"Custom text input 44",""
"Custom text input 45",""
"Custom text input 46",""
"Custom text input 47",""
"Custom text input 48",""
"Custom text input 49",""
"Custom text input 50",""
"Custom number input  1",0.000000,""
"Custom number input  2",0.000000,""
"Custom number input  3",0.000000,""
"Custom number input  4",0.000000,""
"Custom number input  5",0.000000,""
"Custom number input  6",0.000000,""
"Custom number input  7",0.000000,""
"Custom number input  8",0.000000,""
"Custom number input  9",0.000000,""
"Custom number input 10",0.000000,""
"Time sec","Extension mm","Load N","Compressive stress MPa","Cycle Count ","Total Cycle Count ","Repetitions Count ","Marked Data ","PIP Count ","Compressive extension mm","Compressive strain %","Compressive load N","True strain %","Corrected Position mm","True stress Pa"
0,-1.780125,-0.6712228,0.06712228,0,0,0,0,0,1.780125,1.780125,0.6712228,1.79616,-1.780125,65927.42
0.014,-1.793775,-3.207237,0.3207237,0,0,0,0,0,1.793775,1.793775,3.207237,1.810058,-1.793775,314970.6
0.025,-1.801725,-5.872615,0.5872614,0,0,0,0,0,1.801725,1.801725,5.872615,1.818154,-1.801725,576680.6
0.036,-1.816725,-8.594781,0.8594781,0,0,0,0,0,1.816725,1.816725,8.594781,1.83343,-1.816725,843863.8
0.046,-1.832475,-11.23868,1.123868,0,0,0,0,0,1.832475,1.832475,11.23868,1.849473,-1.832475,1103273
0.055,-1.84125,-13.80125,1.380125,0,0,0,0,0,1.84125,1.84125,13.80125,1.858412,-1.84125,1354714
0.064,-1.850175,-16.40171,1.640171,0,0,0,0,0,1.850175,1.850175,16.40171,1.867505,-1.850175,1609825
0.07300001,-1.8621,-18.94742,1.894742,0,0,0,0,0,1.8621,1.8621,18.94741,1.879655,-1.8621,1859460
0.082,-1.877775,-21.50936,2.150936,0,0,0,0,0,1.877775,1.877775,21.50936,1.895629,-1.877775,2110546
0.09100001,-1.8957,-24.23328,2.423328,0,0,0,0,0,1.8957,1.8957,24.23328,1.913899,-1.8957,2377389
0.09900001,-1.912425,-26.91496,2.691496,0,0,0,0,0,1.912425,1.912425,26.91496,1.930948,-1.912425,2640023
0.106,-1.926675,-29.50051,2.950051,0,0,0,0,0,1.926675,1.926675,29.50051,1.945477,-1.926675,2893214
0.113,-1.940325,-32.26082,3.226082,0,0,0,0,0,1.940325,1.940325,32.26082,1.959396,-1.940325,3163486
0.12,-1.95345,-35.11755,3.511755,0,0,0,0,0,1.95345,1.95345,35.11755,1.972782,-1.95345,3443155
0.127,-1.965975,-37.99519,3.799519,0,0,0,0,0,1.965975,1.965975,37.99519,1.985558,-1.965975,3724821
0.134,-1.9779,-40.84624,4.084624,0,0,0,0,0,1.9779,1.9779,40.84624,1.997722,-1.9779,4003834
0.141,-1.989525,-43.64306,4.364305,0,0,0,0,0,1.989525,1.989525,43.64306,2.009583,-1.989525,4277477
0.157,-2.016825,-40.70842,4.070841,0,0,0,0,0,2.016825,2.016825,40.70842,2.037441,-2.016825,3988740
0.161,-2.02365,-38.14875,3.814875,0,0,0,0,0,2.02365,2.02365,38.14875,2.044406,-2.02365,3737675
0.165,-2.03055,-35.5292,3.55292,0,0,0,0,0,2.03055,2.03055,35.5292,2.051449,-2.03055,3480776
0.17,-2.0391,-32.47638,3.247638,0,0,0,0,0,2.0391,2.0391,32.47638,2.060177,-2.0391,3181415
0.175,-2.04765,-29.91703,2.991703,0,0,0,0,0,2.04765,2.04765,29.91703,2.068905,-2.04765,2930444
0.182,-2.0595,-27.31162,2.731162,0,0,0,0,0,2.0595,2.0595,27.31161,2.081003,-2.0595,2674913
0.199,-2.088,-24.7055,2.47055,0,0,0,0,0,2.088,2.088,24.7055,2.110107,-2.088,2418965
0.211,-2.107725,-22.16638,2.216638,0,0,0,0,0,2.107725,2.107725,22.16638,2.130255,-2.107725,2169917
0.221,-2.12415,-19.50846,1.950846,0,0,0,0,0,2.12415,2.12415,19.50846,2.147035,-2.12415,1909407
0.233,-2.14395,-16.96097,1.696097,0,0,0,0,0,2.14395,2.14395,16.96097,2.167266,-2.14395,1659734
0.333,-2.31225,-18.30248,1.830248,0,0,0,0,0,2.31225,2.31225,18.30248,2.339402,-2.31225,1787928
0.361,-2.358675,-15.79009,1.579009,0,0,0,0,0,2.358675,2.358675,15.79009,2.386937,-2.358675,1541765
0.381,-2.3913,-13.28816,1.328816,0,0,0,0,0,2.3913,2.3913,13.28816,2.420356,-2.3913,1297040
0.459,-2.52195,-15.80974,1.580974,0,0,0,0,0,2.52195,2.52195,15.80974,2.554296,-2.52195,1541102
0.559,-2.6886,-16.15985,1.615985,0,0,0,0,0,2.6886,2.6886,16.15985,2.725404,-2.6886,1572537
0.574,-2.71335,-13.56989,1.356989,0,0,0,0,0,2.71335,2.71335,13.56989,2.750841,-2.71335,1320169
0.674,-2.880825,-12.0699,1.20699,0,0,0,0,0,2.880825,2.880825,12.0699,2.923136,-2.880825,1172218
0.725,-2.965275,-9.549111,0.9549111,0,0,0,0,0,2.965275,2.965275,9.549111,3.010128,-2.965275,926595.4
0.781,-3.057675,-7.038519,0.7038519,0,0,0,0,0,3.057675,3.057675,7.038519,3.105397,-3.057675,682330.4
0.8810001,-3.22575,-4.765444,0.4765444,0,0,0,0,0,3.22575,3.22575,4.765443,3.278924,-3.22575,461172.2
0.9810001,-3.3915,-4.826792,0.4826792,0,0,0,0,0,3.3915,3.3915,4.826792,3.450346,-3.3915,466309.1
1.081,-3.5586,-5.064078,0.5064077,0,0,0,0,0,3.5586,3.5586,5.064078,3.623462,-3.5586,488386.7
1.181,-3.7254,-5.275555,0.5275555,0,0,0,0,0,3.7254,3.7254,5.275555,3.796566,-3.7254,507901.9
1.281,-3.89205,-5.145766,0.5145766,0,0,0,0,0,3.89205,3.89205,5.145766,3.969815,-3.89205,494549
1.373,-4.045575,-5.248338,0.5248337,0,0,0,0,0,4.045575,4.045575,5.248338,4.129685,-4.045575,503601.2
"Specimen",3
"Specimen label",""
"Width",10.000000,"mm"
"Thickness",1.000000,"mm"
"Anvil height",100.000000,"mm"
"Diameter",10.000000,"mm"
"Inner diameter",8.000000,"mm"
"Outer diameter",10.000000,"mm"
"Wall thickness",1.000000,"mm"
"Area",0.100000,"cm^2"
"Linear density",100.000000,"tex"
"Sled weight",10.000000,"N"
"Loading span",10.000000,"mm"
"Support span",100.000000,"mm"
"Span ratio","2"
"Fixture type","4-point"
"Included"
"Final width",10.000000,"mm"
"Final thickness",1.000000,"mm"
"Final anvil height",100.000000,"mm"
"Final diameter",10.000000,"mm"
"Final Inner diameter",8.000000,"mm"
"Final outer diameter",10.000000,"mm"
"Final wall thickness",1.000000,"mm"
"Final area",0.100000,"cm^2"
"Final linear density",100.000000,"tex"
"Custom text input  1",""
"Custom text input  2",""
"Custom text input  3",""
"Custom text input  4",""
"Custom text input  5",""
"Custom text input  6",""
"Custom text input  7",""
"Custom text input  8",""
"Custom text input  9",""
"Custom text input 10",""
"Custom text input 11",""
"Custom text input 12",""
"Custom text input 13",""
"Custom text input 14",""
"Custom text input 15",""
"Custom text input 16",""
"Custom text input 17",""
"Custom text input 18",""
"Custom text input 19",""
"Custom text input 20",""
"Custom text input 21",""
"Custom text input 22",""
"Custom text input 23",""
"Custom text input 24",""
"Custom text input 25",""
"Custom text input 26",""
"Custom text input 27",""
"Custom text input 28",""
"Custom text input 29",""
"Custom text input 30",""
"Custom text input 31",""
"Custom text input 32",""
"Custom text input 33",""
"Custom text input 34",""
"Custom text input 35",""
"Custom text input 36",""
"Custom text input 37",""
"Custom text input 38",""
"Custom text input 39",""
"Custom text input 40",""
"Custom text input 41",""
"Custom text input 42",""
"Custom text input 43",""
"Custom text input 44",""
"Custom text input 45",""
"Custom text input 46",""
"Custom text input 47",""
"Custom text input 48",""
"Custom text input 49",""
"Custom text input 50",""
"Custom number input  1",0.000000,""
"Custom number input  2",0.000000,""
"Custom number input  3",0.000000,""
"Custom number input  4",0.000000,""
"Custom number input  5",0.000000,""
"Custom number input  6",0.000000,""
"Custom number input  7",0.000000,""
"Custom number input  8",0.000000,""
"Custom number input  9",0.000000,""
"Custom number input 10",0.000000,""
"Time sec","Extension mm","Load N","Compressive stress MPa","Cycle Count ","Total Cycle Count ","Repetitions Count ","Marked Data ","PIP Count ","Compressive extension mm","Compressive strain %","Compressive load N","True strain %","Corrected Position mm","True stress Pa"
0,-0.3474,-0.6303266,0.06303266,0,0,0,0,0,0.3474,0.3474,0.6303266,0.3480049,-0.3474,62813.68
0.015,-0.365025,-3.21345,0.3213451,0,0,0,0,0,0.365025,0.365025,3.21345,0.3656929,-0.365025,320172.1
0.026,-0.37725,-5.893134,0.5893134,0,0,0,0,0,0.37725,0.37725,5.893134,0.3779634,-0.37725,587090.2
0.036,-0.392625,-8.521207,0.8521206,0,0,0,0,0,0.392625,0.392625,8.521207,0.3933978,-0.392625,848775
0.045,-0.4095,-11.05061,1.105061,0,0,0,0,0,0.4095,0.4095,11.05061,0.4103408,-0.4095,1100536
0.054,-0.4275,-13.78871,1.378871,0,0,0,0,0,0.4275,0.4275,13.78871,0.4284164,-0.4275,1372976
0.062,-0.443475,-16.40462,1.640462,0,0,0,0,0,0.443475,0.443475,16.40462,0.4444613,-0.443475,1633187
0.07,-0.458925,-19.18336,1.918336,0,0,0,0,0,0.458925,0.458925,19.18336,0.4599813,-0.458925,1909532
0.07700001,-0.4719,-21.72858,2.172858,0,0,0,0,0,0.4719,0.4719,21.72858,0.473017,-0.4719,2162605
0.08400001,-0.48435,-24.34629,2.434629,0,0,0,0,0,0.48435,0.48435,24.34629,0.4855268,-0.48435,2422837
0.09100001,-0.4965,-26.98281,2.698281,0,0,0,0,0,0.4965,0.4965,26.98281,0.4977367,-0.4965,2684884
0.09800001,-0.508425,-29.59992,2.959992,0,0,0,0,0,0.508425,0.508425,29.59992,0.5097219,-0.508425,2944943
0.105,-0.520125,-32.19149,3.219149,0,0,0,0,0,0.520125,0.520125,32.19149,0.5214824,-0.520125,3202405
0.112,-0.531825,-34.77065,3.477065,0,0,0,0,0,0.531825,0.531825,34.77065,0.5332442,-0.531825,3458573
0.119,-0.5433,-37.34019,3.734019,0,0,0,0,0,0.5433,0.5433,37.34019,0.5447812,-0.5433,3713732
0.126,-0.55485,-39.89954,3.989954,0,0,0,0,0,0.55485,0.55485,39.89954,0.556395,-0.55485,3967815
0.133,-0.5664,-42.44487,4.244487,0,0,0,0,0,0.5664,0.5664,42.44487,0.5680101,-0.5664,4220446
0.14,-0.577875,-44.9709,4.49709,0,0,0,0,0,0.577875,0.577875,44.9709,0.5795512,-0.577875,4471102
0.16,-0.612225,-42.37012,4.237012,0,0,0,0,0,0.6122251,0.6122251,42.37012,0.6141068,-0.612225,4211072
0.164,-0.6192,-39.43518,3.943518,0,0,0,0,0,0.6192,0.6192,39.43518,0.621125,-0.6192,3919100
0.168,-0.626175,-36.44234,3.644234,0,0,0,0,0,0.626175,0.626175,36.44234,0.6281437,-0.626175,3621415
0.172,-0.633075,-33.60315,3.360315,0,0,0,0,0,0.633075,0.633075,33.60315,0.6350874,-0.633075,3339041
0.176,-0.6399,-31.0564,3.10564,0,0,0,0,0,0.6399,0.6399,31.0564,0.6419562,-0.6399,3085767
0.181,-0.64845,-28.39455,2.839455,0,0,0,0,0,0.6484501,0.6484501,28.39455,0.6505616,-0.64845,2821043
0.188,-0.6603751,-25.72383,2.572383,0,0,0,0,0,0.6603751,0.6603751,25.72383,0.6625652,-0.6603751,2555396
0.209,-0.69585,-23.19571,2.319571,0,0,0,0,0,0.69585,0.69585,23.19571,0.6982823,-0.69585,2303430
0.222,-0.717825,-20.57505,2.057505,0,0,0,0,0,0.717825,0.717825,20.57505,0.7204138,-0.717825,2042736
0.232,-0.7347,-17.95787,1.795787,0,0,0,0,0,0.7347,0.7347,17.95787,0.7374122,-0.7347,1782594
0.249,-0.763275,-15.42348,1.542348,0,0,0,0,0,0.763275,0.763275,15.42348,0.7662029,-0.763275,1530576
0.323,-0.88515,-17.94109,1.794109,0,0,0,0,0,0.8851501,0.8851501,17.94109,0.8890908,-0.88515,1778228
0.423,-1.05255,-19.24898,1.924899,0,0,0,0,0,1.05255,1.05255,19.24899,1.058129,-1.05255,1904638
0.436,-1.07445,-16.74151,1.674151,0,0,0,0,0,1.07445,1.07445,16.74151,1.080264,-1.07445,1656163
0.456,-1.108125,-14.22668,1.422668,0,0,0,0,0,1.108125,1.108125,14.22668,1.114311,-1.108125,1406903
0.5560001,-1.2744,-16.63753,1.663753,0,0,0,0,0,1.2744,1.2744,16.63753,1.28259,-1.2744,1642551
0.656,-1.440975,-17.18725,1.718725,0,0,0,0,0,1.440975,1.440975,17.18725,1.451458,-1.440975,1693959
0.7050001,-1.521375,-14.58933,1.458933,0,0,0,0,0,1.521375,1.521375,14.58933,1.533067,-1.521375,1436737
0.7370001,-1.575375,-12.06961,1.206961,0,0,0,0,0,1.575375,1.575375,12.06961,1.587916,-1.575375,1187947
0.837,-1.742625,-11.82815,1.182815,0,0,0,0,0,1.742625,1.742625,11.82815,1.757987,-1.742625,1162203
0.9370001,-1.9098,-11.05165,1.105165,0,0,0,0,0,1.9098,1.9098,11.05165,1.928272,-1.9098,1084058
1.037,-2.075025,-11.3263,1.13263,0,0,0,0,0,2.075025,2.075025,11.3263,2.096856,-2.075025,1109127
1.137,-2.24325,-11.43862,1.143862,0,0,0,0,0,2.24325,2.24325,11.43862,2.268794,-2.24325,1118203
1.237,-2.408325,-11.38536,1.138536,0,0,0,0,0,2.408325,2.408325,11.38536,2.437799,-2.408325,1111116
1.337,-2.576025,-10.36921,1.036921,0,0,0,0,0,2.576025,2.576025,10.36921,2.609786,-2.576025,1010210
1.364,-2.620875,-7.860497,0.7860497,0,0,0,0,0,2.620875,2.620875,7.860497,2.655832,-2.620875,765448.3
1.464,-2.78775,-6.599568,0.6599568,0,0,0,0,0,2.78775,2.78775,6.599568,2.827346,-2.78775,641558.8
1.564,-2.954175,-6.766438,0.6766438,0,0,0,0,0,2.954175,2.954175,6.766438,2.99869,-2.954175,656654.6
1.664,-3.1215,-5.928539,0.5928539,0,0,0,0,0,3.1215,3.1215,5.928539,3.171257,-3.1215,574347.9
1.764,-3.2868,-5.274586,0.5274587,0,0,0,0,0,3.2868,3.2868,5.274586,3.342029,-3.2868,510122.1
1.864,-3.454425,-5.392633,0.5392634,0,0,0,0,0,3.454425,3.454425,5.392633,3.515501,-3.454425,520634.9
1.925,-3.555975,-5.518705,0.5518704,0,0,0,0,0,3.555975,3.555975,5.518704,3.62074,-3.555975,532246
"Specimen",4
"Specimen label",""
"Width",10.000000,"mm"
"Thickness",1.000000,"mm"
"Anvil height",100.000000,"mm"
"Diameter",10.000000,"mm"
"Inner diameter",8.000000,"mm"
"Outer diameter",10.000000,"mm"
"Wall thickness",1.000000,"mm"
"Area",0.100000,"cm^2"
"Linear density",100.000000,"tex"
"Sled weight",10.000000,"N"
"Loading span",10.000000,"mm"
"Support span",100.000000,"mm"
"Span ratio","2"
"Fixture type","4-point"
"Included"
"Final width",10.000000,"mm"
"Final thickness",1.000000,"mm"
"Final anvil height",100.000000,"mm"
"Final diameter",10.000000,"mm"
"Final Inner diameter",8.000000,"mm"
"Final outer diameter",10.000000,"mm"
"Final wall thickness",1.000000,"mm"
"Final area",0.100000,"cm^2"
"Final linear density",100.000000,"tex"
"Custom text input  1",""
"Custom text input  2",""
"Custom text input  3",""
"Custom text input  4",""
"Custom text input  5",""
"Custom text input  6",""
"Custom text input  7",""
"Custom text input  8",""
"Custom text input  9",""
"Custom text input 10",""
"Custom text input 11",""
"Custom text input 12",""
"Custom text input 13",""
"Custom text input 14",""
"Custom text input 15",""
"Custom text input 16",""
"Custom text input 17",""
"Custom text input 18",""
"Custom text input 19",""
"Custom text input 20",""
"Custom text input 21",""
"Custom text input 22",""
"Custom text input 23",""
"Custom text input 24",""
"Custom text input 25",""
"Custom text input 26",""
"Custom text input 27",""
"Custom text input 28",""
"Custom text input 29",""
"Custom text input 30",""
"Custom text input 31",""
"Custom text input 32",""
"Custom text input 33",""
"Custom text input 34",""
"Custom text input 35",""
"Custom text input 36",""
"Custom text input 37",""
"Custom text input 38",""
"Custom text input 39",""
"Custom text input 40",""
"Custom text input 41",""
"Custom text input 42",""
"Custom text input 43",""
"Custom text input 44",""
"Custom text input 45",""
"Custom text input 46",""
"Custom text input 47",""
"Custom text input 48",""
"Custom text input 49",""
"Custom text input 50",""
"Custom number input  1",0.000000,""
"Custom number input  2",0.000000,""
"Custom number input  3",0.000000,""
"Custom number input  4",0.000000,""
"Custom number input  5",0.000000,""
"Custom number input  6",0.000000,""
"Custom number input  7",0.000000,""
"Custom number input  8",0.000000,""
"Custom number input  9",0.000000,""
"Custom number input 10",0.000000,""
"Time sec","Extension mm","Load N","Compressive stress MPa","Cycle Count ","Total Cycle Count ","Repetitions Count ","Marked Data ","PIP Count ","Compressive extension mm","Compressive strain %","Compressive load N","True strain %","Corrected Position mm","True stress Pa"
0,-1.816725,-0.6944612,0.06944612,0,0,0,0,0,1.816725,1.816725,0.6944612,1.83343,-1.816725,68184.47
0.016,-1.83465,-3.400281,0.3400281,0,0,0,0,0,1.83465,1.83465,3.400281,1.851688,-1.83465,333789.8
0.028,-1.848,-6.09839,0.609839,0,0,0,0,0,1.848,1.848,6.09839,1.865289,-1.848,598569.1
0.039,-1.8663,-8.785792,0.8785791,0,0,0,0,0,1.8663,1.8663,8.785791,1.883935,-1.8663,862182.2
0.049,-1.8861,-11.47016,1.147016,0,0,0,0,0,1.8861,1.8861,11.47016,1.904114,-1.8861,1125382
0.058,-1.904775,-14.17931,1.417931,0,0,0,0,0,1.904775,1.904775,14.17931,1.92315,-1.904775,1390923
0.066,-1.9209,-16.86162,1.686162,0,0,0,0,0,1.9209,1.9209,16.86162,1.939589,-1.9209,1653772
0.07300001,-1.93425,-19.36907,1.936907,0,0,0,0,0,1.93425,1.93425,19.36907,1.953202,-1.93425,1899443
0.08000001,-1.94685,-21.93897,2.193897,0,0,0,0,0,1.94685,1.94685,21.93897,1.966051,-1.94685,2151185
0.08700001,-1.95915,-24.49696,2.449696,0,0,0,0,0,1.95915,1.95915,24.49696,1.978596,-1.95915,2401703
0.09400001,-1.971075,-27.02156,2.702157,0,0,0,0,0,1.971075,1.971075,27.02156,1.99076,-1.971075,2648895
0.102,-1.984425,-29.84534,2.984534,0,0,0,0,0,1.984425,1.984425,29.84534,2.004379,-1.984425,2925308
0.11,-1.9977,-32.56659,3.256659,0,0,0,0,0,1.9977,1.9977,32.56659,2.017924,-1.9977,3191601
0.118,-2.0112,-35.15849,3.515849,0,0,0,0,0,2.0112,2.0112,35.15849,2.0317,-2.0112,3445138
0.127,-2.026575,-37.92682,3.792681,0,0,0,0,0,2.026575,2.026575,37.92682,2.047392,-2.026575,3715820
0.136,-2.041425,-40.64744,4.064744,0,0,0,0,0,2.041425,2.041425,40.64744,2.06255,-2.041425,3981765
0.145,-2.056125,-43.39321,4.339321,0,0,0,0,0,2.056125,2.056125,43.39321,2.077558,-2.056125,4250099
0.154,-2.071125,-46.18672,4.618671,0,0,0,0,0,2.071125,2.071125,46.18671,2.092874,-2.071125,4523013
0.172,-2.1018,-43.26719,4.326719,0,0,0,0,0,2.1018,2.1018,43.26719,2.124202,-2.1018,4235780
0.175,-2.10705,-40.18517,4.018517,0,0,0,0,0,2.10705,2.10705,40.18517,2.129565,-2.10705,3933845
0.178,-2.1123,-36.82779,3.682779,0,0,0,0,0,2.1123,2.1123,36.82779,2.134928,-2.1123,3604987
0.181,-2.11755,-33.38377,3.338377,0,0,0,0,0,2.11755,2.11755,33.38377,2.140292,-2.11755,3267685
0.184,-2.1228,-29.9471,2.99471,0,0,0,0,0,2.1228,2.1228,29.9471,2.145656,-2.1228,2931138
0.187,-2.12805,-26.66572,2.666573,0,0,0,0,0,2.12805,2.12805,26.66573,2.151019,-2.12805,2609826
0.19,-2.133225,-23.61318,2.361319,0,0,0,0,0,2.133225,2.133225,23.61318,2.156307,-2.133225,2310946
0.193,-2.1384,-20.82366,2.082366,0,0,0,0,0,2.1384,2.1384,20.82367,2.161595,-2.1384,2037837
0.197,-2.14515,-17.57062,1.757062,0,0,0,0,0,2.14515,2.14515,17.57062,2.168493,-2.14515,1719371
0.201,-2.1519,-14.85893,1.485893,0,0,0,0,0,2.1519,2.1519,14.85893,2.175391,-2.1519,1453918
0.206,-2.1603,-12.22702,1.222702,0,0,0,0,0,2.1603,2.1603,12.22702,2.183976,-2.1603,1196288
0.214,-2.1738,-9.590723,0.9590722,0,0,0,0,0,2.1738,2.1738,9.590723,2.197775,-2.1738,938223.9
0.281,-2.28555,-12.13156,1.213156,0,0,0,0,0,2.28555,2.28555,12.13156,2.312074,-2.28555,1185428
0.381,-2.451225,-14.45917,1.445917,0,0,0,0,0,2.451225,2.451225,14.45917,2.481768,-2.451225,1410474
0.481,-2.617875,-16.42394,1.642394,0,0,0,0,0,2.617875,2.617875,16.42394,2.652751,-2.617875,1599398
0.581,-2.78535,-17.36625,1.736625,0,0,0,0,0,2.78535,2.78535,17.36625,2.824877,-2.78535,1688254
0.61,-2.834175,-14.6854,1.46854,0,0,0,0,0,2.834175,2.834175,14.6854,2.875113,-2.834175,1426919
0.62,-2.850975,-12.02192,1.202192,0,0,0,0,0,2.850975,2.850975,12.02192,2.892405,-2.850975,1167918
0.632,-2.871075,-9.520516,0.9520516,0,0,0,0,0,2.871075,2.871075,9.520515,2.913097,-2.871075,924717.5
0.689,-2.96505,-7.011883,0.7011883,0,0,0,0,0,2.96505,2.96505,7.011883,3.009896,-2.96505,680397.7
0.7890001,-3.132375,-5.753137,0.5753137,0,0,0,0,0,3.132375,3.132375,5.753137,3.182483,-3.132375,557292.7
0.8890001,-3.29775,-5.418934,0.5418934,0,0,0,0,0,3.29775,3.29775,5.418934,3.353352,-3.29775,524023.1
0.989,-3.4656,-5.184367,0.5184367,0,0,0,0,0,3.4656,3.4656,5.184367,3.527077,-3.4656,500469.8
1.089,-3.631125,-5.119637,0.5119637,0,0,0,0,0,3.631125,3.631125,5.119637,3.698691,-3.631125,493373.6
1.189,-3.798825,-4.831977,0.4831977,0,0,0,0,0,3.798825,3.798825,4.831977,3.872862,-3.798825,464841.9
1.229,-3.86475,-4.902318,0.4902318,0,0,0,0,0,3.86475,3.86475,4.902318,3.941413,-3.86475,471285.6
"Specimen",5
"Specimen label",""
"Width",10.000000,"mm"
"Thickness",1.000000,"mm"
"Anvil height",100.000000,"mm"
"Diameter",10.000000,"mm"
"Inner diameter",8.000000,"mm"
"Outer diameter",10.000000,"mm"
"Wall thickness",1.000000,"mm"
"Area",0.100000,"cm^2"
"Linear density",100.000000,"tex"
"Sled weight",10.000000,"N"
"Loading span",10.000000,"mm"
"Support span",100.000000,"mm"
"Span ratio","2"
"Fixture type","4-point"
"Included"
"Final width",10.000000,"mm"
"Final thickness",1.000000,"mm"
"Final anvil height",100.000000,"mm"
"Final diameter",10.000000,"mm"
"Final Inner diameter",8.000000,"mm"
"Final outer diameter",10.000000,"mm"
"Final wall thickness",1.000000,"mm"
"Final area",0.100000,"cm^2"
"Final linear density",100.000000,"tex"
"Custom text input  1",""
"Custom text input  2",""
"Custom text input  3",""
"Custom text input  4",""
"Custom text input  5",""
"Custom text input  6",""
"Custom text input  7",""
"Custom text input  8",""
"Custom text input  9",""
"Custom text input 10",""
"Custom text input 11",""
"Custom text input 12",""
"Custom text input 13",""
"Custom text input 14",""
"Custom text input 15",""
"Custom text input 16",""
"Custom text input 17",""
"Custom text input 18",""
"Custom text input 19",""
"Custom text input 20",""
"Custom text input 21",""
"Custom text input 22",""
"Custom text input 23",""
"Custom text input 24",""
"Custom text input 25",""
"Custom text input 26",""
"Custom text input 27",""
"Custom text input 28",""
"Custom text input 29",""
"Custom text input 30",""
"Custom text input 31",""
"Custom text input 32",""
"Custom text input 33",""
"Custom text input 34",""
"Custom text input 35",""
"Custom text input 36",""
"Custom text input 37",""
"Custom text input 38",""
"Custom text input 39",""
"Custom text input 40",""
"Custom text input 41",""
"Custom text input 42",""
"Custom text input 43",""
"Custom text input 44",""
"Custom text input 45",""
"Custom text input 46",""
"Custom text input 47",""
"Custom text input 48",""
"Custom text input 49",""
"Custom text input 50",""
"Custom number input  1",0.000000,""
"Custom number input  2",0.000000,""
"Custom number input  3",0.000000,""
"Custom number input  4",0.000000,""
"Custom number input  5",0.000000,""
"Custom number input  6",0.000000,""
"Custom number input  7",0.000000,""
"Custom number input  8",0.000000,""
"Custom number input  9",0.000000,""
"Custom number input 10",0.000000,""
"Time sec","Extension mm","Load N","Compressive stress MPa","Cycle Count ","Total Cycle Count ","Repetitions Count ","Marked Data ","PIP Count ","Compressive extension mm","Compressive strain %","Compressive load N","True strain %","Corrected Position mm","True stress Pa"
0,-2.4666,-0.6482154,0.06482154,0,0,0,0,0,2.4666,2.4666,0.6482154,2.49753,-2.4666,63222.65
0.014,-2.48265,-3.281944,0.3281944,0,0,0,0,0,2.48265,2.48265,3.281944,2.513988,-2.48265,320046.4
0.024,-2.49315,-5.929947,0.5929947,0,0,0,0,0,2.49315,2.49315,5.929947,2.524755,-2.49315,578210.4
0.033,-2.506125,-8.478649,0.8478649,0,0,0,0,0,2.506125,2.506125,8.478649,2.538063,-2.506125,826616.3
0.042,-2.5221,-11.15372,1.115372,0,0,0,0,0,2.5221,2.5221,11.15372,2.55445,-2.5221,1087241
0.05,-2.537775,-13.67564,1.367564,0,0,0,0,0,2.537775,2.537775,13.67564,2.570532,-2.537775,1332858
0.058,-2.553975,-16.38576,1.638576,0,0,0,0,0,2.553975,2.553975,16.38576,2.587155,-2.553975,1596727
0.06500001,-2.568,-18.96422,1.896422,0,0,0,0,0,2.568,2.568,18.96422,2.601549,-2.568,1847722
0.07200001,-2.58135,-21.72641,2.172641,0,0,0,0,0,2.58135,2.58135,21.72641,2.615252,-2.58135,2116557
0.079,-2.5941,-24.60958,2.460958,0,0,0,0,0,2.5941,2.5941,24.60958,2.62834,-2.5941,2397118
0.085,-2.604675,-27.11945,2.711945,0,0,0,0,0,2.604675,2.604675,27.11945,2.639197,-2.604675,2641308
0.09200001,-2.61675,-30.02741,3.002741,0,0,0,0,0,2.61675,2.61675,30.02741,2.651596,-2.61675,2924167
0.09900001,-2.62875,-32.87838,3.287838,0,0,0,0,0,2.62875,2.62875,32.87838,2.66392,-2.62875,3201409
0.106,-2.64045,-35.66099,3.566099,0,0,0,0,0,2.64045,2.64045,35.66099,2.675936,-2.64045,3471938
0.113,-2.652,-38.38414,3.838414,0,0,0,0,0,2.652,2.652,38.38414,2.6878,-2.652,3736619
0.12,-2.663775,-41.05656,4.105656,0,0,0,0,0,2.663775,2.663775,41.05656,2.699897,-2.663775,3996290
0.127,-2.67555,-43.68959,4.368959,0,0,0,0,0,2.67555,2.67555,43.68959,2.711994,-2.67555,4252066
0.134,-2.68725,-46.2975,4.62975,0,0,0,0,0,2.68725,2.68725,46.2975,2.724017,-2.68725,4505337
0.141,-2.69895,-48.89464,4.889463,0,0,0,0,0,2.69895,2.69895,48.89464,2.736041,-2.69895,4757499
0.148,-2.71065,-51.4723,5.14723,0,0,0,0,0,2.71065,2.71065,51.47229,2.748066,-2.71065,5007706
0.155,-2.7225,-53.99802,5.399802,0,0,0,0,0,2.7225,2.7225,53.99802,2.760247,-2.7225,5252792
0.165,-2.740125,-50.86197,5.086197,0,0,0,0,0,2.740125,2.740125,50.86197,2.778367,-2.740125,4946829
0.168,-2.7453,-48.12485,4.812485,0,0,0,0,0,2.7453,2.7453,48.12485,2.783688,-2.7453,4680368
0.171,-2.75055,-45.03516,4.503516,0,0,0,0,0,2.75055,2.75055,45.03516,2.789086,-2.75055,4379645
0.174,-2.755875,-41.73151,4.173151,0,0,0,0,0,2.755875,2.755875,41.73151,2.794562,-2.755875,4058145
0.177,-2.761125,-38.42897,3.842897,0,0,0,0,0,2.761125,2.761125,38.42897,2.799961,-2.761125,3736790
0.18,-2.76645,-35.20755,3.520755,0,0,0,0,0,2.76645,2.76645,35.20755,2.805437,-2.76645,3423355
0.183,-2.771625,-32.15733,3.215733,0,0,0,0,0,2.771625,2.771625,32.15733,2.810759,-2.771625,3126605
0.186,-2.7768,-29.38745,2.938745,0,0,0,0,0,2.7768,2.7768,29.38745,2.816082,-2.7768,2857142
0.189,-2.781975,-26.88739,2.688739,0,0,0,0,0,2.781975,2.781975,26.88739,2.821405,-2.781975,2613939
0.193,-2.788875,-24.02659,2.402659,0,0,0,0,0,2.788875,2.788875,24.02659,2.828503,-2.788875,2335652
0.198,-2.79735,-21.22506,2.122506,0,0,0,0,0,2.79735,2.79735,21.22506,2.837221,-2.79735,2063132
0.205,-2.809125,-18.63162,1.863162,0,0,0,0,0,2.809125,2.809125,18.63162,2.849336,-2.809125,1810824
0.273,-2.92185,-21.15062,2.115062,0,0,0,0,0,2.92185,2.92185,21.15062,2.965386,-2.92185,2053263
0.373,-3.088275,-20.41879,2.041878,0,0,0,0,0,3.088275,3.088275,20.41879,3.136968,-3.088275,1978820
0.394,-3.123675,-17.80785,1.780785,0,0,0,0,0,3.123675,3.123675,17.80785,3.173502,-3.123675,1725159
0.401,-3.13545,-15.26222,1.526222,0,0,0,0,0,3.13545,3.13545,15.26222,3.185658,-3.13545,1478368
0.409,-3.1488,-12.4725,1.24725,0,0,0,0,0,3.1488,3.1488,12.4725,3.199441,-3.1488,1207977
0.419,-3.165675,-9.849839,0.9849839,0,0,0,0,0,3.165675,3.165675,9.849839,3.216866,-3.165675,953802.5
0.437,-3.19575,-7.344417,0.7344418,0,0,0,0,0,3.19575,3.19575,7.344417,3.247929,-3.19575,710970.8
0.464,-3.240825,-4.789844,0.4789844,0,0,0,0,0,3.240825,3.240825,4.789844,3.294503,-3.240825,463461.4
0.564,-3.407025,-4.122809,0.4122809,0,0,0,0,0,3.407025,3.407025,4.122808,3.466417,-3.407025,398234.3
0.6640001,-3.57315,-4.132129,0.4132129,0,0,0,0,0,3.57315,3.57315,4.132129,3.63855,-3.57315,398448.2
0.706,-3.64275,-4.235543,0.4235543,0,0,0,0,0,3.64275,3.64275,4.235543,3.710755,-3.64275,408125.3
"Specimen",6
"Specimen label",""
"Width",10.000000,"mm"
"Thickness",1.000000,"mm"
"Anvil height",100.000000,"mm"
"Diameter",10.000000,"mm"
"Inner diameter",8.000000,"mm"
"Outer diameter",10.000000,"mm"
"Wall thickness",1.000000,"mm"
"Area",0.100000,"cm^2"
"Linear density",100.000000,"tex"
"Sled weight",10.000000,"N"
"Loading span",10.000000,"mm"
"Support span",100.000000,"mm"
"Span ratio","2"
"Fixture type","4-point"
"Included"
"Final width",10.000000,"mm"
"Final thickness",1.000000,"mm"
"Final anvil height",100.000000,"mm"
"Final diameter",10.000000,"mm"
"Final Inner diameter",8.000000,"mm"
"Final outer diameter",10.000000,"mm"
"Final wall thickness",1.000000,"mm"
"Final area",0.100000,"cm^2"
"Final linear density",100.000000,"tex"
"Custom text input  1",""
"Custom text input  2",""
"Custom text input  3",""
"Custom text input  4",""
"Custom text input  5",""
"Custom text input  6",""
"Custom text input  7",""
"Custom text input  8",""
"Custom text input  9",""
"Custom text input 10",""
"Custom text input 11",""
"Custom text input 12",""
"Custom text input 13",""
"Custom text input 14",""
"Custom text input 15",""
"Custom text input 16",""
"Custom text input 17",""
"Custom text input 18",""
"Custom text input 19",""
"Custom text input 20",""
"Custom text input 21",""
"Custom text input 22",""
"Custom text input 23",""
"Custom text input 24",""
"Custom text input 25",""
"Custom text input 26",""
"Custom text input 27",""
"Custom text input 28",""
"Custom text input 29",""
"Custom text input 30",""
"Custom text input 31",""
"Custom text input 32",""
"Custom text input 33",""
"Custom text input 34",""
"Custom text input 35",""
"Custom text input 36",""
"Custom text input 37",""
"Custom text input 38",""
"Custom text input 39",""
"Custom text input 40",""
"Custom text input 41",""
"Custom text input 42",""
"Custom text input 43",""
"Custom text input 44",""
"Custom text input 45",""
"Custom text input 46",""
"Custom text input 47",""
"Custom text input 48",""
"Custom text input 49",""
"Custom text input 50",""
"Custom number input  1",0.000000,""
"Custom number input  2",0.000000,""
"Custom number input  3",0.000000,""
"Custom number input  4",0.000000,""
"Custom number input  5",0.000000,""
"Custom number input  6",0.000000,""
"Custom number input  7",0.000000,""
"Custom number input  8",0.000000,""
"Custom number input  9",0.000000,""
"Custom number input 10",0.000000,""
"Time sec","Extension mm","Load N","Compressive stress MPa","Cycle Count ","Total Cycle Count ","Repetitions Count ","Marked Data ","PIP Count ","Compressive extension mm","Compressive strain %","Compressive load N","True strain %","Corrected Position mm","True stress Pa"
0,-2.448,-0.6122291,0.06122291,0,0,0,0,0,2.448,2.448,0.6122291,2.478462,-2.448,59724.17
0.015,-2.46525,-3.120497,0.3120497,0,0,0,0,0,2.46525,2.46525,3.120497,2.496146,-2.46525,304356.9
0.026,-2.476725,-5.647771,0.5647771,0,0,0,0,0,2.476725,2.476725,5.647771,2.507912,-2.476725,550789.1
0.037,-2.493675,-8.344412,0.8344412,0,0,0,0,0,2.493675,2.493675,8.344412,2.525294,-2.493675,813632.9
[...]
"Custom text input 30",""
"Custom text input 31",""
"Custom text input 32",""
"Custom text input 33",""
"Custom text input 34",""
"Custom text input 35",""
"Custom text input 36",""
"Custom text input 37",""
"Custom text input 38",""
"Custom text input 39",""
"Custom text input 40",""
"Custom text input 41",""
"Custom text input 42",""
"Custom text input 43",""
"Custom text input 44",""
"Custom text input 45",""
"Custom text input 46",""
"Custom text input 47",""
"Custom text input 48",""
"Custom text input 49",""
"Custom text input 50",""
"Custom number input  1",0.000000,""
"Custom number input  2",0.000000,""
"Custom number input  3",0.000000,""
"Custom number input  4",0.000000,""
"Custom number input  5",0.000000,""
"Custom number input  6",0.000000,""
"Custom number input  7",0.000000,""
"Custom number input  8",0.000000,""
"Custom number input  9",0.000000,""
"Custom number input 10",0.000000,""
"Time sec","Extension mm","Load N","Compressive stress MPa","Cycle Count ","Total Cycle Count ","Repetitions Count ","Marked Data ","PIP Count ","Compressive extension mm","Compressive strain %","Compressive load N","True strain %","Corrected Position mm","True stress Pa"
0,-1.257,-0.7387549,0.07387549,0,0,0,0,0,1.257,1.257,0.7387549,1.264967,-1.257,72946.87
0.012,-1.2699,-3.258258,0.3258258,0,0,0,0,0,1.2699,1.2699,3.258258,1.278032,-1.2699,321688.1
0.021,-1.2756,-5.934432,0.5934432,0,0,0,0,0,1.2756,1.2756,5.934432,1.283806,-1.2756,585873.3
0.03,-1.285125,-8.738972,0.8738972,0,0,0,0,0,1.285125,1.285125,8.738973,1.293454,-1.285125,862666.6
0.038,-1.297875,-11.24949,1.124949,0,0,0,0,0,1.297875,1.297875,11.24949,1.306371,-1.297875,1110349
0.046,-1.3086,-13.87293,1.387293,0,0,0,0,0,1.3086,1.3086,13.87293,1.317238,-1.3086,1369139
0.054,-1.316175,-16.57761,1.657761,0,0,0,0,0,1.316175,1.316175,16.57761,1.324913,-1.316175,1635942
0.062,-1.324575,-19.22989,1.922989,0,0,0,0,0,1.324575,1.324575,19.22989,1.333426,-1.324575,1897517
0.07,-1.335525,-21.77709,2.177709,0,0,0,0,0,1.335525,1.335525,21.77709,1.344523,-1.335525,2148625
0.078,-1.3491,-24.31049,2.431049,0,0,0,0,0,1.3491,1.3491,24.31049,1.358283,-1.3491,2398252
0.086,-1.3647,-26.97517,2.697517,0,0,0,0,0,1.3647,1.3647,26.97517,1.374098,-1.3647,2660704
0.093,-1.37895,-29.5241,2.95241,0,0,0,0,0,1.37895,1.37895,29.5241,1.388546,-1.37895,2911697
0.1,-1.39335,-32.34227,3.234227,0,0,0,0,0,1.39335,1.39335,32.34227,1.403148,-1.39335,3189163
0.106,-1.405275,-34.9722,3.49722,0,0,0,0,0,1.405275,1.405275,34.9722,1.415243,-1.405275,3448074
0.112,-1.41675,-37.74725,3.774725,0,0,0,0,0,1.41675,1.41675,37.74725,1.426882,-1.41675,3721246
0.118,-1.42785,-40.56992,4.056993,0,0,0,0,0,1.42785,1.42785,40.56992,1.438142,-1.42785,3999065
0.131,-1.451025,-37.78873,3.778873,0,0,0,0,0,1.451025,1.451025,37.78873,1.461655,-1.451025,3724040
0.135,-1.458,-34.89356,3.489356,0,0,0,0,0,1.458,1.458,34.89356,1.468733,-1.458,3438481
0.139,-1.46475,-31.7751,3.17751,0,0,0,0,0,1.46475,1.46475,31.7751,1.475583,-1.46475,3130968
0.143,-1.4715,-28.6912,2.86912,0,0,0,0,0,1.4715,1.4715,28.6912,1.482434,-1.4715,2826901
0.147,-1.478175,-25.83282,2.583282,0,0,0,0,0,1.478175,1.478175,25.83282,1.489209,-1.478175,2545096
0.151,-1.48485,-23.31142,2.331142,0,0,0,0,0,1.48485,1.48485,23.31142,1.495984,-1.48485,2296528
0.156,-1.49325,-20.67768,2.067768,0,0,0,0,0,1.49325,1.49325,20.67768,1.504511,-1.49325,2036891
0.163,-1.505175,-17.97619,1.797619,0,0,0,0,0,1.505175,1.505175,17.97619,1.516618,-1.505175,1770562
0.175,-1.52535,-15.44627,1.544627,0,0,0,0,0,1.52535,1.52535,15.44627,1.537103,-1.52535,1521066
0.259,-1.665075,-12.91654,1.291654,0,0,0,0,0,1.665075,1.665075,12.91654,1.679093,-1.665075,1270147
0.332,-1.78845,-10.34854,1.034854,0,0,0,0,0,1.78845,1.78845,10.34854,1.804636,-1.78845,1016346
0.432,-1.953525,-12.62705,1.262705,0,0,0,0,0,1.953525,1.953525,12.62705,1.972859,-1.953525,1238038
0.471,-2.019675,-15.14747,1.514747,0,0,0,0,0,2.019675,2.019675,15.14747,2.040349,-2.019675,1484154
0.544,-2.141625,-12.50111,1.250111,0,0,0,0,0,2.141625,2.141625,12.50111,2.164891,-2.141625,1223339
0.565,-2.1762,-9.999231,0.9999231,0,0,0,0,0,2.1762,2.1762,9.99923,2.200229,-2.1762,978162.7
0.5890001,-2.21535,-7.358901,0.7358902,0,0,0,0,0,2.21535,2.21535,7.358901,2.240257,-2.21535,719587.6
0.6070001,-2.245125,-4.820116,0.4820116,0,0,0,0,0,2.245125,2.245125,4.820116,2.270712,-2.245125,471189.8
0.683,-2.37345,-2.315953,0.2315953,0,0,0,0,0,2.37345,2.37345,2.315953,2.40207,-2.37345,226098.5
0.7830001,-2.538375,-2.078094,0.2078094,0,0,0,0,0,2.538375,2.538375,2.078094,2.571148,-2.538375,202534.4
0.883,-2.706675,-2.238765,0.2238765,0,0,0,0,0,2.706675,2.706675,2.238765,2.74398,-2.706675,217816.9
0.9830001,-2.8725,-2.4978,0.24978,0,0,0,0,0,2.8725,2.8725,2.4978,2.914564,-2.8725,242605
1.083,-3.039825,-2.773248,0.2773248,0,0,0,0,0,3.039825,3.039825,2.773248,3.086986,-3.039825,268894.6
1.183,-3.20625,-3.118962,0.3118962,0,0,0,0,0,3.20625,3.20625,3.118962,3.258776,-3.20625,301896
1.283,-3.3729,-3.471822,0.3471822,0,0,0,0,0,3.3729,3.3729,3.471822,3.431095,-3.3729,335472
1.383,-3.540225,-3.880054,0.3880054,0,0,0,0,0,3.540225,3.540225,3.880054,3.60441,-3.540225,374269.1
1.483,-3.70575,-4.09811,0.409811,0,0,0,0,0,3.70575,3.70575,4.09811,3.776158,-3.70575,394624.4
1.516,-3.759975,-3.867023,0.3867023,0,0,0,0,0,3.759975,3.759975,3.867023,3.832486,-3.759975,372162.4
"Specimen",59
"Specimen label",""
"Width",10.000000,"mm"
"Thickness",1.000000,"mm"
"Anvil height",100.000000,"mm"
"Diameter",10.000000,"mm"
"Inner diameter",8.000000,"mm"
"Outer diameter",10.000000,"mm"
"Wall thickness",1.000000,"mm"
"Area",0.100000,"cm^2"
"Linear density",100.000000,"tex"
"Sled weight",10.000000,"N"
"Loading span",10.000000,"mm"
"Support span",100.000000,"mm"
"Span ratio","2"
"Fixture type","4-point"
"Included"
"Final width",10.000000,"mm"
"Final thickness",1.000000,"mm"
"Final anvil height",100.000000,"mm"
"Final diameter",10.000000,"mm"
"Final Inner diameter",8.000000,"mm"
"Final outer diameter",10.000000,"mm"
"Final wall thickness",1.000000,"mm"
"Final area",0.100000,"cm^2"
"Final linear density",100.000000,"tex"
"Custom text input  1",""
"Custom text input  2",""
"Custom text input  3",""
"Custom text input  4",""
"Custom text input  5",""
"Custom text input  6",""
"Custom text input  7",""
"Custom text input  8",""
"Custom text input  9",""
"Custom text input 10",""
"Custom text input 11",""
"Custom text input 12",""
"Custom text input 13",""
"Custom text input 14",""
"Custom text input 15",""
"Custom text input 16",""
"Custom text input 17",""
"Custom text input 18",""
"Custom text input 19",""
"Custom text input 20",""
"Custom text input 21",""
"Custom text input 22",""
"Custom text input 23",""
"Custom text input 24",""
"Custom text input 25",""
"Custom text input 26",""
"Custom text input 27",""
"Custom text input 28",""
"Custom text input 29",""
"Custom text input 30",""
"Custom text input 31",""
"Custom text input 32",""
"Custom text input 33",""
"Custom text input 34",""
"Custom text input 35",""
"Custom text input 36",""
"Custom text input 37",""
"Custom text input 38",""
"Custom text input 39",""
"Custom text input 40",""
"Custom text input 41",""
"Custom text input 42",""
"Custom text input 43",""
"Custom text input 44",""
"Custom text input 45",""
"Custom text input 46",""
"Custom text input 47",""
"Custom text input 48",""
"Custom text input 49",""
"Custom text input 50",""
"Custom number input  1",0.000000,""
"Custom number input  2",0.000000,""
"Custom number input  3",0.000000,""
"Custom number input  4",0.000000,""
"Custom number input  5",0.000000,""
"Custom number input  6",0.000000,""
"Custom number input  7",0.000000,""
"Custom number input  8",0.000000,""
"Custom number input  9",0.000000,""
"Custom number input 10",0.000000,""
"Time sec","Extension mm","Load N","Compressive stress MPa","Cycle Count ","Total Cycle Count ","Repetitions Count ","Marked Data ","PIP Count ","Compressive extension mm","Compressive strain %","Compressive load N","True strain %","Corrected Position mm","True stress Pa"
0,-1.7112,-0.7189885,0.07189885,0,0,0,0,0,1.7112,1.7112,0.7189885,1.72601,-1.7112,70668.51
0.013,-1.726575,-3.386609,0.3386609,0,0,0,0,0,1.726575,1.726575,3.386609,1.741654,-1.726575,332813.7
0.022,-1.73565,-6.092034,0.6092035,0,0,0,0,0,1.73565,1.73565,6.092034,1.750889,-1.73565,598629.8
0.03,-1.746225,-8.736782,0.8736782,0,0,0,0,0,1.746225,1.746225,8.736782,1.761651,-1.746225,858421.8
0.038,-1.7598,-11.54266,1.154266,0,0,0,0,0,1.7598,1.7598,11.54266,1.775469,-1.7598,1133953
0.045,-1.773375,-14.17857,1.417857,0,0,0,0,0,1.773375,1.773375,14.17857,1.789288,-1.773375,1392713
0.052,-1.787625,-17.02832,1.702832,0,0,0,0,0,1.787625,1.787625,17.02832,1.803796,-1.787625,1672392
0.058,-1.799925,-19.64611,1.964611,0,0,0,0,0,1.799925,1.799925,19.64611,1.816321,-1.799925,1929249
0.064,-1.81185,-22.40413,2.240413,0,0,0,0,0,1.81185,1.81185,22.40413,1.828465,-1.81185,2199820
0.07,-1.8234,-25.26461,2.526461,0,0,0,0,0,1.8234,1.8234,25.26461,1.840229,-1.8234,2480394
0.07600001,-1.834425,-28.19349,2.819349,0,0,0,0,0,1.834425,1.834425,28.19349,1.851459,-1.834425,2767630
0.082,-1.844925,-31.14677,3.114677,0,0,0,0,0,1.844925,1.844925,31.14677,1.862156,-1.844925,3057214
0.08800001,-1.8552,-34.06809,3.406809,0,0,0,0,0,1.8552,1.8552,34.06808,1.872625,-1.8552,3343605
0.09400001,-1.86525,-36.91166,3.691166,0,0,0,0,0,1.86525,1.86525,36.91166,1.882865,-1.86525,3622316
0.1,-1.875075,-39.64671,3.964672,0,0,0,0,0,1.875075,1.875075,39.64671,1.892877,-1.875075,3890331
0.118,-1.905225,-36.88046,3.688046,0,0,0,0,0,1.905225,1.905225,36.88046,1.923608,-1.905225,3617781
0.122,-1.911975,-33.55879,3.355879,0,0,0,0,0,1.911975,1.911975,33.55878,1.93049,-1.911975,3291715
0.125,-1.917075,-30.98369,3.098369,0,0,0,0,0,1.917075,1.917075,30.98369,1.935689,-1.917075,3038971
0.128,-1.922175,-28.41958,2.841959,0,0,0,0,0,1.922175,1.922175,28.41958,1.940889,-1.922175,2787331
0.132,-1.929,-25.21599,2.521599,0,0,0,0,0,1.929,1.929,25.21599,1.947848,-1.929,2472957
0.136,-1.9359,-22.34546,2.234546,0,0,0,0,0,1.9359,1.9359,22.34546,1.954884,-1.9359,2191288
0.141,-1.944375,-19.31214,1.931214,0,0,0,0,0,1.944375,1.944375,19.31214,1.963527,-1.944375,1893664
0.147,-1.95465,-16.54013,1.654012,0,0,0,0,0,1.95465,1.95465,16.54012,1.974006,-1.95465,1621682
0.156,-1.970025,-13.9729,1.39729,0,0,0,0,0,1.970025,1.970025,13.9729,1.989689,-1.970025,1369763
0.225,-2.086575,-16.48142,1.648142,0,0,0,0,0,2.086575,2.086575,16.48142,2.108652,-2.086575,1613752
0.282,-2.180775,-13.80563,1.380563,0,0,0,0,0,2.180775,2.180775,13.80563,2.204906,-2.180775,1350456
0.298,-2.206725,-11.26462,1.126462,0,0,0,0,0,2.206725,2.206725,11.26462,2.231437,-2.206725,1101604
0.332,-2.26395,-8.594118,0.8594118,0,0,0,0,0,2.26395,2.26395,8.594118,2.289971,-2.26395,839955.2
0.347,-2.289375,-5.98713,0.598713,0,0,0,0,0,2.289375,2.289375,5.98713,2.315988,-2.289375,585006.2
0.398,-2.3751,-8.533292,0.8533292,0,0,0,0,0,2.3751,2.3751,8.533292,2.40376,-2.3751,833061.7
0.423,-2.4168,-11.08279,1.108279,0,0,0,0,0,2.4168,2.4168,11.08279,2.446484,-2.4168,1081494
0.448,-2.4576,-13.59928,1.359928,0,0,0,0,0,2.4576,2.4576,13.59928,2.488303,-2.4576,1326506
0.479,-2.5086,-16.16973,1.616973,0,0,0,0,0,2.5086,2.5086,16.16973,2.540602,-2.5086,1576410
0.5790001,-2.676675,-15.06974,1.506974,0,0,0,0,0,2.676675,2.676675,15.06974,2.71315,-2.676675,1466637
0.679,-2.842275,-13.88998,1.388998,0,0,0,0,0,2.842275,2.842275,13.88998,2.88345,-2.842275,1349519
0.749,-2.9601,-11.31458,1.131458,0,0,0,0,0,2.9601,2.9601,11.31458,3.004795,-2.9601,1097966
0.768,-2.9919,-8.765161,0.8765162,0,0,0,0,0,2.9919,2.9919,8.765162,3.037571,-2.9919,850291.7
0.7920001,-3.031725,-6.22341,0.6223411,0,0,0,0,0,3.031725,3.031725,6.223411,3.078632,-3.031725,603473.4
0.892,-3.19815,-5.015053,0.5015053,0,0,0,0,0,3.19815,3.19815,5.015053,3.250408,-3.19815,485466.4
0.9920001,-3.3645,-6.23583,0.6235831,0,0,0,0,0,3.3645,3.3645,6.23583,3.422402,-3.3645,602602.6
1.057,-3.47265,-8.761704,0.8761703,0,0,0,0,0,3.47265,3.47265,8.761703,3.53438,-3.47265,845744
1.108,-3.55845,-11.31158,1.131158,0,0,0,0,0,3.55845,3.55845,11.31158,3.623306,-3.55845,1090907
1.15,-3.6282,-12.58489,1.258489,0,0,0,0,0,3.6282,3.6282,12.5849,3.695656,-3.6282,1212829
"Specimen",60
"Specimen label",""
"Width",10.000000,"mm"
"Thickness",1.000000,"mm"
"Anvil height",100.000000,"mm"
"Diameter",10.000000,"mm"
"Inner diameter",8.000000,"mm"
"Outer diameter",10.000000,"mm"
"Wall thickness",1.000000,"mm"
"Area",0.100000,"cm^2"
"Linear density",100.000000,"tex"
"Sled weight",10.000000,"N"
"Loading span",10.000000,"mm"
"Support span",100.000000,"mm"
"Span ratio","2"
"Fixture type","4-point"
"Included"
"Final width",10.000000,"mm"
"Final thickness",1.000000,"mm"
"Final anvil height",100.000000,"mm"
"Final diameter",10.000000,"mm"
"Final Inner diameter",8.000000,"mm"
"Final outer diameter",10.000000,"mm"
"Final wall thickness",1.000000,"mm"
"Final area",0.100000,"cm^2"
"Final linear density",100.000000,"tex"
"Custom text input  1",""
"Custom text input  2",""
"Custom text input  3",""
"Custom text input  4",""
"Custom text input  5",""
"Custom text input  6",""
"Custom text input  7",""
"Custom text input  8",""
"Custom text input  9",""
"Custom text input 10",""
"Custom text input 11",""
"Custom text input 12",""
"Custom text input 13",""
"Custom text input 14",""
"Custom text input 15",""
"Custom text input 16",""
"Custom text input 17",""
"Custom text input 18",""
"Custom text input 19",""
"Custom text input 20",""
"Custom text input 21",""
"Custom text input 22",""
"Custom text input 23",""
"Custom text input 24",""
"Custom text input 25",""
"Custom text input 26",""
"Custom text input 27",""
"Custom text input 28",""
"Custom text input 29",""
"Custom text input 30",""
"Custom text input 31",""
"Custom text input 32",""
"Custom text input 33",""
"Custom text input 34",""
"Custom text input 35",""
"Custom text input 36",""
"Custom text input 37",""
"Custom text input 38",""
"Custom text input 39",""
"Custom text input 40",""
"Custom text input 41",""
"Custom text input 42",""
"Custom text input 43",""
"Custom text input 44",""
"Custom text input 45",""
"Custom text input 46",""
"Custom text input 47",""
"Custom text input 48",""
"Custom text input 49",""
"Custom text input 50",""
"Custom number input  1",0.000000,""
"Custom number input  2",0.000000,""
"Custom number input  3",0.000000,""
"Custom number input  4",0.000000,""
"Custom number input  5",0.000000,""
"Custom number input  6",0.000000,""
"Custom number input  7",0.000000,""
"Custom number input  8",0.000000,""
"Custom number input  9",0.000000,""
"Custom number input 10",0.000000,""
"Time sec","Extension mm","Load N","Compressive stress MPa","Cycle Count ","Total Cycle Count ","Repetitions Count ","Marked Data ","PIP Count ","Compressive extension mm","Compressive strain %","Compressive load N","True strain %","Corrected Position mm","True stress Pa"
0,-1.4178,-0.6133094,0.06133094,0,0,0,0,0,1.4178,1.4178,0.6133094,1.427947,-1.4178,60461.39
0.021,-1.441725,-3.12297,0.3122971,0,0,0,0,0,1.441725,1.441725,3.122971,1.452219,-1.441725,307794.6
0.033,-1.4583,-5.692787,0.5692787,0,0,0,0,0,1.4583,1.4583,5.692788,1.469038,-1.4583,560977
0.042,-1.47435,-8.229375,0.8229375,0,0,0,0,0,1.47435,1.47435,8.229375,1.485327,-1.47435,810804.5
0.05,-1.4901,-10.93849,1.093849,0,0,0,0,0,1.4901,1.4901,10.93849,1.501314,-1.4901,1077549
0.057,-1.5042,-13.60924,1.360924,0,0,0,0,0,1.5042,1.5042,13.60924,1.515628,-1.5042,1340453
0.064,-1.518,-16.47485,1.647485,0,0,0,0,0,1.518,1.518,16.47485,1.52964,-1.518,1622476
0.07,-1.5294,-19.01621,1.901621,0,0,0,0,0,1.5294,1.5294,19.01621,1.541216,-1.5294,1872537
0.07600001,-1.54035,-21.59412,2.159412,0,0,0,0,0,1.54035,1.54035,21.59412,1.552337,-1.54035,2126150
0.082,-1.551075,-24.18398,2.418398,0,0,0,0,0,1.551075,1.551075,24.18398,1.56323,-1.551075,2380887
0.089,-1.563225,-27.05114,2.705114,0,0,0,0,0,1.563225,1.563225,27.05114,1.575572,-1.563225,2662827
0.096,-1.574925,-29.56152,2.956152,0,0,0,0,0,1.574925,1.574925,29.56152,1.587459,-1.574925,2909595
0.104,-1.588125,-32.37596,3.237596,0,0,0,0,0,1.588125,1.588125,32.37596,1.600871,-1.588125,3186179
0.111,-1.599675,-34.965,3.4965,0,0,0,0,0,1.599675,1.599675,34.965,1.612608,-1.599675,3440567
0.118,-1.611225,-37.75125,3.775125,0,0,0,0,0,1.611225,1.611225,37.75125,1.624346,-1.611225,3714299
0.124,-1.621275,-40.28602,4.028602,0,0,0,0,0,1.621275,1.621275,40.28602,1.634562,-1.621275,3963287
0.13,-1.631325,-42.91917,4.291917,0,0,0,0,0,1.631325,1.631325,42.91917,1.644778,-1.631325,4221902
0.136,-1.641375,-45.59383,4.559383,0,0,0,0,0,1.641375,1.641375,45.59383,1.654995,-1.641375,4484546
0.142,-1.65165,-48.29831,4.829831,0,0,0,0,0,1.65165,1.65165,48.29831,1.665442,-1.65165,4750059
0.158,-1.679775,-45.56338,4.556338,0,0,0,0,0,1.679775,1.679775,45.56339,1.694043,-1.679775,4479802
0.161,-1.6851,-42.53206,4.253206,0,0,0,0,0,1.6851,1.6851,42.53206,1.699459,-1.6851,4181536
0.164,-1.690425,-39.26665,3.926665,0,0,0,0,0,1.690425,1.690425,39.26665,1.704876,-1.690425,3860287
0.167,-1.69575,-35.97292,3.597291,0,0,0,0,0,1.69575,1.69575,35.97292,1.710293,-1.69575,3536290
0.17,-1.701,-32.72796,3.272796,0,0,0,0,0,1.701,1.701,32.72796,1.715633,-1.701,3217126
0.173,-1.70625,-29.68092,2.968091,0,0,0,0,0,1.70625,1.70625,29.68092,1.720974,-1.70625,2917448
0.176,-1.711425,-26.8945,2.68945,0,0,0,0,0,1.711425,1.711425,26.8945,1.726239,-1.711425,2643422
0.179,-1.716675,-24.38514,2.438514,0,0,0,0,0,1.716675,1.716675,24.38514,1.731581,-1.716675,2396653
0.183,-1.7235,-21.52326,2.152326,0,0,0,0,0,1.7235,1.7235,21.52326,1.738525,-1.7235,2115231
0.188,-1.7319,-18.68694,1.868694,0,0,0,0,0,1.7319,1.7319,18.68694,1.747073,-1.7319,1836330
0.195,-1.74345,-15.95353,1.595353,0,0,0,0,0,1.74345,1.74345,15.95353,1.758827,-1.74345,1567539
0.206,-1.76175,-13.29489,1.329489,0,0,0,0,0,1.76175,1.76175,13.29489,1.777454,-1.76175,1306067
0.27,-1.86795,-15.81085,1.581085,0,0,0,0,0,1.86795,1.86795,15.81085,1.885617,-1.86795,1551552
0.305,-1.9251,-18.33289,1.833289,0,0,0,0,0,1.9251,1.9251,18.33289,1.943871,-1.9251,1797996
0.384,-2.05875,-15.75483,1.575483,0,0,0,0,0,2.05875,2.05875,15.75483,2.080238,-2.05875,1543048
0.415,-2.110125,-13.09218,1.309218,0,0,0,0,0,2.110125,2.110125,13.09218,2.132706,-2.110125,1281592
0.43,-2.135175,-10.58479,1.058479,0,0,0,0,0,2.135175,2.135175,10.58479,2.1583,-2.135175,1035878
0.5300001,-2.301,-10.00512,1.000512,0,0,0,0,0,2.301,2.301,10.00512,2.327886,-2.301,977490.6
0.6300001,-2.46765,-10.49625,1.049625,0,0,0,0,0,2.46765,2.46765,10.49625,2.498607,-2.46765,1023724
0.6670001,-2.5284,-13.01045,1.301045,0,0,0,0,0,2.5284,2.5284,13.01045,2.560913,-2.5284,1268149
0.711,-2.6031,-10.41583,1.041583,0,0,0,0,0,2.6031,2.6031,10.41583,2.63758,-2.6031,1014470
0.7220001,-2.621775,-7.847428,0.7847428,0,0,0,0,0,2.621775,2.621775,7.847428,2.656756,-2.621775,764168.6
0.7450001,-2.660175,-5.344085,0.5344086,0,0,0,0,0,2.660175,2.660175,5.344085,2.696198,-2.660175,520192.3
0.8210001,-2.78595,-7.907294,0.7907294,0,0,0,0,0,2.78595,2.78595,7.907294,2.825494,-2.78595,768700
0.8620001,-2.85345,-10.47257,1.047257,0,0,0,0,0,2.85345,2.85345,10.47257,2.894952,-2.85345,1017374
0.8990001,-2.91615,-12.97924,1.297924,0,0,0,0,0,2.91615,2.91615,12.97924,2.959515,-2.91615,1260075
0.933,-2.9733,-15.55835,1.555835,0,0,0,0,0,2.9733,2.9733,15.55835,3.018399,-2.9733,1509576
1.021,-3.1185,-13.0479,1.30479,0,0,0,0,0,3.1185,3.1185,13.0479,3.168161,-3.1185,1264100
1.039,-3.148425,-10.42987,1.042987,0,0,0,0,0,3.148425,3.148425,10.42987,3.199054,-3.148425,1010150
1.057,-3.1791,-7.910877,0.7910877,0,0,0,0,0,3.1791,3.1791,7.910877,3.230731,-3.1791,765938.3
1.157,-3.34635,-9.282112,0.9282112,0,0,0,0,0,3.34635,3.34635,9.282112,3.403622,-3.34635,897150
1.211,-3.435525,-11.81793,1.181793,0,0,0,0,0,3.435525,3.435525,11.81793,3.495927,-3.435525,1141192
1.311,-3.603375,-12.18899,1.218899,0,0,0,0,0,3.603375,3.603375,12.18899,3.6699,-3.603375,1174978
1.411,-3.768975,-11.11538,1.111538,0,0,0,0,0,3.768975,3.768975,11.11538,3.841838,-3.768975,1069644
1.491,-3.903675,-10.64558,1.064558,0,0,0,0,0,3.903675,3.903675,10.64558,3.981911,-3.903675,1023001