File: EXPERIMENTAL/COMPRESSION/10mm_min.txt
"Test Type","Compression"
"Method Name",""
"Sample name","C:\Users\EGS\Desktop\Eggs\2024-02-08\10mm_min.is_comp"
"User",""
"Sample note 1",""
"Sample note 2",""
"Sample note 3",""
"Geometry","Rectangular"
"Specimen",1
"Specimen label",""
"Width",10.000000,"mm"
"Thickness",1.000000,"mm"
"Anvil height",100.000000,"mm"
"Diameter",10.000000,"mm"
"Inner diameter",8.000000,"mm"
"Outer diameter",10.000000,"mm"
"Wall thickness",1.000000,"mm"
"Area",0.100000,"cm^2"
"Linear density",100.000000,"tex"
"Sled weight",10.000000,"N"
"Loading span",10.000000,"mm"
"Support span",100.000000,"mm"
"Span ratio","2"
"Fixture type","4-point"
"Included"
"Final width",10.000000,"mm"
"Final thickness",1.000000,"mm"
"Final anvil height",100.000000,"mm"
"Final diameter",10.000000,"mm"
"Final Inner diameter",8.000000,"mm"
"Final outer diameter",10.000000,"mm"
"Final wall thickness",1.000000,"mm"
"Final area",0.100000,"cm^2"
"Final linear density",100.000000,"tex"
"Custom text input  1",""
"Custom text input  2",""
"Custom text input  3",""
"Custom text input  4",""
"Custom text input  5",""
"Custom text input  6",""
"Custom text input  7",""
"Custom text input  8",""
"Custom text input  9",""
"Custom text input 10",""
"Custom text input 11",""
"Custom text input 12",""
"Custom text input 13",""
"Custom text input 14",""
"Custom text input 15",""
"Custom text input 16",""
"Custom text input 17",""
"Custom text input 18",""
"Custom text input 19",""
"Custom text input 20",""
"Custom text input 21",""
"Custom text input 22",""
"Custom text input 23",""
"Custom text input 24",""
"Custom text input 25",""
"Custom text input 26",""
"Custom text input 27",""
"Custom text input 28",""
"Custom text input 29",""
"Custom text input 30",""
"Custom text input 31",""
"Custom text input 32",""
"Custom text input 33",""
"Custom text input 34",""
"Custom text input 35",""
"Custom text input 36",""
"Custom text input 37",""
"Custom text input 38",""
"Custom text input 39",""
"Custom text input 40",""
"Custom text input 41",""
"Custom text input 42",""
"Custom text input 43",""
"Custom text input 44",""
"Custom text input 45",""
"Custom text input 46",""
"Custom text input 47",""
"Custom text input 48",""
"Custom text input 49",""
"Custom text input 50",""
"Custom number input  1",0.000000,""
"Custom number input  2",0.000000,""
"Custom number input  3",0.000000,""
"Custom number input  4",0.000000,""
"Custom number input  5",0.000000,""
"Custom number input  6",0.000000,""
"Custom number input  7",0.000000,""
"Custom number input  8",0.000000,""
"Custom number input  9",0.000000,""
"Custom number input 10",0.000000,""
"Time sec","Extension mm","Load N","Compressive stress MPa","Cycle Count ","Total Cycle Count ","Repetitions Count ","Marked Data ","PIP Count ","Compressive extension mm","Compressive strain %","Compressive load N","True strain %","Corrected Position mm","True stress Pa"
0,-0.624675,-0.5496815,0.05496815,0,0,0,0,0,0.624675,0.624675,0.5496815,0.6266343,-0.624675,54624.78
0.1,-0.62955,-2.016343,0.2016343,0,0,0,0,0,0.62955,0.62955,2.016343,0.63154,-0.62955,200364.9
0.184,-0.65115,-4.532628,0.4532628,0,0,0,0,0,0.65115,0.65115,4.532628,0.6532792,-0.65115,450311.4
0.239,-0.6606,-7.041574,0.7041574,0,0,0,0,0,0.6606,0.6606,7.041574,0.6627916,-0.6606,699505.7
0.322,-0.67455,-9.56393,0.956393,0,0,0,0,0,0.67455,0.67455,9.563931,0.6768354,-0.67455,949941.7
0.402,-0.689175,-12.07028,1.207028,0,0,0,0,0,0.689175,0.689175,12.07028,0.6915608,-0.689175,1198709
0.469,-0.699375,-14.57049,1.457049,0,0,0,0,0,0.699375,0.699375,14.57049,0.7018321,-0.699375,1446859
0.544,-0.712275,-17.08051,1.708051,0,0,0,0,0,0.712275,0.712275,17.08051,0.7148238,-0.712275,1695885
0.6440001,-0.728625,-18.46379,1.846379,0,0,0,0,0,0.7286251,0.7286251,18.46379,0.7312925,-0.728625,1832926
0.744,-0.74535,-20.28476,2.028476,0,0,0,0,0,0.74535,0.74535,20.28477,0.7481416,-0.74535,2013357
0.8440001,-0.7623,-21.25589,2.125589,0,0,0,0,0,0.7623,0.7623,21.25589,0.7652204,-0.7623,2109385
0.8980001,-0.77085,-23.8058,2.38058,0,0,0,0,0,0.7708501,0.7708501,23.80581,0.7738365,-0.77085,2362230
0.9480001,-0.778875,-26.31246,2.631246,0,0,0,0,0,0.778875,0.778875,26.31246,0.781924,-0.778875,2610752
0.998,-0.788775,-28.82388,2.882388,0,0,0,0,0,0.788775,0.788775,28.82388,0.7919023,-0.788775,2859653
1.098,-0.8043,-29.59767,2.959767,0,0,0,0,0,0.8043,0.8043,29.59767,0.807552,-0.8043,2935962
1.198,-0.8216251,-31.6273,3.16273,0,0,0,0,0,0.8216251,0.8216251,31.6273,0.825019,-0.8216251,3136745
1.265,-0.831375,-34.15198,3.415198,0,0,0,0,0,0.831375,0.831375,34.15198,0.8348502,-0.831375,3386805
1.326,-0.842325,-36.66954,3.666955,0,0,0,0,0,0.842325,0.842325,36.66954,0.8458926,-0.842325,3636067
1.413,-0.85725,-39.17689,3.917689,0,0,0,0,0,0.85725,0.85725,39.17689,0.8609455,-0.85725,3884104
1.513,-0.87345,-40.11554,4.011554,0,0,0,0,0,0.87345,0.87345,40.11554,0.8772869,-0.87345,3976515
1.613,-0.8904751,-40.7237,4.07237,0,0,0,0,0,0.890475,0.890475,40.7237,0.8944635,-0.8904751,4036106
1.713,-0.906825,-41.18959,4.118959,0,0,0,0,0,0.906825,0.906825,41.18959,0.9109617,-0.906825,4081607
1.813,-0.9246001,-39.89328,3.989328,0,0,0,0,0,0.9246001,0.9246001,39.89328,0.928901,-0.9246001,3952443
1.913,-0.939825,-39.15916,3.915916,0,0,0,0,0,0.939825,0.939825,39.15916,0.9442692,-0.939825,3879114
2.013,-0.958125,-39.73892,3.973892,0,0,0,0,0,0.9581251,0.9581251,39.73892,0.9627446,-0.958125,3935817
2.113,-0.9735,-41.02311,4.102311,0,0,0,0,0,0.9735,0.9735,41.02311,0.9782695,-0.9735,4062375
2.213,-0.990825,-43.33768,4.333768,0,0,0,0,0,0.990825,0.990825,43.33768,0.9957663,-0.990825,4290828
2.289,-1.002675,-40.76227,4.076227,0,0,0,0,0,1.002675,1.002675,40.76227,1.007736,-1.002675,4035355
2.292,-1.00335,-38.23283,3.823282,0,0,0,0,0,1.00335,1.00335,38.23283,1.008417,-1.00335,3784922
2.295,-1.0041,-35.64235,3.564235,0,0,0,0,0,1.0041,1.0041,35.64235,1.009175,-1.0041,3528446
2.298,-1.00485,-32.79375,3.279375,0,0,0,0,0,1.00485,1.00485,32.79375,1.009933,-1.00485,3246422
2.302,-1.005675,-29.48504,2.948504,0,0,0,0,0,1.005675,1.005675,29.48504,1.010766,-1.005675,2918852
2.306,-1.006575,-26.3269,2.63269,0,0,0,0,0,1.006575,1.006575,26.3269,1.011675,-1.006575,2606190
2.31,-1.0074,-23.73033,2.373033,0,0,0,0,0,1.0074,1.0074,23.73033,1.012509,-1.0074,2349127
2.315,-1.0083,-21.08948,2.108948,0,0,0,0,0,1.0083,1.0083,21.08948,1.013418,-1.0083,2087683
2.321,-1.009275,-18.49399,1.849399,0,0,0,0,0,1.009275,1.009275,18.49399,1.014403,-1.009275,1830733
2.329,-1.01055,-15.7586,1.57586,0,0,0,0,0,1.01055,1.01055,15.7586,1.015691,-1.01055,1559936
2.342,-1.012425,-13.17456,1.317456,0,0,0,0,0,1.012425,1.012425,13.17456,1.017585,-1.012425,1304117
2.442,-1.028775,-14.76845,1.476845,0,0,0,0,0,1.028775,1.028775,14.76845,1.034103,-1.028775,1461652
2.542,-1.0449,-15.64295,1.564295,0,0,0,0,0,1.0449,1.0449,15.64295,1.050397,-1.0449,1547950
2.642,-1.062225,-16.55303,1.655303,0,0,0,0,0,1.062225,1.062225,16.55303,1.067907,-1.062225,1637720
2.742,-1.07835,-16.82881,1.682881,0,0,0,0,0,1.07835,1.07835,16.82881,1.084206,-1.07835,1664733
2.842,-1.095225,-16.3053,1.63053,0,0,0,0,0,1.095225,1.095225,16.3053,1.101267,-1.095225,1612672
2.942,-1.1115,-14.81579,1.481579,0,0,0,0,0,1.1115,1.1115,14.81579,1.117723,-1.1115,1465111
3.042,-1.128,-15.08608,1.508608,0,0,0,0,0,1.128,1.128,15.08608,1.13441,-1.128,1491591
3.142,-1.1451,-15.67321,1.567321,0,0,0,0,0,1.1451,1.1451,15.67321,1.151707,-1.1451,1549373
3.242,-1.16115,-16.30342,1.630342,0,0,0,0,0,1.16115,1.16115,16.30342,1.167944,-1.16115,1611411
3.342,-1.178325,-17.14626,1.714626,0,0,0,0,0,1.178325,1.178325,17.14626,1.185322,-1.178325,1694422
3.442,-1.195125,-17.97296,1.797296,0,0,0,0,0,1.195125,1.195125,17.97296,1.202324,-1.195125,1775816
3.542,-1.211025,-18.86207,1.886207,0,0,0,0,0,1.211025,1.211025,18.86207,1.218418,-1.211025,1863364
3.642,-1.22865,-19.74826,1.974826,0,0,0,0,0,1.22865,1.22865,19.74826,1.23626,-1.22865,1950563
3.742,-1.245225,-20.26401,2.026401,0,0,0,0,0,1.245225,1.245225,20.26401,1.253043,-1.245225,2001167
3.842,-1.26165,-20.61689,2.061689,0,0,0,0,0,1.26165,1.26165,20.61689,1.269676,-1.26165,2035678
3.942,-1.278825,-20.8574,2.08574,0,0,0,0,0,1.278825,1.278825,20.8574,1.287072,-1.278825,2059067
4.042,-1.2951,-19.9927,1.99927,0,0,0,0,0,1.2951,1.2951,19.9927,1.30356,-1.2951,1973378
4.142,-1.311825,-19.36319,1.936319,0,0,0,0,0,1.311825,1.311825,19.3632,1.320505,-1.311825,1910918
4.22,-1.324875,-16.85359,1.685359,0,0,0,0,0,1.324875,1.324875,16.85359,1.33373,-1.324875,1663030
4.32,-1.3413,-15.49967,1.549967,0,0,0,0,0,1.3413,1.3413,15.49967,1.350377,-1.3413,1529177
4.42,-1.35885,-15.76082,1.576082,0,0,0,0,0,1.35885,1.35885,15.76082,1.368167,-1.35885,1554665
4.52,-1.374375,-15.87467,1.587467,0,0,0,0,0,1.374375,1.374375,15.87467,1.383907,-1.374375,1565649
4.575,-1.384425,-13.29071,1.329071,0,0,0,0,0,1.384425,1.384425,13.29071,1.394098,-1.384425,1310671
4.593,-1.38825,-10.78659,1.078659,0,0,0,0,0,1.38825,1.38825,10.78659,1.397976,-1.38825,1063684
4.689,-1.402725,-8.284844,0.8284844,0,0,0,0,0,1.402725,1.402725,8.284844,1.412656,-1.402725,816863.1
4.789,-1.420575,-8.105271,0.8105271,0,0,0,0,0,1.420575,1.420575,8.10527,1.430762,-1.420575,799012.9
4.889,-1.43535,-8.265913,0.8265914,0,0,0,0,0,1.43535,1.43535,8.265913,1.445751,-1.43535,814726.9
4.989,-1.45335,-9.08117,0.908117,0,0,0,0,0,1.45335,1.45335,9.08117,1.464015,-1.45335,894918.9
5.089,-1.4691,-9.700105,0.9700105,0,0,0,0,0,1.4691,1.4691,9.700105,1.479998,-1.4691,955760
5.189,-1.4865,-9.226978,0.9226979,0,0,0,0,0,1.4865,1.4865,9.226978,1.497659,-1.4865,908982
5.289,-1.5027,-8.81891,0.881891,0,0,0,0,0,1.5027,1.5027,8.81891,1.514105,-1.5027,868638.8
5.389,-1.520475,-9.366296,0.9366297,0,0,0,0,0,1.520475,1.520475,9.366296,1.532153,-1.520475,922388.4
5.489,-1.535625,-9.779751,0.977975,0,0,0,0,0,1.535625,1.535625,9.779751,1.547538,-1.535625,962957
5.589,-1.554375,-8.766428,0.8766428,0,0,0,0,0,1.554375,1.554375,8.766428,1.566582,-1.554375,863016.4
5.689,-1.56915,-7.438973,0.7438973,0,0,0,0,0,1.56915,1.56915,7.438972,1.581591,-1.56915,732224.4
5.789,-1.58715,-7.648408,0.7648408,0,0,0,0,0,1.58715,1.58715,7.648408,1.59988,-1.58715,752701.7
5.889,-1.6023,-7.024534,0.7024534,0,0,0,0,0,1.6023,1.6023,7.024534,1.615276,-1.6023,691198
5.989,-1.620525,-7.364675,0.7364675,0,0,0,0,0,1.620525,1.620525,7.364676,1.633799,-1.620525,724532.9
6.089,-1.63605,-7.623874,0.7623874,0,0,0,0,0,1.63605,1.63605,7.623874,1.649581,-1.63605,749914.3
6.189,-1.65315,-8.045822,0.8045822,0,0,0,0,0,1.65315,1.65315,8.045822,1.666967,-1.65315,791281.3
6.289,-1.669275,-8.311711,0.8311712,0,0,0,0,0,1.669275,1.669275,8.311711,1.683365,-1.669275,817296.6
6.389,-1.6872,-8.560568,0.8560568,0,0,0,0,0,1.6872,1.6872,8.560568,1.701595,-1.6872,841613.4
6.489,-1.7022,-8.759156,0.8759156,0,0,0,0,0,1.7022,1.7022,8.759156,1.716854,-1.7022,861005.8
6.589,-1.7208,-9.001173,0.9001173,0,0,0,0,0,1.7208,1.7208,9.001173,1.735778,-1.7208,884628.1
6.689,-1.735725,-9.052001,0.9052001,0,0,0,0,0,1.735725,1.735725,9.052001,1.750965,-1.735725,889488.3
6.789,-1.75335,-9.025112,0.9025112,0,0,0,0,0,1.75335,1.75335,9.025112,1.768903,-1.75335,886687
6.889,-1.769175,-8.920886,0.8920885,0,0,0,0,0,1.769175,1.769175,8.920886,1.785012,-1.769175,876306
6.989,-1.786875,-8.992031,0.8992031,0,0,0,0,0,1.786875,1.786875,8.992031,1.803032,-1.786875,883135.5
7.089,-1.802625,-8.686222,0.8686222,0,0,0,0,0,1.802625,1.802625,8.686222,1.81907,-1.802625,852964.2
7.189,-1.820025,-8.576363,0.8576363,0,0,0,0,0,1.820025,1.820025,8.576364,1.836791,-1.820025,842027.1
7.289,-1.835775,-8.554049,0.8554049,0,0,0,0,0,1.835775,1.835775,8.554049,1.852835,-1.835775,839701.6
7.389,-1.853775,-8.632094,0.8632094,0,0,0,0,0,1.853775,1.853775,8.632093,1.871173,-1.853775,847207.4
7.489,-1.868775,-8.705392,0.8705392,0,0,0,0,0,1.868775,1.868775,8.705393,1.886457,-1.868775,854270.8
7.589,-1.8873,-8.881748,0.8881749,0,0,0,0,0,1.8873,1.8873,8.881748,1.905337,-1.8873,871412.3
7.689,-1.90245,-8.868828,0.8868828,0,0,0,0,0,1.90245,1.90245,8.868829,1.92078,-1.90245,870010.3
7.789,-1.920075,-8.865125,0.8865125,0,0,0,0,0,1.920075,1.920075,8.865126,1.938748,-1.920075,869490.8
7.889,-1.936425,-8.912519,0.8912519,0,0,0,0,0,1.936425,1.936425,8.912519,1.955419,-1.936425,873993.4
7.989,-1.953675,-7.319219,0.7319219,0,0,0,0,0,1.953675,1.953675,7.31922,1.973012,-1.953675,717622.6
8.089,-1.969125,-7.365443,0.7365443,0,0,0,0,0,1.969125,1.969125,7.365443,1.988771,-1.969125,722040.8
8.189,-1.9872,-7.669248,0.7669247,0,0,0,0,0,1.9872,1.9872,7.669248,2.00721,-1.9872,751684.4
8.289001,-2.002425,-7.673979,0.7673979,0,0,0,0,0,2.002425,2.002425,7.673979,2.022745,-2.002425,752031.3
8.389,-2.0205,-6.787151,0.6787152,0,0,0,0,0,2.0205,2.0205,6.787151,2.041191,-2.0205,665001.7
8.489,-2.0352,-6.627366,0.6627366,0,0,0,0,0,2.0352,2.0352,6.627366,2.056196,-2.0352,649248.6
8.589001,-2.053275,-6.620534,0.6620533,0,0,0,0,0,2.053275,2.053275,6.620534,2.074648,-2.053275,648459.6
8.689,-2.069175,-6.706916,0.6706916,0,0,0,0,0,2.069175,2.069175,6.706916,2.090882,-2.069175,656813.8
8.789001,-2.08635,-7.04699,0.704699,0,0,0,0,0,2.08635,2.08635,7.04699,2.108422,-2.08635,689996.5
8.889001,-2.102775,-7.447265,0.7447265,0,0,0,0,0,2.102775,2.102775,7.447265,2.125198,-2.102775,729066.6
8.989,-2.12025,-7.588506,0.7588506,0,0,0,0,0,2.12025,2.12025,7.588506,2.14305,-2.12025,742761
9.089001,-2.135625,-7.965185,0.7965184,0,0,0,0,0,2.135625,2.135625,7.965185,2.15876,-2.135625,779507.8
9.189,-2.154,-8.129038,0.8129038,0,0,0,0,0,2.154,2.154,8.129038,2.177537,-2.154,795393.8
9.289001,-2.16915,-8.30394,0.8303939,0,0,0,0,0,2.16915,2.16915,8.30394,2.193022,-2.16915,812381.4
9.389001,-2.187,-8.583464,0.8583463,0,0,0,0,0,2.187,2.187,8.583464,2.211269,-2.187,839574.3
9.489,-2.20245,-8.823566,0.8823566,0,0,0,0,0,2.20245,2.20245,8.823566,2.227066,-2.20245,862923.2
9.589001,-2.220225,-9.05221,0.905221,0,0,0,0,0,2.220225,2.220225,9.05221,2.245243,-2.220225,885123
9.689,-2.23605,-9.173915,0.9173915,0,0,0,0,0,2.23605,2.23605,9.173915,2.261429,-2.23605,896878.1
9.789001,-2.253,-9.388201,0.9388201,0,0,0,0,0,2.253,2.253,9.388201,2.278768,-2.253,917668.5
9.889001,-2.269275,-9.624243,0.9624243,0,0,0,0,0,2.269275,2.269275,9.624243,2.295419,-2.269275,940584.2
9.989,-2.287125,-9.843975,0.9843975,0,0,0,0,0,2.287125,2.287125,9.843975,2.313685,-2.287125,961883.1
10.089,-2.30235,-10.14592,1.014592,0,0,0,0,0,2.30235,2.30235,10.14592,2.329268,-2.30235,991232.3
10.189,-2.320575,-10.22476,1.022476,0,0,0,0,0,2.320575,2.320575,10.22476,2.347924,-2.320575,998748.7
10.277,-2.333775,-7.706307,0.7706307,0,0,0,0,0,2.333775,2.333775,7.706307,2.361439,-2.333775,752645.9
10.377,-2.351475,-8.407898,0.8407898,0,0,0,0,0,2.351475,2.351475,8.407898,2.379564,-2.351475,821018.9
10.477,-2.367075,-7.066041,0.7066041,0,0,0,0,0,2.367075,2.367075,7.066041,2.39554,-2.367075,689878.2
10.577,-2.38455,-7.54223,0.754223,0,0,0,0,0,2.38455,2.38455,7.54223,2.413441,-2.38455,736238.2
10.677,-2.4006,-7.512413,0.7512413,0,0,0,0,0,2.4006,2.4006,7.512413,2.429884,-2.4006,733207
10.777,-2.417325,-7.75855,0.7758551,0,0,0,0,0,2.417325,2.417325,7.75855,2.447022,-2.417325,757100.1
10.877,-2.43375,-8.119933,0.8119934,0,0,0,0,0,2.43375,2.43375,8.119933,2.463855,-2.43375,792231.4
10.977,-2.45175,-8.6395,0.86395,0,0,0,0,0,2.45175,2.45175,8.6395,2.482306,-2.45175,842768.1
11.077,-2.466975,-8.181281,0.8181281,0,0,0,0,0,2.466975,2.466975,8.181281,2.497915,-2.466975,797945.1
11.177,-2.4855,-8.727044,0.8727044,0,0,0,0,0,2.4855,2.4855,8.727044,2.51691,-2.4855,851013.3
11.277,-2.5005,-9.143963,0.9143963,0,0,0,0,0,2.5005,2.5005,9.143964,2.532294,-2.5005,891531.9
11.377,-2.5182,-9.226918,0.9226918,0,0,0,0,0,2.5182,2.5182,9.226918,2.550449,-2.5182,899456.6
11.477,-2.5344,-9.084053,0.9084053,0,0,0,0,0,2.5344,2.5344,9.084053,2.567069,-2.5344,885382.7
11.577,-2.55165,-9.531401,0.9531401,0,0,0,0,0,2.55165,2.55165,9.531401,2.584769,-2.55165,928819.3
11.677,-2.567175,-9.311929,0.9311929,0,0,0,0,0,2.567175,2.567175,9.31193,2.600702,-2.567175,907287.6
11.777,-2.584725,-8.614935,0.8614935,0,0,0,0,0,2.584725,2.584725,8.614935,2.618716,-2.584725,839226.3
11.877,-2.60055,-8.667655,0.8667655,0,0,0,0,0,2.60055,2.60055,8.667655,2.634962,-2.60055,844224.9
11.977,-2.618325,-8.75891,0.875891,0,0,0,0,0,2.618325,2.618325,8.75891,2.653214,-2.618325,852957.3
12.077,-2.63325,-8.741915,0.8741914,0,0,0,0,0,2.63325,2.63325,8.741915,2.668541,-2.63325,851171.8
12.177,-2.651475,-9.101525,0.9101525,0,0,0,0,0,2.651475,2.651475,9.101525,2.687261,-2.651475,886020
12.277,-2.66715,-9.33966,0.933966,0,0,0,0,0,2.66715,2.66715,9.339661,2.703364,-2.66715,909055.8
12.377,-2.6844,-8.852601,0.8852601,0,0,0,0,0,2.6844,2.6844,8.852601,2.721088,-2.6844,861496.2
12.477,-2.7006,-9.095125,0.9095125,0,0,0,0,0,2.7006,2.7006,9.095125,2.737736,-2.7006,884950.2
12.577,-2.71815,-9.375766,0.9375766,0,0,0,0,0,2.71815,2.71815,9.375766,2.755775,-2.71815,912091.9
12.677,-2.73375,-9.804182,0.9804182,0,0,0,0,0,2.73375,2.73375,9.804182,2.771812,-2.73375,953616
12.777,-2.751975,-10.21468,1.021468,0,0,0,0,0,2.751975,2.751975,10.21468,2.790551,-2.751975,993357.4
12.877,-2.76735,-10.57111,1.057111,0,0,0,0,0,2.76735,2.76735,10.57111,2.806363,-2.76735,1027857
12.977,-2.78505,-10.91832,1.091832,0,0,0,0,0,2.78505,2.78505,10.91832,2.824568,-2.78505,1061424
13.077,-2.800425,-10.65313,1.065313,0,0,0,0,0,2.800425,2.800425,10.65313,2.840385,-2.800425,1035480
13.177,-2.818125,-9.510733,0.9510733,0,0,0,0,0,2.818125,2.818125,9.510734,2.858596,-2.818125,924270.9
13.277,-2.83425,-10.02266,1.002266,0,0,0,0,0,2.83425,2.83425,10.02266,2.87519,-2.83425,973859.5
13.377,-2.851125,-9.596728,0.9596728,0,0,0,0,0,2.851125,2.851125,9.596727,2.892559,-2.851125,932311.3
13.477,-2.867475,-9.927645,0.9927645,0,0,0,0,0,2.867475,2.867475,9.927646,2.90939,-2.867475,964297.3
13.577,-2.8851,-9.84966,0.984966,0,0,0,0,0,2.8851,2.8851,9.84966,2.927537,-2.8851,956548.8
13.677,-2.900475,-9.174146,0.9174145,0,0,0,0,0,2.900475,2.900475,9.174146,2.94337,-2.900475,890805.2
13.777,-2.918775,-9.154864,0.9154863,0,0,0,0,0,2.918775,2.918775,9.154863,2.962219,-2.918775,888765.4
13.877,-2.933775,-9.150289,0.9150289,0,0,0,0,0,2.933775,2.933775,9.150289,2.977671,-2.933775,888184
13.977,-2.9511,-8.636191,0.8636191,0,0,0,0,0,2.9511,2.9511,8.636191,2.995521,-2.9511,838132.9
14.077,-2.967075,-8.754507,0.8754507,0,0,0,0,0,2.967075,2.967075,8.754507,3.011983,-2.967075,849475.4
14.177,-2.98455,-9.000599,0.9000598,0,0,0,0,0,2.98455,2.98455,9.000599,3.029994,-2.98455,873197.1
14.277,-3.000375,-9.149022,0.9149022,0,0,0,0,0,3.000375,3.000375,9.149022,3.046307,-3.000375,887451.7
14.377,-3.0171,-9.587988,0.9587988,0,0,0,0,0,3.0171,3.0171,9.587988,3.063551,-3.0171,929870.9
14.477,-3.0339,-10.15153,1.015153,0,0,0,0,0,3.0339,3.0339,10.15153,3.080875,-3.0339,984354.1
14.577,-3.051825,-10.25161,1.025161,0,0,0,0,0,3.051825,3.051825,10.25161,3.099363,-3.051825,993875
14.677,-3.066975,-10.13932,1.013932,0,0,0,0,0,3.066975,3.066975,10.13932,3.114991,-3.066975,982834.6
14.777,-3.0852,-10.27305,1.027305,0,0,0,0,0,3.0852,3.0852,10.27305,3.133795,-3.0852,995610.3
14.877,-3.100575,-10.44261,1.044261,0,0,0,0,0,3.100575,3.100575,10.44261,3.14966,-3.100575,1011883
14.977,-3.118125,-10.17612,1.017612,0,0,0,0,0,3.118125,3.118125,10.17612,3.167773,-3.118125,985881.9
15.077,-3.134175,-10.00451,1.000451,0,0,0,0,0,3.134175,3.134175,10.00451,3.184341,-3.134175,969094.7
15.177,-3.151725,-10.07681,1.007681,0,0,0,0,0,3.151725,3.151725,10.07681,3.202461,-3.151725,975921.3
15.277,-3.1671,-10.20672,1.020672,0,0,0,0,0,3.1671,3.1671,10.20672,3.218337,-3.1671,988346.5
15.377,-3.184725,-10.32875,1.032876,0,0,0,0,0,3.184725,3.184725,10.32875,3.236541,-3.184725,999981.2
15.477,-3.2007,-10.45403,1.045403,0,0,0,0,0,3.2007,3.2007,10.45403,3.253042,-3.2007,1011943
15.577,-3.218325,-9.317249,0.9317249,0,0,0,0,0,3.218325,3.218325,9.317249,3.271252,-3.218325,901739
15.677,-3.23325,-9.658888,0.9658888,0,0,0,0,0,3.23325,3.23325,9.658888,3.286674,-3.23325,934659.2
15.777,-3.251475,-9.872273,0.9872273,0,0,0,0,0,3.251475,3.251475,9.872272,3.30551,-3.251475,955127.8
15.877,-3.267225,-10.18663,1.018663,0,0,0,0,0,3.267225,3.267225,10.18663,3.321791,-3.267225,985380.7
15.977,-3.2844,-10.45827,1.045827,0,0,0,0,0,3.2844,3.2844,10.45827,3.339547,-3.2844,1011478
16.077,-3.300825,-9.874597,0.9874597,0,0,0,0,0,3.300825,3.300825,9.874598,3.356532,-3.300825,954865.4
16.177,-3.318225,-9.849899,0.9849899,0,0,0,0,0,3.318225,3.318225,9.849898,3.374527,-3.318225,952305.7
16.277,-3.3339,-9.776458,0.9776458,0,0,0,0,0,3.3339,3.3339,9.776458,3.390742,-3.3339,945052.1
16.377,-3.3519,-9.725697,0.9725697,0,0,0,0,0,3.3519,3.3519,9.725698,3.409364,-3.3519,939970.2
16.477,-3.36735,-9.533189,0.953319,0,0,0,0,0,3.36735,3.36735,9.533189,3.425351,-3.36735,921217.3
16.577,-3.3849,-9.677365,0.9677365,0,0,0,0,0,3.3849,3.3849,9.677365,3.443514,-3.3849,934979.6
16.677,-3.400275,-9.874463,0.9874463,0,0,0,0,0,3.400275,3.400275,9.874463,3.459429,-3.400275,953870.4
16.777,-3.41805,-10.18453,1.018453,0,0,0,0,0,3.41805,3.41805,10.18453,3.477832,-3.41805,983641.4
16.877,-3.4341,-10.03301,1.003301,0,0,0,0,0,3.4341,3.4341,10.03301,3.494451,-3.4341,968846.8
16.977,-3.450975,-9.027891,0.9027891,0,0,0,0,0,3.450975,3.450975,9.027891,3.511928,-3.450975,871634.1
17.077,-3.46725,-9.341389,0.9341389,0,0,0,0,0,3.46725,3.46725,9.341389,3.528786,-3.46725,901750
17.177,-3.484875,-9.491809,0.9491808,0,0,0,0,0,3.484875,3.484875,9.491809,3.547046,-3.484875,916103.1
17.277,-3.5004,-9.53605,0.9536051,0,0,0,0,0,3.5004,3.5004,9.53605,3.563132,-3.5004,920225
17.377,-3.518625,-9.494975,0.9494975,0,0,0,0,0,3.518625,3.518625,9.494975,3.58202,-3.518625,916088.3
17.477,-3.5337,-9.436384,0.9436384,0,0,0,0,0,3.5337,3.5337,9.436384,3.597646,-3.5337,910293
17.577,-3.55125,-9.417228,0.9417229,0,0,0,0,0,3.55125,3.55125,9.417229,3.615841,-3.55125,908279.9
17.677,-3.566925,-8.951731,0.8951731,0,0,0,0,0,3.566925,3.566925,8.951731,3.632094,-3.566925,863242.9
17.777,-3.584775,-9.12077,0.912077,0,0,0,0,0,3.584775,3.584775,9.12077,3.650606,-3.584775,879381.1
17.877,-3.600675,-9.394467,0.9394466,0,0,0,0,0,3.600675,3.600675,9.394466,3.667099,-3.600675,905620.2
17.977,-3.617325,-9.787157,0.9787157,0,0,0,0,0,3.617325,3.617325,9.787157,3.684372,-3.617325,943312.4
18.077,-3.6336,-9.378389,0.9378389,0,0,0,0,0,3.6336,3.6336,9.378388,3.701259,-3.6336,903761.5
18.177,-3.651975,-9.872206,0.9872205,0,0,0,0,0,3.651975,3.651975,9.872206,3.720329,-3.651975,951167.5
18.277,-3.6669,-10.18763,1.018763,0,0,0,0,0,3.6669,3.6669,10.18763,3.735821,-3.6669,981406.3
18.377,-3.6855,-10.64933,1.064933,0,0,0,0,0,3.6855,3.6855,10.64933,3.755131,-3.6855,1025685
18.477,-3.7005,-10.8512,1.08512,0,0,0,0,0,3.7005,3.7005,10.8512,3.770706,-3.7005,1044965
18.577,-3.718275,-11.0054,1.10054,0,0,0,0,0,3.718275,3.718275,11.0054,3.789166,-3.718275,1059619
18.677,-3.73425,-11.15932,1.115932,0,0,0,0,0,3.73425,3.73425,11.15932,3.805759,-3.73425,1074260
18.777,-3.751575,-11.24778,1.124778,0,0,0,0,0,3.751575,3.751575,11.24778,3.823758,-3.751575,1082581
18.877,-3.767175,-11.383,1.1383,0,0,0,0,0,3.767175,3.767175,11.383,3.839967,-3.767175,1095418
18.977,-3.784725,-11.46599,1.146599,0,0,0,0,0,3.784725,3.784725,11.46599,3.858206,-3.784725,1103203
19.054,-3.797025,-8.920737,0.8920736,0,0,0,0,0,3.797025,3.797025,8.920736,3.870991,-3.797025,858201.4
19.089,-3.80265,-6.417841,0.6417841,0,0,0,0,0,3.80265,3.80265,6.417841,3.876838,-3.80265,617379.3
19.189,-3.82065,-6.688684,0.6688685,0,0,0,0,0,3.82065,3.82065,6.688684,3.895551,-3.82065,643313.3
19.289,-3.83535,-6.949335,0.6949335,0,0,0,0,0,3.83535,3.83535,6.949335,3.910836,-3.83535,668280.4
19.389,-3.85365,-7.368818,0.7368818,0,0,0,0,0,3.85365,3.85365,7.368818,3.929868,-3.85365,708484.9
19.489,-3.86925,-8.067124,0.8067124,0,0,0,0,0,3.86925,3.86925,8.067123,3.946094,-3.86925,775498.6
19.589,-3.8865,-8.890413,0.8890413,0,0,0,0,0,3.8865,3.8865,8.890412,3.96404,-3.8865,854488.7
19.689,-3.9027,-9.252198,0.9252198,0,0,0,0,0,3.9027,3.9027,9.252198,3.980897,-3.9027,889111.3
19.789,-3.92055,-9.402595,0.9402596,0,0,0,0,0,3.92055,3.92055,9.402596,3.999473,-3.92055,903396.2
19.889,-3.9357,-9.897508,0.9897507,0,0,0,0,0,3.9357,3.9357,9.897508,4.015243,-3.9357,950797.1
19.989,-3.954375,-10.41814,1.041814,0,0,0,0,0,3.954375,3.954375,10.41814,4.034685,-3.954375,1000617
20.089,-3.969375,-10.34058,1.034058,0,0,0,0,0,3.969375,3.969375,10.34058,4.050304,-3.969375,993012.2
20.189,-3.987,-10.70507,1.070507,0,0,0,0,0,3.987,3.987,10.70507,4.068659,-3.987,1027826
20.289,-4.002525,-10.9673,1.09673,0,0,0,0,0,4.002525,4.002525,10.9673,4.08483,-4.002525,1052833
20.389,-4.0203,-10.45725,1.045725,0,0,0,0,0,4.0203,4.0203,10.45726,4.103348,-4.0203,1003684
20.489,-4.0362,-10.61863,1.061863,0,0,0,0,0,4.0362,4.0362,10.61863,4.119915,-4.0362,1019005
20.589,-4.053225,-10.7417,1.07417,0,0,0,0,0,4.053225,4.053225,10.7417,4.137657,-4.053225,1030632
20.689,-4.0695,-10.66955,1.066955,0,0,0,0,0,4.0695,4.0695,10.66955,4.154622,-4.0695,1023535
20.789,-4.08735,-10.66943,1.066942,0,0,0,0,0,4.08735,4.08735,10.66943,4.173231,-4.08735,1023333
20.889,-4.10235,-10.76585,1.076585,0,0,0,0,0,4.10235,4.10235,10.76585,4.188871,-4.10235,1032420
20.989,-4.12065,-11.04993,1.104993,0,0,0,0,0,4.12065,4.12065,11.04993,4.207956,-4.12065,1059460
21.089,-4.135875,-11.12051,1.112051,0,0,0,0,0,4.135875,4.135875,11.12051,4.223836,-4.135875,1066058
21.189,-4.15335,-11.15789,1.115788,0,0,0,0,0,4.15335,4.15335,11.15789,4.242067,-4.15335,1069446
21.289,-4.169475,-10.05588,1.005589,0,0,0,0,0,4.169475,4.169475,10.05588,4.258892,-4.169475,963660.7
21.389,-4.186875,-10.51266,1.051266,0,0,0,0,0,4.186875,4.186875,10.51266,4.277051,-4.186875,1007251
21.489,-4.20255,-10.80033,1.080033,0,0,0,0,0,4.20255,4.20255,10.80033,4.293412,-4.20255,1034644
21.589,-4.220025,-11.13446,1.113446,0,0,0,0,0,4.220025,4.220025,11.13446,4.311655,-4.220025,1066458
21.689,-4.236,-10.72706,1.072706,0,0,0,0,0,4.236,4.236,10.72706,4.328336,-4.236,1027266
21.789,-4.253925,-10.68611,1.068611,0,0,0,0,0,4.253925,4.253925,10.68611,4.347055,-4.253925,1023153
21.889,-4.268775,-9.022005,0.9022005,0,0,0,0,0,4.268775,4.268775,9.022005,4.362567,-4.268775,863687.6
21.989,-4.28745,-9.866573,0.9866573,0,0,0,0,0,4.28745,4.28745,9.866573,4.382076,-4.28745,944354.9
22.089,-4.30275,-10.10579,1.010579,0,0,0,0,0,4.30275,4.30275,10.10579,4.398063,-4.30275,967096.3
22.189,-4.319925,-10.38381,1.038381,0,0,0,0,0,4.319925,4.319925,10.38381,4.416012,-4.319925,993523.4
22.289,-4.33635,-10.70976,1.070976,0,0,0,0,0,4.33635,4.33635,10.70976,4.433179,-4.33635,1024535
22.389,-4.3536,-10.74851,1.074851,0,0,0,0,0,4.3536,4.3536,10.74851,4.451213,-4.3536,1028056
22.489,-4.369125,-10.6441,1.06441,0,0,0,0,0,4.369125,4.369125,10.6441,4.467446,-4.369125,1017905
22.589,-4.3872,-9.988613,0.9988613,0,0,0,0,0,4.3872,4.3872,9.988613,4.486349,-4.3872,955039.3
22.689,-4.40265,-9.111822,0.9111823,0,0,0,0,0,4.40265,4.40265,9.111822,4.502509,-4.40265,871066.1
22.789,-4.420425,-9.604469,0.9604469,0,0,0,0,0,4.420425,4.420425,9.604469,4.521104,-4.420425,917991.1
22.889,-4.435425,-9.959385,0.9959385,0,0,0,0,0,4.435425,4.435425,9.959385,4.536799,-4.435425,951764.4
22.989,-4.453425,-10.05244,1.005244,0,0,0,0,0,4.453425,4.453425,10.05244,4.555636,-4.453425,960476.5
23.089,-4.469475,-9.487256,0.9487256,0,0,0,0,0,4.469475,4.469475,9.487256,4.572436,-4.469475,906322.6
23.189,-4.48665,-10.12563,1.012563,0,0,0,0,0,4.48665,4.48665,10.12563,4.590416,-4.48665,967132.8
23.289,-4.502775,-10.19674,1.019674,0,0,0,0,0,4.502775,4.502775,10.19674,4.6073,-4.502775,973760.2
23.389,-4.52055,-10.26206,1.026206,0,0,0,0,0,4.52055,4.52055,10.26206,4.625915,-4.52055,979816.3
23.489,-4.5357,-10.21027,1.021027,0,0,0,0,0,4.5357,4.5357,10.21027,4.641783,-4.5357,974716.1
23.589,-4.554225,-10.37101,1.037102,0,0,0,0,0,4.554225,4.554225,10.37101,4.66119,-4.554225,989869.5
23.689,-4.569525,-10.40102,1.040102,0,0,0,0,0,4.569525,4.569525,10.40102,4.677222,-4.569525,992574.1
23.789,-4.587,-10.52895,1.052895,0,0,0,0,0,4.587,4.587,10.52895,4.695535,-4.587,1004599
23.889,-4.602525,-10.57368,1.057368,0,0,0,0,0,4.602525,4.602525,10.57368,4.711808,-4.602525,1008702
23.989,-4.620375,-10.57755,1.057755,0,0,0,0,0,4.620375,4.620375,10.57755,4.730521,-4.620375,1008883
24.089,-4.636275,-10.68091,1.068091,0,0,0,0,0,4.636275,4.636275,10.68091,4.747192,-4.636275,1018572
24.189,-4.65315,-10.68371,1.068371,0,0,0,0,0,4.65315,4.65315,10.68371,4.764889,-4.65315,1018658
24.289,-4.6695,-10.60664,1.060664,0,0,0,0,0,4.6695,4.6695,10.60664,4.782039,-4.6695,1011136
24.389,-4.687125,-10.13127,1.013127,0,0,0,0,0,4.687125,4.687125,10.13127,4.800529,-4.687125,965640.4
24.489,-4.702275,-9.879559,0.9879559,0,0,0,0,0,4.702275,4.702275,9.87956,4.816425,-4.702275,941499.5
24.589,-4.7208,-9.974979,0.9974979,0,0,0,0,0,4.7208,4.7208,9.974978,4.835866,-4.7208,950408
24.689,-4.73595,-9.818435,0.9818435,0,0,0,0,0,4.73595,4.73595,9.818435,4.851768,-4.73595,935343.9
24.789,-4.7535,-9.954758,0.9954758,0,0,0,0,0,4.7535,4.7535,9.954758,4.870192,-4.7535,948155.9
24.889,-4.769175,-10.06337,1.006336,0,0,0,0,0,4.769176,4.769176,10.06336,4.886651,-4.769175,958342.6
24.989,-4.787025,-10.07007,1.007007,0,0,0,0,0,4.787025,4.787025,10.07007,4.905396,-4.787025,958801.4
25.018,-4.791825,-7.507332,0.7507331,0,0,0,0,0,4.791825,4.791825,7.507332,4.910438,-4.791825,714759.3
25.118,-4.80735,-7.00096,0.700096,0,0,0,0,0,4.80735,4.80735,7.00096,4.926746,-4.80735,666440
25.218,-4.825575,-7.17517,0.717517,0,0,0,0,0,4.825575,4.825575,7.17517,4.945893,-4.825575,682892.7
25.318,-4.840875,-7.103115,0.7103115,0,0,0,0,0,4.840875,4.840875,7.103115,4.96197,-4.840875,675926.2
25.418,-4.858725,-7.041439,0.7041439,0,0,0,0,0,4.858725,4.858725,7.04144,4.98073,-4.858725,669931.5
25.518,-4.874025,-7.12432,0.712432,0,0,0,0,0,4.874025,4.874025,7.12432,4.996812,-4.874025,677707.9
25.618,-4.89165,-7.223278,0.7223278,0,0,0,0,0,4.89165,4.89165,7.223278,5.015342,-4.89165,686994
25.718,-4.907925,-7.199571,0.7199571,0,0,0,0,0,4.907925,4.907925,7.199571,5.032455,-4.907925,684622.1
25.818,-4.92405,-7.201396,0.7201396,0,0,0,0,0,4.92405,4.92405,7.201396,5.049414,-4.92405,684679.6
25.918,-4.941,-7.314429,0.7314429,0,0,0,0,0,4.941,4.941,7.314429,5.067244,-4.941,695302.3
26.018,-4.95855,-7.257938,0.7257938,0,0,0,0,0,4.95855,4.95855,7.257938,5.085707,-4.95855,689805
26.118,-4.974075,-7.310495,0.7310495,0,0,0,0,0,4.974075,4.974075,7.310495,5.102044,-4.974075,694686.5
26.218,-4.991925,-7.401057,0.7401056,0,0,0,0,0,4.991925,4.991925,7.401057,5.12083,-4.991925,703160.1
26.318,-5.0076,-7.323243,0.7323242,0,0,0,0,0,5.0076,5.0076,7.323243,5.13733,-5.0076,695652.4
26.357,-5.014725,-7.376917,0.7376916,0,0,0,0,0,5.014725,5.014725,7.376917,5.144831,-5.014725,700698.5
"Specimen",2
"Specimen label",""
"Width",10.000000,"mm"
"Thickness",1.000000,"mm"
"Anvil height",100.000000,"mm"
"Diameter",10.000000,"mm"
"Inner diameter",8.000000,"mm"
"Outer diameter",10.000000,"mm"
"Wall thickness",1.000000,"mm"
"Area",0.100000,"cm^2"
"Linear density",100.000000,"tex"
"Sled weight",10.000000,"N"
"Loading span",10.000000,"mm"
"Support span",100.000000,"mm"
"Span ratio","2"
"Fixture type","4-point"
"Included"
"Final width",10.000000,"mm"
"Final thickness",1.000000,"mm"
"Final anvil height",100.000000,"mm"
"Final diameter",10.000000,"mm"
"Final Inner diameter",8.000000,"mm"
"Final outer diameter",10.000000,"mm"
"Final wall thickness",1.000000,"mm"
"Final area",0.100000,"cm^2"
"Final linear density",100.000000,"tex"
"Custom text input  1",""
"Custom text input  2",""
"Custom text input  3",""
"Custom text input  4",""
"Custom text input  5",""
"Custom text input  6",""
"Custom text input  7",""
"Custom text input  8",""
"Custom text input  9",""
"Custom text input 10",""
"Custom text input 11",""
"Custom text input 12",""
"Custom text input 13",""
"Custom text input 14",""
"Custom text input 15",""
"Custom text input 16",""
"Custom text input 17",""
"Custom text input 18",""
"Custom text input 19",""
"Custom text input 20",""
"Custom text input 21",""
"Custom text input 22",""
"Custom text input 23",""
"Custom text input 24",""
"Custom text input 25",""
"Custom text input 26",""
"Custom text input 27",""
"Custom text input 28",""
"Custom text input 29",""
"Custom text input 30",""
"Custom text input 31",""
"Custom text input 32",""
"Custom text input 33",""
"Custom text input 34",""
"Custom text input 35",""
"Custom text input 36",""
"Custom text input 37",""
"Custom text input 38",""
"Custom text input 39",""
"Custom text input 40",""
"Custom text input 41",""
"Custom text input 42",""
"Custom text input 43",""
"Custom text input 44",""
"Custom text input 45",""
"Custom text input 46",""
"Custom text input 47",""
"Custom text input 48",""
"Custom text input 49",""
"Custom text input 50",""
"Custom number input  1",0.000000,""
"Custom number input  2",0.000000,""
"Custom number input  3",0.000000,""
"Custom number input  4",0.000000,""
"Custom number input  5",0.000000,""
"Custom number input  6",0.000000,""
"Custom number input  7",0.000000,""
"Custom number input  8",0.000000,""
"Custom number input  9",0.000000,""
"Custom number input 10",0.000000,""
"Time sec","Extension mm","Load N","Compressive stress MPa","Cycle Count ","Total Cycle Count ","Repetitions Count ","Marked Data ","PIP Count ","Compressive extension mm","Compressive strain %","Compressive load N","True strain %","Corrected Position mm","True stress Pa"
0,-0.37995,-0.5536601,0.05536601,0,0,0,0,0,0.37995,0.37995,0.5536601,0.3806737,-0.37995,55155.65
0.1,-0.385425,-2.460927,0.2460927,0,0,0,0,0,0.385425,0.385425,2.460927,0.3861697,-0.385425,245144.2
0.158,-0.40065,-5.032964,0.5032964,0,0,0,0,0,0.40065,0.40065,5.032964,0.4014548,-0.40065,501279.9
0.202,-0.4101,-7.552564,0.7552564,0,0,0,0,0,0.4101,0.4101,7.552564,0.4109432,-0.4101,752159.1
0.296,-0.426975,-10.07383,1.007383,0,0,0,0,0,0.426975,0.426975,10.07383,0.4278892,-0.426975,1003082
0.396,-0.443625,-11.89249,1.189249,0,0,0,0,0,0.443625,0.443625,11.89249,0.4446119,-0.443625,1183973
0.496,-0.4608,-13.09653,1.309653,0,0,0,0,0,0.4608,0.4608,13.09653,0.461865,-0.4608,1303618
0.596,-0.477075,-14.80156,1.480156,0,0,0,0,0,0.477075,0.477075,14.80156,0.4782167,-0.477075,1473095
0.6780001,-0.49125,-17.34297,1.734297,0,0,0,0,0,0.49125,0.49125,17.34297,0.4924606,-0.49125,1725777
0.7450001,-0.501375,-19.87572,1.987572,0,0,0,0,0,0.501375,0.501375,19.87572,0.5026361,-0.501375,1977607
0.8440001,-0.51945,-22.37719,2.237719,0,0,0,0,0,0.51945,0.51945,22.37719,0.5208038,-0.51945,2226095
0.924,-0.5313,-24.90407,2.490407,0,0,0,0,0,0.5313,0.5313,24.90407,0.5327164,-0.5313,2477176
0.984,-0.54165,-27.43622,2.743622,0,0,0,0,0,0.54165,0.54165,27.43622,0.5431222,-0.54165,2728761
1.057,-0.554025,-29.94252,2.994252,0,0,0,0,0,0.554025,0.554025,29.94252,0.5555654,-0.554025,2977663
1.139,-0.567,-32.45794,3.245794,0,0,0,0,0,0.567,0.567,32.45794,0.5686136,-0.567,3227390
1.188,-0.57555,-34.97864,3.497864,0,0,0,0,0,0.57555,0.57555,34.97863,0.5772127,-0.57555,3477732
1.246,-0.585825,-37.50175,3.750175,0,0,0,0,0,0.585825,0.585825,37.50175,0.5875477,-0.585825,3728206
1.313,-0.5964,-40.01782,4.001782,0,0,0,0,0,0.5964,0.5964,40.01782,0.5981856,-0.5964,3977915
1.413,-0.612675,-40.82166,4.082166,0,0,0,0,0,0.612675,0.612675,40.82166,0.6145596,-0.612675,4057156
1.513,-0.62985,-40.83624,4.083624,0,0,0,0,0,0.62985,0.62985,40.83625,0.6318419,-0.62985,4057904
1.613,-0.646875,-40.47097,4.047097,0,0,0,0,0,0.646875,0.646875,40.47097,0.6489763,-0.646875,4020918
1.713,-0.663,-39.88574,3.988574,0,0,0,0,0,0.663,0.663,39.88574,0.6652077,-0.663,3962129
1.813,-0.68055,-39.92368,3.992368,0,0,0,0,0,0.68055,0.68055,39.92368,0.6828763,-0.68055,3965198
1.913,-0.6963,-40.90957,4.090957,0,0,0,0,0,0.6963,0.6963,40.90957,0.6987355,-0.6963,4062472
2.013,-0.713325,-43.26008,4.326008,0,0,0,0,0,0.713325,0.713325,43.26008,0.7158814,-0.713325,4295150
2.113,-0.73005,-41.59595,4.159595,0,0,0,0,0,0.73005,0.73005,41.59595,0.7327279,-0.73005,4129228
2.117,-0.730875,-38.35583,3.835583,0,0,0,0,0,0.730875,0.730875,38.35583,0.733559,-0.730875,3807550
2.121,-0.7317,-35.20933,3.520933,0,0,0,0,0,0.7317001,0.7317001,35.20933,0.7343901,-0.7317,3495170
2.124,-0.7323,-32.61982,3.261982,0,0,0,0,0,0.7323,0.7323,32.61982,0.7349945,-0.7323,3238094
2.128,-0.733125,-29.47991,2.947991,0,0,0,0,0,0.733125,0.733125,29.47991,0.7358256,-0.733125,2926378
2.132,-0.733875,-26.4409,2.64409,0,0,0,0,0,0.733875,0.733875,26.4409,0.7365811,-0.733875,2624686
2.136,-0.734625,-23.5458,2.35458,0,0,0,0,0,0.734625,0.734625,23.5458,0.7373367,-0.734625,2337283
2.14,-0.735375,-20.76615,2.076615,0,0,0,0,0,0.735375,0.735375,20.76615,0.7380923,-0.735375,2061344
2.144,-0.73605,-18.19289,1.819288,0,0,0,0,0,0.73605,0.73605,18.19289,0.7387722,-0.73605,1805898
2.149,-0.7368,-15.38883,1.538883,0,0,0,0,0,0.7368,0.7368,15.38883,0.7395278,-0.7368,1527545
2.155,-0.7377,-12.66066,1.266066,0,0,0,0,0,0.7377,0.7377,12.66066,0.7404345,-0.7377,1256726
2.163,-0.738825,-10.04761,1.004761,0,0,0,0,0,0.738825,0.738825,10.04761,0.7415678,-0.738825,997337.3
2.263,-0.755775,-10.65091,1.065091,0,0,0,0,0,0.755775,0.755775,10.65091,0.7586455,-0.755775,1057041
2.363,-0.7713001,-10.043,1.0043,0,0,0,0,0,0.7713001,0.7713001,10.043,0.77429,-0.7713001,996554.1
2.463,-0.789225,-11.40602,1.140602,0,0,0,0,0,0.789225,0.789225,11.40602,0.7923559,-0.789225,1131600
2.563,-0.8046,-12.2382,1.22382,0,0,0,0,0,0.8046,0.8046,12.2382,0.8078544,-0.8046,1213973
2.663,-0.82215,-12.88623,1.288623,0,0,0,0,0,0.8221501,0.8221501,12.88623,0.8255483,-0.82215,1278028
2.763,-0.837525,-13.30702,1.330702,0,0,0,0,0,0.837525,0.837525,13.30702,0.841052,-0.837525,1319557
2.863,-0.8551501,-13.98327,1.398327,0,0,0,0,0,0.85515,0.85515,13.98327,0.8588274,-0.8551501,1386369
2.963,-0.8715001,-14.63417,1.463417,0,0,0,0,0,0.8715001,0.8715001,14.63417,0.8753198,-0.8715001,1450663
3.063,-0.8883,-15.41155,1.541155,0,0,0,0,0,0.8883,0.8883,15.41155,0.8922689,-0.8883,1527465
3.163,-0.90465,-16.05499,1.605499,0,0,0,0,0,0.90465,0.90465,16.05499,0.9087668,-0.90465,1590975
3.263,-0.92265,-16.65103,1.665103,0,0,0,0,0,0.92265,0.92265,16.65103,0.9269328,-0.92265,1649740
3.363,-0.937725,-17.16509,1.716509,0,0,0,0,0,0.937725,0.937725,17.16509,0.9421493,-0.937725,1700413
3.463,-0.9561001,-17.92867,1.792867,0,0,0,0,0,0.9561,0.9561,17.92867,0.9607,-0.9561001,1775726
3.527,-0.965325,-15.32716,1.532716,0,0,0,0,0,0.9653251,0.9653251,15.32716,0.9700145,-0.965325,1517920
3.592,-0.976725,-12.76866,1.276866,0,0,0,0,0,0.976725,0.976725,12.76866,0.9815263,-0.976725,1264395
3.615,-0.9808501,-10.24339,1.024339,0,0,0,0,0,0.9808501,0.9808501,10.24339,0.9856921,-0.9808501,1014292
3.634,-0.98415,-7.616274,0.7616274,0,0,0,0,0,0.98415,0.98415,7.616274,0.9890248,-0.98415,754131.8
3.734,-0.9993,-5.915038,0.5915039,0,0,0,0,0,0.9993001,0.9993001,5.915038,1.004327,-0.9993,585592.9
3.834,-1.017075,-6.309718,0.6309718,0,0,0,0,0,1.017075,1.017075,6.309718,1.022283,-1.017075,624554.4
3.934,-1.0335,-6.311461,0.6311461,0,0,0,0,0,1.0335,1.0335,6.311461,1.038878,-1.0335,624623.2
4.034,-1.050075,-6.77073,0.677073,0,0,0,0,0,1.050075,1.050075,6.77073,1.055627,-1.050075,669963.2
4.134,-1.066575,-7.076576,0.7076576,0,0,0,0,0,1.066575,1.066575,7.076576,1.072304,-1.066575,700109.9
4.234,-1.083825,-7.43448,0.743448,0,0,0,0,0,1.083825,1.083825,7.43448,1.089741,-1.083825,735390.3
4.334,-1.099575,-7.689737,0.7689737,0,0,0,0,0,1.099575,1.099575,7.689737,1.105665,-1.099575,760518.2
4.434,-1.117575,-8.065715,0.8065715,0,0,0,0,0,1.117575,1.117575,8.065716,1.123867,-1.117575,797557.5
4.534,-1.132725,-8.639179,0.8639179,0,0,0,0,0,1.132725,1.132725,8.639179,1.139189,-1.132725,854132.1
4.634,-1.150125,-9.453267,0.9453267,0,0,0,0,0,1.150125,1.150125,9.453267,1.15679,-1.150125,934454.2
4.734,-1.166025,-10.21006,1.021006,0,0,0,0,0,1.166025,1.166025,10.21006,1.172876,-1.166025,1009101
4.834,-1.18365,-11.18475,1.118475,0,0,0,0,0,1.18365,1.18365,11.18475,1.190711,-1.18365,1105236
4.934,-1.1997,-12.05827,1.205827,0,0,0,0,0,1.1997,1.1997,12.05827,1.206955,-1.1997,1191361
5.034,-1.216275,-12.98966,1.298965,0,0,0,0,0,1.216275,1.216275,12.98966,1.223732,-1.216275,1283167
5.134,-1.233,-13.8798,1.38798,0,0,0,0,0,1.233,1.233,13.8798,1.240665,-1.233,1370866
5.234,-1.2507,-14.93511,1.493511,0,0,0,0,0,1.2507,1.2507,14.93511,1.258587,-1.2507,1474831
5.334,-1.266075,-16.20343,1.620343,0,0,0,0,0,1.266075,1.266075,16.20343,1.274158,-1.266075,1599828
[...]
"Final Inner diameter",8.000000,"mm"
"Final outer diameter",10.000000,"mm"
"Final wall thickness",1.000000,"mm"
"Final area",0.100000,"cm^2"
"Final linear density",100.000000,"tex"
"Custom text input  1",""
"Custom text input  2",""
"Custom text input  3",""
"Custom text input  4",""
"Custom text input  5",""
"Custom text input  6",""
"Custom text input  7",""
"Custom text input  8",""
"Custom text input  9",""
"Custom text input 10",""
"Custom text input 11",""
"Custom text input 12",""
"Custom text input 13",""
"Custom text input 14",""
"Custom text input 15",""
"Custom text input 16",""
"Custom text input 17",""
"Custom text input 18",""
"Custom text input 19",""
"Custom text input 20",""
"Custom text input 21",""
"Custom text input 22",""
"Custom text input 23",""
"Custom text input 24",""
"Custom text input 25",""
"Custom text input 26",""
"Custom text input 27",""
"Custom text input 28",""
"Custom text input 29",""
"Custom text input 30",""
"Custom text input 31",""
"Custom text input 32",""
"Custom text input 33",""
"Custom text input 34",""
"Custom text input 35",""
"Custom text input 36",""
"Custom text input 37",""
"Custom text input 38",""
"Custom text input 39",""
"Custom text input 40",""
"Custom text input 41",""
"Custom text input 42",""
"Custom text input 43",""
"Custom text input 44",""
"Custom text input 45",""
"Custom text input 46",""
"Custom text input 47",""
"Custom text input 48",""
"Custom text input 49",""
"Custom text input 50",""
"Custom number input  1",0.000000,""
"Custom number input  2",0.000000,""
"Custom number input  3",0.000000,""
"Custom number input  4",0.000000,""
"Custom number input  5",0.000000,""
"Custom number input  6",0.000000,""
"Custom number input  7",0.000000,""
"Custom number input  8",0.000000,""
"Custom number input  9",0.000000,""
"Custom number input 10",0.000000,""
"Time sec","Extension mm","Load N","Compressive stress MPa","Cycle Count ","Total Cycle Count ","Repetitions Count ","Marked Data ","PIP Count ","Compressive extension mm","Compressive strain %","Compressive load N","True strain %","Corrected Position mm","True stress Pa"
0,-0.381975,-0.5486906,0.05486906,0,0,0,0,0,0.381975,0.381975,0.5486906,0.3827064,-0.381975,54659.47
0.1,-0.386475,-2.509646,0.2509646,0,0,0,0,0,0.386475,0.386475,2.509646,0.3872237,-0.386475,249994.7
0.162,-0.404475,-5.07585,0.5075849,0,0,0,0,0,0.404475,0.404475,5.07585,0.4052952,-0.404475,505531.9
0.2,-0.41145,-7.611118,0.7611119,0,0,0,0,0,0.41145,0.41145,7.611118,0.4122988,-0.41145,757980.2
0.261,-0.422475,-10.11914,1.011914,0,0,0,0,0,0.422475,0.422475,10.11914,0.42337,-0.422475,1007639
0.325,-0.433275,-12.62933,1.262933,0,0,0,0,0,0.433275,0.433275,12.62933,0.4342164,-0.433275,1257461
0.386,-0.44445,-15.13225,1.513225,0,0,0,0,0,0.44445,0.44445,15.13225,0.4454406,-0.44445,1506499
0.457,-0.4551,-17.63245,1.763245,0,0,0,0,0,0.4551,0.4551,17.63245,0.4561387,-0.4551,1755221
0.527,-0.466875,-20.17,2.016999,0,0,0,0,0,0.466875,0.466875,20.17,0.4679683,-0.466875,2007583
0.586,-0.47775,-22.70968,2.270968,0,0,0,0,0,0.47775,0.47775,22.70968,0.4788949,-0.47775,2260119
0.656,-0.488325,-25.2374,2.52374,0,0,0,0,0,0.488325,0.488325,25.2374,0.4895212,-0.488325,2511416
0.72,-0.4995,-27.74873,2.774873,0,0,0,0,0,0.4995,0.4995,27.74873,0.5007517,-0.4995,2761012
0.777,-0.5094,-30.25025,3.025025,0,0,0,0,0,0.5094,0.5094,30.25025,0.5107019,-0.5094,3009616
0.8470001,-0.519675,-32.75418,3.275418,0,0,0,0,0,0.519675,0.519675,32.75418,0.52103,-0.519675,3258396
0.9070001,-0.53055,-35.27144,3.527143,0,0,0,0,0,0.53055,0.53055,35.27143,0.5319624,-0.53055,3508430
0.9650001,-0.54075,-37.79452,3.779452,0,0,0,0,0,0.54075,0.54075,37.79452,0.5422174,-0.54075,3759015
1.027,-0.550125,-40.309,4.0309,0,0,0,0,0,0.550125,0.550125,40.309,0.5516438,-0.550125,4008725
1.09,-0.560625,-42.81396,4.281396,0,0,0,0,0,0.5606251,0.5606251,42.81396,0.5622024,-0.560625,4257394
1.15,-0.570825,-45.35137,4.535137,0,0,0,0,0,0.570825,0.570825,45.35137,0.5724604,-0.570825,4509249
1.21,-0.58095,-47.86192,4.786192,0,0,0,0,0,0.58095,0.58095,47.86192,0.5826441,-0.58095,4758387
1.273,-0.59145,-50.39588,5.039587,0,0,0,0,0,0.59145,0.59145,50.39588,0.593206,-0.59145,5009781
1.336,-0.6021,-52.93028,5.293028,0,0,0,0,0,0.6021,0.6021,52.93028,0.6039199,-0.6021,5261159
1.346,-0.6042,-49.82693,4.982693,0,0,0,0,0,0.6042,0.6042,49.82693,0.6060327,-0.6042,4952587
1.349,-0.60495,-47.06462,4.706462,0,0,0,0,0,0.60495,0.60495,47.06462,0.6067872,-0.60495,4677990
1.352,-0.6057,-43.86123,4.386123,0,0,0,0,0,0.6057,0.6057,43.86123,0.6075418,-0.6057,4359556
1.355,-0.606375,-40.44144,4.044144,0,0,0,0,0,0.606375,0.606375,40.44144,0.608221,-0.606375,4019621
1.358,-0.607125,-36.91318,3.691318,0,0,0,0,0,0.607125,0.607125,36.91318,0.6089755,-0.607125,3668907
1.361,-0.607875,-33.43801,3.343801,0,0,0,0,0,0.607875,0.607875,33.43801,0.6097301,-0.607875,3323475
1.364,-0.60855,-30.1212,3.01212,0,0,0,0,0,0.60855,0.60855,30.1212,0.6104092,-0.60855,2993790
1.367,-0.60915,-26.99845,2.699845,0,0,0,0,0,0.6091501,0.6091501,26.99845,0.6110129,-0.60915,2683399
1.37,-0.60975,-24.15915,2.415915,0,0,0,0,0,0.60975,0.60975,24.15915,0.6116166,-0.60975,2401184
1.373,-0.61035,-21.61167,2.161167,0,0,0,0,0,0.6103501,0.6103501,21.61167,0.6122203,-0.61035,2147976
1.377,-0.611025,-18.67122,1.867122,0,0,0,0,0,0.611025,0.611025,18.67122,0.6128994,-0.611025,1855714
1.382,-0.611775,-15.7468,1.57468,0,0,0,0,0,0.611775,0.611775,15.7468,0.613654,-0.611775,1565047
1.388,-0.6126,-13.23725,1.323725,0,0,0,0,0,0.6126,0.6126,13.23725,0.6144841,-0.6126,1315615
1.401,-0.6141,-10.6573,1.06573,0,0,0,0,0,0.6141,0.6141,10.6573,0.6159934,-0.6141,1059185
1.501,-0.629025,-12.47044,1.247044,0,0,0,0,0,0.629025,0.629025,12.47044,0.6310117,-0.629025,1239200
1.601,-0.64695,-12.83237,1.283237,0,0,0,0,0,0.6469501,0.6469501,12.83237,0.6490519,-0.64695,1274935
1.701,-0.663,-12.95856,1.295856,0,0,0,0,0,0.663,0.663,12.95856,0.6652077,-0.663,1287265
1.801,-0.6795001,-13.12607,1.312607,0,0,0,0,0,0.6795,0.6795,13.12607,0.6818192,-0.6795001,1303688
1.901,-0.696225,-12.62884,1.262884,0,0,0,0,0,0.696225,0.696225,12.62884,0.69866,-0.696225,1254091
2.001,-0.71355,-12.91653,1.291653,0,0,0,0,0,0.71355,0.71355,12.91653,0.716108,-0.71355,1282436
2.101,-0.72915,-13.07716,1.307716,0,0,0,0,0,0.72915,0.72915,13.07716,0.7318213,-0.72915,1298181
2.201,-0.746775,-13.10825,1.310825,0,0,0,0,0,0.746775,0.746775,13.10825,0.7495773,-0.746775,1301036
2.301,-0.7626,-13.08991,1.308991,0,0,0,0,0,0.7626001,0.7626001,13.08991,0.7655227,-0.7626,1299009
2.381,-0.777,-10.51287,1.051287,0,0,0,0,0,0.777,0.777,10.51287,0.7800344,-0.777,1043118
2.481,-0.792,-8.895151,0.8895152,0,0,0,0,0,0.7920001,0.7920001,8.895151,0.795153,-0.792,882470.2
2.581,-0.809925,-9.278409,0.9278409,0,0,0,0,0,0.809925,0.809925,9.278409,0.8132227,-0.809925,920326.1
2.681,-0.825975,-9.492882,0.9492881,0,0,0,0,0,0.8259751,0.8259751,9.492882,0.8294051,-0.825975,941447.3
2.781,-0.843225,-9.738401,0.9738401,0,0,0,0,0,0.8432251,0.8432251,9.7384,0.8468003,-0.843225,965628.4
2.881,-0.8595751,-9.027541,0.9027539,0,0,0,0,0,0.859575,0.859575,9.02754,0.8632907,-0.8595751,894994.1
2.981,-0.8769,-8.849397,0.8849397,0,0,0,0,0,0.8769,0.8769,8.849398,0.8807674,-0.8769,877179.7
3.081,-0.89295,-9.17314,0.917314,0,0,0,0,0,0.8929501,0.8929501,9.17314,0.8969607,-0.89295,909122.8
3.181,-0.910425,-9.186871,0.9186871,0,0,0,0,0,0.910425,0.910425,9.186872,0.9145947,-0.910425,910323.2
3.281,-0.92595,-9.00539,0.900539,0,0,0,0,0,0.92595,0.92595,9.00539,0.9302636,-0.92595,892200.5
3.381,-0.94365,-8.895323,0.8895323,0,0,0,0,0,0.94365,0.94365,8.895323,0.9481306,-0.94365,881138.2
3.481,-0.9591,-8.808471,0.8808471,0,0,0,0,0,0.9591,0.9591,8.808472,0.963729,-0.9591,872398.9
3.581,-0.976725,-9.045407,0.9045407,0,0,0,0,0,0.976725,0.976725,9.045407,0.9815263,-0.976725,895705.8
3.681,-0.9927,-8.933321,0.8933321,0,0,0,0,0,0.9927,0.9927,8.933321,0.9976601,-0.9927,884464
3.781,-1.009575,-9.063557,0.9063557,0,0,0,0,0,1.009575,1.009575,9.063557,1.014706,-1.009575,897205.3
3.881,-1.026225,-9.054758,0.9054757,0,0,0,0,0,1.026225,1.026225,9.054758,1.031527,-1.026225,896183.5
3.981,-1.04385,-9.154364,0.9154364,0,0,0,0,0,1.04385,1.04385,9.154365,1.049336,-1.04385,905880.7
4.081,-1.059075,-9.09809,0.909809,0,0,0,0,0,1.059075,1.059075,9.09809,1.064723,-1.059075,900173.5
4.181,-1.077075,-9.20777,0.920777,0,0,0,0,0,1.077075,1.077075,9.20777,1.082917,-1.077075,910859.6
4.281,-1.092525,-9.10648,0.910648,0,0,0,0,0,1.092525,1.092525,9.10648,1.098537,-1.092525,900698.9
4.381,-1.109925,-9.249851,0.9249851,0,0,0,0,0,1.109925,1.109925,9.249851,1.116131,-1.109925,914718.5
4.481,-1.125825,-9.228669,0.9228669,0,0,0,0,0,1.125825,1.125825,9.228669,1.13221,-1.125825,912477
4.581,-1.143375,-9.320058,0.9320058,0,0,0,0,0,1.143375,1.143375,9.320058,1.149962,-1.143375,921349.5
4.681,-1.1592,-9.189755,0.9189755,0,0,0,0,0,1.1592,1.1592,9.189754,1.165971,-1.1592,908322.7
4.781,-1.176225,-9.269215,0.9269215,0,0,0,0,0,1.176225,1.176225,9.269216,1.183197,-1.176225,916018.8
4.881,-1.19295,-9.021059,0.9021059,0,0,0,0,0,1.19295,1.19295,9.021059,1.200123,-1.19295,891344.2
4.981,-1.210425,-8.779176,0.8779175,0,0,0,0,0,1.210425,1.210425,8.779176,1.21781,-1.210425,867291
5.081,-1.225725,-9.096444,0.9096442,0,0,0,0,0,1.225725,1.225725,9.096443,1.233299,-1.225725,898494.5
5.181,-1.24395,-9.207554,0.9207554,0,0,0,0,0,1.24395,1.24395,9.207554,1.251752,-1.24395,909301.7
5.281,-1.2594,-9.340659,0.9340659,0,0,0,0,0,1.2594,1.2594,9.340659,1.267398,-1.2594,922302.3
5.381,-1.276425,-9.431288,0.9431288,0,0,0,0,0,1.276425,1.276425,9.431288,1.284641,-1.276425,931090.4
5.481,-1.292775,-9.461232,0.9461231,0,0,0,0,0,1.292775,1.292775,9.461231,1.301204,-1.292775,933891.9
5.581,-1.31025,-9.613357,0.9613358,0,0,0,0,0,1.31025,1.31025,9.613358,1.31891,-1.31025,948739.8
5.681,-1.326075,-9.568088,0.9568088,0,0,0,0,0,1.326075,1.326075,9.568088,1.334946,-1.326075,944120.8
5.781,-1.34325,-9.628586,0.9628587,0,0,0,0,0,1.34325,1.34325,9.628587,1.352353,-1.34325,949925
5.881,-1.35915,-9.698145,0.9698145,0,0,0,0,0,1.35915,1.35915,9.698145,1.368471,-1.35915,956633.3
5.981,-1.377,-9.754054,0.9754055,0,0,0,0,0,1.377,1.377,9.754054,1.386569,-1.377,961974.1
6.081,-1.39215,-9.838492,0.9838492,0,0,0,0,0,1.39215,1.39215,9.838491,1.401931,-1.39215,970152.5
6.181,-1.41,-9.897277,0.9897277,0,0,0,0,0,1.41,1.41,9.897277,1.420035,-1.41,975772.5
6.281,-1.42605,-9.906955,0.9906955,0,0,0,0,0,1.42605,1.42605,9.906955,1.436316,-1.42605,976567.7
6.381,-1.443225,-10.02848,1.002848,0,0,0,0,0,1.443225,1.443225,10.02848,1.453741,-1.443225,988374.8
6.481,-1.4595,-10.01539,1.001539,0,0,0,0,0,1.4595,1.4595,10.01539,1.470256,-1.4595,986921.6
6.581,-1.476675,-9.794742,0.9794742,0,0,0,0,0,1.476675,1.476675,9.794742,1.487686,-1.476675,965010.5
6.681,-1.49295,-9.705402,0.9705402,0,0,0,0,0,1.49295,1.49295,9.705402,1.504207,-1.49295,956050.5
6.781,-1.510575,-9.528197,0.9528197,0,0,0,0,0,1.510575,1.510575,9.528197,1.5221,-1.510575,938426.7
6.881,-1.5261,-9.466052,0.9466052,0,0,0,0,0,1.5261,1.5261,9.466052,1.537865,-1.5261,932159.1
6.981,-1.543725,-9.479649,0.9479649,0,0,0,0,0,1.543725,1.543725,9.47965,1.555765,-1.543725,933331
7.081,-1.559025,-9.489581,0.9489581,0,0,0,0,0,1.559025,1.559025,9.489581,1.571306,-1.559025,934163.6
7.181,-1.5768,-9.628281,0.9628281,0,0,0,0,0,1.5768,1.5768,9.628281,1.589364,-1.5768,947646.2
7.281,-1.592775,-9.486243,0.9486243,0,0,0,0,0,1.592775,1.592775,9.486243,1.605596,-1.592775,933514.9
7.381,-1.60965,-9.319469,0.9319469,0,0,0,0,0,1.60965,1.60965,9.319469,1.622746,-1.60965,916945.8
7.481,-1.626225,-9.176381,0.9176381,0,0,0,0,0,1.626225,1.626225,9.176381,1.639593,-1.626225,902715.2
7.581,-1.64385,-9.171255,0.9171255,0,0,0,0,0,1.64385,1.64385,9.171255,1.657511,-1.64385,902049.3
7.681,-1.658925,-9.155035,0.9155035,0,0,0,0,0,1.658925,1.658925,9.155035,1.672839,-1.658925,900316
7.781,-1.677,-9.217471,0.9217471,0,0,0,0,0,1.677,1.677,9.217471,1.691221,-1.677,906289.4
7.881,-1.692525,-9.332679,0.933268,0,0,0,0,0,1.692525,1.692525,9.332679,1.707012,-1.692525,917472.1
7.981,-1.70985,-8.824535,0.8824534,0,0,0,0,0,1.70985,1.70985,8.824534,1.724637,-1.70985,867364.8
8.081,-1.725825,-8.839339,0.8839339,0,0,0,0,0,1.725825,1.725825,8.839339,1.740891,-1.725825,868678.7
8.181,-1.74315,-8.93268,0.893268,0,0,0,0,0,1.74315,1.74315,8.93268,1.758522,-1.74315,877697
8.281,-1.7592,-9.017266,0.9017266,0,0,0,0,0,1.7592,1.7592,9.017266,1.774858,-1.7592,885863.5
8.381001,-1.77615,-9.121574,0.9121574,0,0,0,0,0,1.77615,1.77615,9.121574,1.792113,-1.77615,895956.2
8.481,-1.79265,-9.21578,0.9215779,0,0,0,0,0,1.79265,1.79265,9.215779,1.808913,-1.79265,905057.3
8.581,-1.810425,-9.301543,0.9301543,0,0,0,0,0,1.810425,1.810425,9.301543,1.827014,-1.810425,913314.6
8.681001,-1.8258,-9.388126,0.9388126,0,0,0,0,0,1.8258,1.8258,9.388126,1.842673,-1.8258,921671.8
8.781,-1.843875,-9.514116,0.9514116,0,0,0,0,0,1.843875,1.843875,9.514115,1.861086,-1.843875,933868.7
8.881001,-1.859475,-9.562284,0.9562284,0,0,0,0,0,1.859475,1.859475,9.562284,1.876981,-1.859475,938447.5
8.981001,-1.876425,-9.580232,0.9580232,0,0,0,0,0,1.876425,1.876425,9.580233,1.894253,-1.876425,940046.6
9.081,-1.89285,-9.641394,0.9641394,0,0,0,0,0,1.89285,1.89285,9.641394,1.910994,-1.89285,945889.7
9.181001,-1.9101,-9.711511,0.9711511,0,0,0,0,0,1.9101,1.9101,9.711512,1.928578,-1.9101,952601.2
9.281,-1.926075,-9.747818,0.9747818,0,0,0,0,0,1.926075,1.926075,9.747818,1.944866,-1.926075,956006.8
9.381001,-1.943475,-9.788387,0.9788387,0,0,0,0,0,1.943475,1.943475,9.788386,1.962609,-1.943475,959815.2
9.481001,-1.95915,-9.809256,0.9809256,0,0,0,0,0,1.95915,1.95915,9.809256,1.978596,-1.95915,961707.8
9.581,-1.977,-9.817772,0.9817772,0,0,0,0,0,1.977,1.977,9.817772,1.996804,-1.977,962367.4
9.681001,-1.99215,-9.868562,0.9868563,0,0,0,0,0,1.99215,1.99215,9.868563,2.012261,-1.99215,967196.7
9.781,-2.00985,-9.945907,0.9945906,0,0,0,0,0,2.00985,2.00985,9.945907,2.030322,-2.00985,974600.9
9.881001,-2.02605,-9.936854,0.9936854,0,0,0,0,0,2.02605,2.02605,9.936854,2.046856,-2.02605,973552.9
9.981001,-2.043,-9.996913,0.9996914,0,0,0,0,0,2.043,2.043,9.996913,2.064158,-2.043,979267.6
10.081,-2.059425,-9.958088,0.9958087,0,0,0,0,0,2.059425,2.059425,9.958088,2.080927,-2.059425,975300.8
10.181,-2.076975,-9.794228,0.9794228,0,0,0,0,0,2.076975,2.076975,9.794228,2.098848,-2.076975,959080.4
10.281,-2.092725,-9.556867,0.9556867,0,0,0,0,0,2.092725,2.092725,9.556868,2.114933,-2.092725,935686.8
10.381,-2.110575,-9.531714,0.9531714,0,0,0,0,0,2.110575,2.110575,9.531714,2.133166,-2.110575,933054
10.481,-2.125875,-9.512961,0.951296,0,0,0,0,0,2.125875,2.125875,9.51296,2.148797,-2.125875,931072.6
10.581,-2.1438,-9.570211,0.9570211,0,0,0,0,0,2.1438,2.1438,9.570211,2.167113,-2.1438,936504.5
10.681,-2.15895,-9.60499,0.9604989,0,0,0,0,0,2.15895,2.15895,9.60499,2.182596,-2.15895,939762.3
10.781,-2.176725,-9.723954,0.9723954,0,0,0,0,0,2.176725,2.176725,9.723954,2.200765,-2.176725,951229
10.881,-2.193,-9.802707,0.9802706,0,0,0,0,0,2.193,2.193,9.802707,2.217404,-2.193,958773.3
10.981,-2.2095,-9.074166,0.9074166,0,0,0,0,0,2.2095,2.2095,9.074166,2.234275,-2.2095,887367.3
11.081,-2.226225,-8.423895,0.8423895,0,0,0,0,0,2.226225,2.226225,8.423895,2.25138,-2.226225,823636
11.181,-2.243775,-7.533669,0.7533669,0,0,0,0,0,2.243775,2.243775,7.533669,2.269331,-2.243775,736463.1
11.233,-2.251575,-4.995547,0.4995547,0,0,0,0,0,2.251575,2.251575,4.995547,2.27731,-2.251575,488306.9
11.333,-2.268,-4.15922,0.415922,0,0,0,0,0,2.268,2.268,4.15922,2.294115,-2.268,406488.8
11.433,-2.284575,-4.131109,0.4131108,0,0,0,0,0,2.284575,2.284575,4.131108,2.311076,-2.284575,403673
11.533,-2.30205,-4.173458,0.4173458,0,0,0,0,0,2.30205,2.30205,4.173458,2.328961,-2.30205,407738.3
11.633,-2.317425,-4.186481,0.4186482,0,0,0,0,0,2.317425,2.317425,4.186481,2.3447,-2.317425,408946.3
11.733,-2.3349,-4.175104,0.4175104,0,0,0,0,0,2.3349,2.3349,4.175104,2.362591,-2.3349,407762
11.833,-2.351175,-4.152328,0.4152327,0,0,0,0,0,2.351175,2.351175,4.152328,2.379256,-2.351175,405469.9
11.933,-2.368125,-4.276089,0.4276089,0,0,0,0,0,2.368125,2.368125,4.276089,2.396616,-2.368125,417482.6
12.033,-2.38485,-4.35143,0.435143,0,0,0,0,0,2.38485,2.38485,4.351429,2.413748,-2.38485,424765.5
12.133,-2.401425,-4.329041,0.4329041,0,0,0,0,0,2.401425,2.401425,4.329041,2.430729,-2.401425,422508.2
12.233,-2.418075,-4.328154,0.4328154,0,0,0,0,0,2.418075,2.418075,4.328154,2.44779,-2.418075,422349.6
12.333,-2.4348,-4.148588,0.4148588,0,0,0,0,0,2.4348,2.4348,4.148588,2.464932,-2.4348,404757.8
12.433,-2.451525,-4.262552,0.4262552,0,0,0,0,0,2.451525,2.451525,4.262552,2.482075,-2.451525,415805.4
12.533,-2.468625,-4.484557,0.4484557,0,0,0,0,0,2.468625,2.468625,4.484557,2.499607,-2.468625,437385
12.633,-2.4843,-4.509211,0.4509211,0,0,0,0,0,2.4843,2.4843,4.509211,2.51568,-2.4843,439718.8
12.733,-2.501625,-4.547559,0.4547559,0,0,0,0,0,2.501625,2.501625,4.547559,2.533448,-2.501625,443379.6
12.833,-2.5185,-4.724294,0.4724293,0,0,0,0,0,2.5185,2.5185,4.724294,2.550757,-2.5185,460531.2
12.933,-2.534475,-4.868969,0.4868969,0,0,0,0,0,2.534475,2.534475,4.868969,2.567146,-2.534475,474556.7
13.033,-2.551725,-5.007863,0.5007863,0,0,0,0,0,2.551725,2.551725,5.007863,2.584846,-2.551725,488007.6
13.133,-2.568375,-4.540481,0.4540481,0,0,0,0,0,2.568375,2.568375,4.540481,2.601934,-2.568375,442386.4
13.233,-2.58465,-4.709169,0.4709169,0,0,0,0,0,2.58465,2.58465,4.709169,2.618639,-2.58465,458745.4
13.333,-2.601825,-4.94425,0.494425,0,0,0,0,0,2.601825,2.601825,4.94425,2.636271,-2.601825,481560.9
13.433,-2.617875,-5.166009,0.5166009,0,0,0,0,0,2.617875,2.617875,5.166009,2.652751,-2.617875,503076.9
13.533,-2.6349,-5.367078,0.5367078,0,0,0,0,0,2.6349,2.6349,5.367078,2.670236,-2.6349,522566.1
13.633,-2.65095,-5.574837,0.5574837,0,0,0,0,0,2.65095,2.65095,5.574837,2.686721,-2.65095,542705.1
13.733,-2.667825,-5.76435,0.576435,0,0,0,0,0,2.667825,2.667825,5.76435,2.704058,-2.667825,561056.8
13.833,-2.6844,-5.959034,0.5959034,0,0,0,0,0,2.6844,2.6844,5.959034,2.721088,-2.6844,579907
13.933,-2.701125,-6.140888,0.6140888,0,0,0,0,0,2.701125,2.701125,6.140888,2.738276,-2.701125,597501.5
14.033,-2.718075,-6.355226,0.6355226,0,0,0,0,0,2.718075,2.718075,6.355226,2.755698,-2.718075,618248.6
14.133,-2.735475,-6.552964,0.6552964,0,0,0,0,0,2.735475,2.735475,6.552964,2.773586,-2.735475,637370.9
14.233,-2.75115,-6.694034,0.6694034,0,0,0,0,0,2.75115,2.75115,6.694034,2.789703,-2.75115,650987.1
14.333,-2.768925,-6.834969,0.6834969,0,0,0,0,0,2.768925,2.768925,6.834969,2.807983,-2.768925,664571.4
14.433,-2.7846,-6.99988,0.6999879,0,0,0,0,0,2.7846,2.7846,6.99988,2.824105,-2.7846,680496.1
14.533,-2.801625,-7.20375,0.7203751,0,0,0,0,0,2.801625,2.801625,7.20375,2.841619,-2.801625,700192.8
14.633,-2.818275,-7.395178,0.7395177,0,0,0,0,0,2.818275,2.818275,7.395178,2.858751,-2.818275,718676.1
14.733,-2.83485,-7.567562,0.7567562,0,0,0,0,0,2.83485,2.83485,7.567562,2.875808,-2.83485,735303.3
14.833,-2.851425,-7.734843,0.7734842,0,0,0,0,0,2.851425,2.851425,7.734843,2.892868,-2.851425,751428.9
14.933,-2.867925,-7.894896,0.7894896,0,0,0,0,0,2.867925,2.867925,7.894896,2.909854,-2.867925,766847.6
15.033,-2.884575,-8.00541,0.800541,0,0,0,0,0,2.884575,2.884575,8.00541,2.926997,-2.884575,777448.8
15.133,-2.902125,-8.149602,0.8149601,0,0,0,0,0,2.902125,2.902125,8.149602,2.94507,-2.902125,791309
15.233,-2.91735,-8.2798,0.82798,0,0,0,0,0,2.91735,2.91735,8.2798,2.960751,-2.91735,803825
15.333,-2.9352,-8.332513,0.8332514,0,0,0,0,0,2.9352,2.9352,8.332513,2.979139,-2.9352,808793.7
15.433,-2.9511,-8.518063,0.8518063,0,0,0,0,0,2.9511,2.9511,8.518063,2.995521,-2.9511,826668.6
15.533,-2.96805,-8.695789,0.8695788,0,0,0,0,0,2.96805,2.96805,8.695788,3.012988,-2.96805,843769.3
15.633,-2.984775,-8.852817,0.8852817,0,0,0,0,0,2.984775,2.984775,8.852818,3.030226,-2.984775,858858
15.733,-3.00165,-9.007484,0.9007484,0,0,0,0,0,3.00165,3.00165,9.007483,3.047622,-3.00165,873711.1
15.833,-3.01785,-9.042829,0.9042829,0,0,0,0,0,3.01785,3.01785,9.04283,3.064325,-3.01785,876993
15.933,-3.03495,-8.368336,0.8368336,0,0,0,0,0,3.03495,3.03495,8.368336,3.081958,-3.03495,811436.1
15.993,-3.04575,-8.334197,0.8334197,0,0,0,0,0,3.04575,3.04575,8.334197,3.093097,-3.04575,808035.8