File: EXPERIMENTAL/COMPRESSION/10MM_MIN_V1001.txt
"Test Type","Compression"
"Method Name",""
"Sample name","C:\Users\EGS\Desktop\Eggs\2024-02-08\10mm_min.is_comp"
"User",""
"Sample note 1",""
"Sample note 2",""
"Sample note 3",""
"Geometry","Rectangular"
"Specimen",1
"Specimen label",""
"Width",10.000000,"mm"
"Thickness",1.000000,"mm"
"Anvil height",100.000000,"mm"
"Diameter",10.000000,"mm"
"Inner diameter",8.000000,"mm"
"Outer diameter",10.000000,"mm"
"Wall thickness",1.000000,"mm"
"Area",0.100000,"cm^2"
"Linear density",100.000000,"tex"
"Sled weight",10.000000,"N"
"Loading span",10.000000,"mm"
"Support span",100.000000,"mm"
"Span ratio","2"
"Fixture type","4-point"
"Included"
"Final width",10.000000,"mm"
"Final thickness",1.000000,"mm"
"Final anvil height",100.000000,"mm"
"Final diameter",10.000000,"mm"
"Final Inner diameter",8.000000,"mm"
"Final outer diameter",10.000000,"mm"
"Final wall thickness",1.000000,"mm"
"Final area",0.100000,"cm^2"
"Final linear density",100.000000,"tex"
"Custom text input  1",""
"Custom text input  2",""
"Custom text input  3",""
"Custom text input  4",""
"Custom text input  5",""
"Custom text input  6",""
"Custom text input  7",""
"Custom text input  8",""
"Custom text input  9",""
"Custom text input 10",""
"Custom text input 11",""
"Custom text input 12",""
"Custom text input 13",""
"Custom text input 14",""
"Custom text input 15",""
"Custom text input 16",""
"Custom text input 17",""
"Custom text input 18",""
"Custom text input 19",""
"Custom text input 20",""
"Custom text input 21",""
"Custom text input 22",""
"Custom text input 23",""
"Custom text input 24",""
"Custom text input 25",""
"Custom text input 26",""
"Custom text input 27",""
"Custom text input 28",""
"Custom text input 29",""
"Custom text input 30",""
"Custom text input 31",""
"Custom text input 32",""
"Custom text input 33",""
"Custom text input 34",""
"Custom text input 35",""
"Custom text input 36",""
"Custom text input 37",""
"Custom text input 38",""
"Custom text input 39",""
"Custom text input 40",""
"Custom text input 41",""
"Custom text input 42",""
"Custom text input 43",""
"Custom text input 44",""
"Custom text input 45",""
"Custom text input 46",""
"Custom text input 47",""
"Custom text input 48",""
"Custom text input 49",""
"Custom text input 50",""
"Custom number input  1",0.000000,""
"Custom number input  2",0.000000,""
"Custom number input  3",0.000000,""
"Custom number input  4",0.000000,""
"Custom number input  5",0.000000,""
"Custom number input  6",0.000000,""
"Custom number input  7",0.000000,""
"Custom number input  8",0.000000,""
"Custom number input  9",0.000000,""
"Custom number input 10",0.000000,""
"Time sec","Extension mm","Load N","Compressive stress MPa","Cycle Count ","Total Cycle Count ","Repetitions Count ","Marked Data ","PIP Count ","Compressive extension mm","Compressive strain %","Compressive load N","True strain %","Corrected Position mm","True stress Pa"
0,-0.7002,-0.547722,0.0547722,0,0,0,0,0,0.7002,0.7002,0.547722,0.7026629,-0.7002,54388.68
0.09900001,-0.711225,-3.059939,0.3059938,0,0,0,0,0,0.711225,0.711225,3.059938,0.7137663,-0.711225,303817.5
0.128,-0.7188,-5.59067,0.559067,0,0,0,0,0,0.7188,0.7188,5.59067,0.7213958,-0.7188,555048.4
0.163,-0.7254001,-8.111037,0.8111037,0,0,0,0,0,0.7254,0.7254,8.111037,0.7280439,-0.7254001,805220
0.208,-0.735075,-10.65157,1.065157,0,0,0,0,0,0.7350751,0.7350751,10.65157,0.73779,-0.735075,1057328
0.258,-0.743325,-13.16306,1.316306,0,0,0,0,0,0.7433251,0.7433251,13.16306,0.7461015,-0.743325,1306522
0.321,-0.75345,-15.67822,1.567822,0,0,0,0,0,0.75345,0.75345,15.67822,0.7563028,-0.75345,1556009
0.372,-0.762225,-18.21522,1.821522,0,0,0,0,0,0.762225,0.762225,18.21522,0.7651448,-0.762225,1807638
0.421,-0.770625,-20.75636,2.075636,0,0,0,0,0,0.770625,0.770625,20.75636,0.7736097,-0.770625,2059640
0.474,-0.779025,-23.27909,2.327909,0,0,0,0,0,0.779025,0.779025,23.27909,0.7820753,-0.779025,2309774
0.523,-0.787425,-25.80726,2.580726,0,0,0,0,0,0.787425,0.787425,25.80726,0.7905416,-0.787425,2560405
0.5710001,-0.79515,-28.32198,2.832198,0,0,0,0,0,0.79515,0.79515,28.32198,0.7983282,-0.79515,2809678
0.619,-0.80385,-30.87587,3.087587,0,0,0,0,0,0.80385,0.80385,30.87587,0.8070983,-0.80385,3062767
0.6620001,-0.81105,-33.38735,3.338735,0,0,0,0,0,0.81105,0.81105,33.38735,0.8143569,-0.81105,3311656
0.716,-0.8193,-35.90833,3.590833,0,0,0,0,0,0.8193,0.8193,35.90833,0.8226747,-0.8193,3561413
0.7700001,-0.827925,-38.42526,3.842526,0,0,0,0,0,0.827925,0.827925,38.42526,0.8313714,-0.827925,3810713
0.8200001,-0.837675,-40.94777,4.094777,0,0,0,0,0,0.837675,0.837675,40.94777,0.8412032,-0.837675,4060476
0.869,-0.845175,-43.46998,4.346998,0,0,0,0,0,0.845175,0.845175,43.46998,0.8487669,-0.845175,4310258
0.9020001,-0.850425,-40.74291,4.074291,0,0,0,0,0,0.8504251,0.8504251,40.74291,0.8540618,-0.850425,4039642
0.906,-0.851175,-37.42822,3.742821,0,0,0,0,0,0.8511751,0.8511751,37.42822,0.8548182,-0.851175,3710964
0.9090001,-0.8517751,-34.6683,3.46683,0,0,0,0,0,0.8517751,0.8517751,34.6683,0.8554234,-0.8517751,3437300
0.9120001,-0.8523751,-31.80322,3.180322,0,0,0,0,0,0.852375,0.852375,31.80322,0.8560286,-0.8523751,3153214
0.915,-0.852975,-28.98185,2.898185,0,0,0,0,0,0.852975,0.852975,28.98185,0.8566337,-0.852975,2873464
0.9180001,-0.8535,-26.26175,2.626175,0,0,0,0,0,0.8535,0.8535,26.26175,0.8571631,-0.8535,2603761
0.9210001,-0.854025,-23.69996,2.369996,0,0,0,0,0,0.854025,0.854025,23.69996,0.8576927,-0.854025,2349756
0.9250001,-0.8547,-20.63355,2.063355,0,0,0,0,0,0.8547,0.8547,20.63355,0.8583736,-0.8547,2045719
0.929,-0.8553001,-17.99175,1.799175,0,0,0,0,0,0.8553001,0.8553001,17.99175,0.8589787,-0.8553001,1783787
0.934,-0.856125,-15.30658,1.530658,0,0,0,0,0,0.8561251,0.8561251,15.30658,0.8598108,-0.856125,1517554
0.9410001,-0.857175,-12.63952,1.263952,0,0,0,0,0,0.8571751,0.8571751,12.63952,0.8608699,-0.857175,1253118
0.957,-0.8598,-10.11448,1.011448,0,0,0,0,0,0.8598,0.8598,10.11448,0.8635176,-0.8598,1002752
1.057,-0.87615,-11.94686,1.194686,0,0,0,0,0,0.87615,0.87615,11.94686,0.8800108,-0.87615,1184219
1.157,-0.8931,-11.78914,1.178914,0,0,0,0,0,0.8931,0.8931,11.78914,0.8971121,-0.8931,1168385
1.257,-0.909675,-12.08138,1.208138,0,0,0,0,0,0.909675,0.909675,12.08138,0.9138378,-0.909675,1197148
1.357,-0.92595,-12.87718,1.287718,0,0,0,0,0,0.92595,0.92595,12.87718,0.9302636,-0.92595,1275794
1.457,-0.94335,-14.02779,1.402779,0,0,0,0,0,0.94335,0.94335,14.02779,0.9478278,-0.94335,1389546
1.557,-0.95955,-14.5179,1.45179,0,0,0,0,0,0.95955,0.95955,14.5179,0.9641834,-0.95955,1437860
1.657,-0.97695,-15.7291,1.57291,0,0,0,0,0,0.97695,0.97695,15.7291,0.9817535,-0.97695,1557543
1.757,-0.99225,-16.83558,1.683558,0,0,0,0,0,0.99225,0.99225,16.83558,0.9972057,-0.99225,1666853
1.857,-1.0104,-15.76519,1.576519,0,0,0,0,0,1.0104,1.0104,15.76519,1.015539,-1.0104,1560590
1.957,-1.026525,-14.68457,1.468457,0,0,0,0,0,1.026525,1.026525,14.68457,1.03183,-1.026525,1453383
2.057,-1.04295,-15.31828,1.531828,0,0,0,0,0,1.04295,1.04295,15.31828,1.048427,-1.04295,1515852
2.157,-1.05975,-16.22494,1.622494,0,0,0,0,0,1.05975,1.05975,16.22494,1.065405,-1.05975,1605300
2.207,-1.068525,-13.67704,1.367704,0,0,0,0,0,1.068525,1.068525,13.67704,1.074275,-1.068525,1353090
2.307,-1.084725,-12.95965,1.295965,0,0,0,0,0,1.084725,1.084725,12.95965,1.090651,-1.084725,1281908
2.407,-1.10115,-13.11281,1.311281,0,0,0,0,0,1.10115,1.10115,13.11281,1.107258,-1.10115,1296842
2.507,-1.1178,-12.71486,1.271486,0,0,0,0,0,1.1178,1.1178,12.71486,1.124094,-1.1178,1257273
2.6,-1.133925,-10.13424,1.013423,0,0,0,0,0,1.133925,1.133925,10.13424,1.140403,-1.133925,1001932
2.636,-1.14075,-7.625632,0.7625632,0,0,0,0,0,1.14075,1.14075,7.625632,1.147306,-1.14075,753864.3
2.736,-1.155225,-7.07294,0.707294,0,0,0,0,0,1.155225,1.155225,7.07294,1.16195,-1.155225,699123.2
2.836,-1.1736,-8.583248,0.8583249,0,0,0,0,0,1.1736,1.1736,8.583248,1.180541,-1.1736,848251.6
2.936,-1.18935,-9.360082,0.9360082,0,0,0,0,0,1.18935,1.18935,9.360083,1.196479,-1.18935,924875.8
3.036,-1.206375,-10.15016,1.015016,0,0,0,0,0,1.206375,1.206375,10.15016,1.213711,-1.206375,1002772
3.136,-1.2228,-10.67977,1.067977,0,0,0,0,0,1.2228,1.2228,10.67977,1.230338,-1.2228,1054917
3.236,-1.24035,-10.73744,1.073744,0,0,0,0,0,1.24035,1.24035,10.73744,1.248107,-1.24035,1060426
3.336,-1.256025,-11.09997,1.109997,0,0,0,0,0,1.256025,1.256025,11.09997,1.26398,-1.256025,1096055
3.436,-1.2741,-11.79887,1.179887,0,0,0,0,0,1.2741,1.2741,11.79887,1.282286,-1.2741,1164854
3.536,-1.289025,-12.64229,1.264229,0,0,0,0,0,1.289025,1.289025,12.64229,1.297405,-1.289025,1247933
3.636,-1.30725,-13.5176,1.35176,0,0,0,0,0,1.30725,1.30725,13.5176,1.31587,-1.30725,1334089
3.736,-1.3221,-14.06369,1.406369,0,0,0,0,0,1.3221,1.3221,14.06369,1.330918,-1.3221,1387776
3.836,-1.340325,-15.00152,1.500152,0,0,0,0,0,1.340325,1.340325,15.00152,1.349388,-1.340325,1480045
3.936,-1.356,-15.50362,1.550362,0,0,0,0,0,1.356,1.356,15.50362,1.365278,-1.356,1529339
4.036,-1.37325,-15.91527,1.591527,0,0,0,0,0,1.37325,1.37325,15.91527,1.382766,-1.37325,1569672
4.136,-1.3896,-17.05696,1.705696,0,0,0,0,0,1.3896,1.3896,17.05696,1.399345,-1.3896,1681994
4.236,-1.4073,-15.84627,1.584627,0,0,0,0,0,1.4073,1.4073,15.84627,1.417296,-1.4073,1562326
4.336,-1.422375,-16.49415,1.649416,0,0,0,0,0,1.422375,1.422375,16.49416,1.432588,-1.422375,1625955
4.38,-1.4295,-13.93784,1.393784,0,0,0,0,0,1.4295,1.4295,13.93784,1.439816,-1.4295,1373860
4.48,-1.446825,-11.93461,1.193461,0,0,0,0,0,1.446825,1.446825,11.93461,1.457394,-1.446825,1176194
4.58,-1.463925,-11.72673,1.172673,0,0,0,0,0,1.463925,1.463925,11.72673,1.474746,-1.463925,1155506
4.68,-1.479375,-12.75208,1.275208,0,0,0,0,0,1.479375,1.479375,12.75208,1.490427,-1.479375,1256343
4.78,-1.49685,-13.37468,1.337468,0,0,0,0,0,1.49685,1.49685,13.37468,1.508166,-1.49685,1317448
4.88,-1.513275,-13.50283,1.350283,0,0,0,0,0,1.513275,1.513275,13.50283,1.524842,-1.513275,1329849
4.98,-1.53,-12.78411,1.278411,0,0,0,0,0,1.53,1.53,12.78411,1.541825,-1.53,1258851
5.08,-1.5471,-12.89484,1.289484,0,0,0,0,0,1.5471,1.5471,12.89484,1.559192,-1.5471,1269534
5.18,-1.5633,-12.37462,1.237463,0,0,0,0,0,1.5633,1.5633,12.37462,1.575648,-1.5633,1218117
5.28,-1.58025,-12.71091,1.271091,0,0,0,0,0,1.58025,1.58025,12.71091,1.592869,-1.58025,1251004
5.372,-1.5948,-10.19157,1.019157,0,0,0,0,0,1.5948,1.5948,10.19158,1.607654,-1.5948,1002904
5.472,-1.61265,-10.6033,1.06033,0,0,0,0,0,1.61265,1.61265,10.6033,1.625795,-1.61265,1043231
5.572,-1.62915,-10.94177,1.094177,0,0,0,0,0,1.62915,1.62915,10.94177,1.642567,-1.62915,1076352
5.672,-1.64535,-11.19281,1.119281,0,0,0,0,0,1.64535,1.64535,11.19281,1.659036,-1.64535,1100865
5.772,-1.66215,-11.72981,1.172981,0,0,0,0,0,1.66215,1.66215,11.72981,1.676119,-1.66215,1153485
5.872,-1.6794,-12.1865,1.21865,0,0,0,0,0,1.6794,1.6794,12.1865,1.693662,-1.6794,1198184
5.925,-1.68765,-9.666048,0.9666048,0,0,0,0,0,1.68765,1.68765,9.666048,1.702053,-1.68765,950291.9
6.025,-1.704525,-9.524144,0.9524144,0,0,0,0,0,1.704525,1.704525,9.524144,1.719219,-1.704525,936180.3
6.081,-1.71405,-6.918944,0.6918944,0,0,0,0,0,1.71405,1.71405,6.918944,1.72891,-1.71405,680035
6.181,-1.7301,-5.835555,0.5835556,0,0,0,0,0,1.7301,1.7301,5.835556,1.745241,-1.7301,573459.5
6.281,-1.747125,-6.140321,0.6140322,0,0,0,0,0,1.747125,1.747125,6.140322,1.762567,-1.747125,603304.3
6.381,-1.763625,-6.242871,0.6242871,0,0,0,0,0,1.763625,1.763625,6.242871,1.779362,-1.763625,613277
6.481,-1.780275,-6.130219,0.6130219,0,0,0,0,0,1.780275,1.780275,6.130219,1.796313,-1.780275,602108.4
6.581,-1.797075,-6.245688,0.6245688,0,0,0,0,0,1.797075,1.797075,6.245687,1.813419,-1.797075,613344.8
6.681,-1.81305,-5.955219,0.5955219,0,0,0,0,0,1.81305,1.81305,5.955219,1.829687,-1.81305,584724.8
6.781,-1.830075,-6.224893,0.6224893,0,0,0,0,0,1.830075,1.830075,6.224893,1.847028,-1.830075,611097.3
6.881,-1.8474,-7.038176,0.7038176,0,0,0,0,0,1.8474,1.8474,7.038176,1.864678,-1.8474,690815.3
6.981,-1.862925,-8.040033,0.8040034,0,0,0,0,0,1.862925,1.862925,8.040033,1.880496,-1.862925,789025.3
7.081,-1.880775,-9.246543,0.9246543,0,0,0,0,0,1.880775,1.880775,9.246543,1.898687,-1.880775,907263.6
7.181,-1.897125,-8.503892,0.8503891,0,0,0,0,0,1.897125,1.897125,8.503892,1.915351,-1.897125,834256.2
7.281,-1.913925,-9.643212,0.9643212,0,0,0,0,0,1.913925,1.913925,9.643212,1.932478,-1.913925,945864.8
7.381,-1.93095,-10.58713,1.058713,0,0,0,0,0,1.93095,1.93095,10.58713,1.949836,-1.93095,1038270
7.481,-1.947075,-11.45991,1.145991,0,0,0,0,0,1.947075,1.947075,11.45991,1.96628,-1.947075,1123678
7.581,-1.963875,-12.35196,1.235196,0,0,0,0,0,1.963875,1.963875,12.35196,1.983415,-1.963875,1210938
7.681,-1.980675,-13.17555,1.317555,0,0,0,0,0,1.980675,1.980675,13.17555,2.000553,-1.980675,1291458
7.781,-1.996725,-13.48794,1.348794,0,0,0,0,0,1.996725,1.996725,13.48794,2.016929,-1.996725,1321863
7.881,-2.014275,-14.11062,1.411062,0,0,0,0,0,2.014275,2.014275,14.11062,2.034838,-2.014275,1382639
7.981,-2.029575,-14.41965,1.441965,0,0,0,0,0,2.029575,2.029575,14.41965,2.050454,-2.029575,1412699
8.024,-2.03835,-11.8089,1.18089,0,0,0,0,0,2.03835,2.03835,11.8089,2.059411,-2.03835,1156820
8.043,-2.041875,-9.280317,0.9280317,0,0,0,0,0,2.041875,2.041875,9.280316,2.06301,-2.041875,909082.4
8.143,-2.056725,-9.120688,0.9120688,0,0,0,0,0,2.056725,2.056725,9.120687,2.07817,-2.056725,893310
8.243,-2.074425,-9.887666,0.9887666,0,0,0,0,0,2.074425,2.074425,9.887666,2.096244,-2.074425,968255.3
8.343,-2.0904,-9.070553,0.9070553,0,0,0,0,0,2.0904,2.0904,9.070553,2.112558,-2.0904,888094.2
8.369,-2.0955,-6.549515,0.6549515,0,0,0,0,0,2.0955,2.0955,6.549515,2.117767,-2.0955,641227
8.469001,-2.1117,-7.22751,0.7227511,0,0,0,0,0,2.1117,2.1117,7.22751,2.134315,-2.1117,707488.7
8.569,-2.12805,-7.809892,0.7809892,0,0,0,0,0,2.12805,2.12805,7.809892,2.151019,-2.12805,764369.4
8.669001,-2.1456,-8.314081,0.831408,0,0,0,0,0,2.1456,2.1456,8.31408,2.168953,-2.1456,813569.4
8.769,-2.161425,-8.657083,0.8657083,0,0,0,0,0,2.161425,2.161425,8.657083,2.185126,-2.161425,846996.7
8.869,-2.178975,-8.909747,0.8909747,0,0,0,0,0,2.178975,2.178975,8.909747,2.203065,-2.178975,871560.6
8.969001,-2.194275,-8.915305,0.8915305,0,0,0,0,0,2.194275,2.194275,8.915305,2.218707,-2.194275,871967.9
9.069,-2.212125,-9.120069,0.912007,0,0,0,0,0,2.212125,2.212125,9.12007,2.23696,-2.212125,891832.2
9.169001,-2.228625,-9.182379,0.9182379,0,0,0,0,0,2.228625,2.228625,9.182379,2.253834,-2.228625,897773.8
9.269,-2.244975,-9.455726,0.9455726,0,0,0,0,0,2.244975,2.244975,9.455726,2.270558,-2.244975,924344.7
9.308001,-2.25105,-6.925382,0.6925381,0,0,0,0,0,2.25105,2.25105,6.925382,2.276773,-2.25105,676948.8
9.408,-2.268675,-6.122835,0.6122835,0,0,0,0,0,2.268675,2.268675,6.122835,2.294805,-2.268675,598392.8
9.508,-2.284725,-6.394282,0.6394282,0,0,0,0,0,2.284725,2.284725,6.394282,2.31123,-2.284725,624819
9.608001,-2.301525,-5.207881,0.5207881,0,0,0,0,0,2.301525,2.301525,5.207881,2.328424,-2.301525,508802.1
9.708,-2.318025,-5.212516,0.5212516,0,0,0,0,0,2.318025,2.318025,5.212516,2.345314,-2.318025,509168.9
9.808001,-2.335425,-5.339041,0.5339041,0,0,0,0,0,2.335425,2.335425,5.339041,2.363128,-2.335425,521435.2
9.908001,-2.351175,-5.626723,0.5626723,0,0,0,0,0,2.351175,2.351175,5.626723,2.379256,-2.351175,549442.9
10.008,-2.369025,-6.283775,0.6283775,0,0,0,0,0,2.369025,2.369025,6.283775,2.397538,-2.369025,613491.1
10.108,-2.384175,-6.68776,0.668776,0,0,0,0,0,2.384175,2.384175,6.68776,2.413057,-2.384175,652831.2
10.208,-2.401875,-6.97574,0.6975741,0,0,0,0,0,2.401875,2.401875,6.97574,2.43119,-2.401875,680819.2
10.308,-2.417775,-7.235371,0.7235371,0,0,0,0,0,2.417775,2.417775,7.235371,2.447483,-2.417775,706043.6
10.408,-2.435025,-8.102141,0.8102142,0,0,0,0,0,2.435025,2.435025,8.102141,2.465162,-2.435025,790485.2
10.508,-2.4513,-8.792005,0.8792006,0,0,0,0,0,2.4513,2.4513,8.792006,2.481845,-2.4513,857648.7
10.608,-2.467725,-9.482905,0.9482905,0,0,0,0,0,2.467725,2.467725,9.482905,2.498684,-2.467725,924889.3
10.708,-2.4846,-10.02666,1.002666,0,0,0,0,0,2.4846,2.4846,10.02666,2.515987,-2.4846,977754.1
10.808,-2.50245,-10.55463,1.055463,0,0,0,0,0,2.50245,2.50245,10.55463,2.534294,-2.50245,1029050
10.908,-2.517525,-10.79523,1.079523,0,0,0,0,0,2.517525,2.517525,10.79523,2.549757,-2.517525,1052346
11.008,-2.5356,-11.2094,1.12094,0,0,0,0,0,2.5356,2.5356,11.2094,2.5683,-2.5356,1092517
11.108,-2.551275,-11.40619,1.140619,0,0,0,0,0,2.551275,2.551275,11.40619,2.584384,-2.551275,1111519
11.208,-2.568525,-10.98508,1.098508,0,0,0,0,0,2.568525,2.568525,10.98508,2.602088,-2.568525,1070292
11.308,-2.584875,-11.20947,1.120947,0,0,0,0,0,2.584875,2.584875,11.20947,2.61887,-2.584875,1091972
11.408,-2.601975,-11.56735,1.156735,0,0,0,0,0,2.601975,2.601975,11.56735,2.636425,-2.601975,1126637
11.508,-2.617875,-11.6249,1.16249,0,0,0,0,0,2.617875,2.617875,11.6249,2.652751,-2.617875,1132058
11.608,-2.635125,-11.80363,1.180363,0,0,0,0,0,2.635125,2.635125,11.80363,2.670467,-2.635125,1149259
11.708,-2.651025,-11.97293,1.197293,0,0,0,0,0,2.651025,2.651025,11.97293,2.686798,-2.651025,1165553
11.808,-2.66895,-12.22583,1.222583,0,0,0,0,0,2.66895,2.66895,12.22583,2.705213,-2.66895,1189953
11.908,-2.683875,-12.47534,1.247534,0,0,0,0,0,2.683875,2.683875,12.47534,2.720549,-2.683875,1214052
12.008,-2.701875,-12.73619,1.273619,0,0,0,0,0,2.701875,2.701875,12.73619,2.739047,-2.701875,1239208
12.108,-2.71785,-12.74715,1.274715,0,0,0,0,0,2.71785,2.71785,12.74715,2.755467,-2.71785,1240071
12.172,-2.728725,-10.16431,1.016431,0,0,0,0,0,2.728725,2.728725,10.16431,2.766646,-2.728725,988695
12.272,-2.745825,-9.369627,0.9369627,0,0,0,0,0,2.745825,2.745825,9.369627,2.784227,-2.745825,911235.3
12.372,-2.762025,-9.883478,0.9883478,0,0,0,0,0,2.762025,2.762025,9.883478,2.800886,-2.762025,961049.4
12.472,-2.779275,-9.993285,0.9993285,0,0,0,0,0,2.779275,2.779275,9.993285,2.818628,-2.779275,971554.4
12.572,-2.794725,-10.04157,1.004157,0,0,0,0,0,2.794725,2.794725,10.04157,2.834521,-2.794725,976093.8
12.672,-2.812725,-10.40629,1.040629,0,0,0,0,0,2.812725,2.812725,10.40629,2.85304,-2.812725,1011359
12.772,-2.82915,-10.67662,1.067662,0,0,0,0,0,2.82915,2.82915,10.67662,2.869942,-2.82915,1037456
12.872,-2.84535,-10.97252,1.097252,0,0,0,0,0,2.84535,2.84535,10.97252,2.886615,-2.84535,1066032
12.972,-2.862075,-11.23261,1.123261,0,0,0,0,0,2.862075,2.862075,11.23261,2.903831,-2.862075,1091113
13.03,-2.872425,-8.730434,0.8730434,0,0,0,0,0,2.872425,2.872425,8.730433,2.914487,-2.872425,847965.9
13.13,-2.88825,-8.524582,0.8524582,0,0,0,0,0,2.88825,2.88825,8.524582,2.930781,-2.88825,827837.1
13.23,-2.90535,-8.996964,0.8996964,0,0,0,0,0,2.90535,2.90535,8.996964,2.948391,-2.90535,873557
13.33,-2.9214,-8.507356,0.8507356,0,0,0,0,0,2.9214,2.9214,8.507356,2.964923,-2.9214,825882.2
13.43,-2.939625,-8.748367,0.8748367,0,0,0,0,0,2.939625,2.939625,8.748367,2.983698,-2.939625,849119.8
13.53,-2.954325,-8.896835,0.8896835,0,0,0,0,0,2.954325,2.954325,8.896835,2.998844,-2.954325,863399.4
13.63,-2.9727,-9.654433,0.9654433,0,0,0,0,0,2.9727,2.9727,9.654432,3.017781,-2.9727,936743.5
13.73,-2.988225,-10.29739,1.029739,0,0,0,0,0,2.988225,2.988225,10.29739,3.033782,-2.988225,998967.9
13.83,-3.00525,-10.80456,1.080456,0,0,0,0,0,3.00525,3.00525,10.80456,3.051333,-3.00525,1047986
13.93,-3.021675,-11.01077,1.101077,0,0,0,0,0,3.021675,3.021675,11.01077,3.068269,-3.021675,1067806
14.03,-3.038775,-9.55537,0.955537,0,0,0,0,0,3.038775,3.038775,9.555369,3.085903,-3.038775,926500.3
14.13,-3.054975,-9.877466,0.9877466,0,0,0,0,0,3.054975,3.054975,9.877465,3.102612,-3.054975,957571.2
14.23,-3.0726,-10.2061,1.02061,0,0,0,0,0,3.0726,3.0726,10.2061,3.120794,-3.0726,989251.1
14.33,-3.088125,-10.26608,1.026608,0,0,0,0,0,3.088125,3.088125,10.26608,3.136813,-3.088125,994905.1
14.43,-3.106275,-10.33851,1.033851,0,0,0,0,0,3.106275,3.106275,10.33851,3.155543,-3.106275,1001737
14.53,-3.1209,-10.37549,1.037549,0,0,0,0,0,3.1209,3.1209,10.37549,3.170638,-3.1209,1005168
14.63,-3.1392,-9.918787,0.9918786,0,0,0,0,0,3.1392,3.1392,9.918787,3.189529,-3.1392,960741.6
14.73,-3.155025,-10.10035,1.010035,0,0,0,0,0,3.155025,3.155025,10.10035,3.205868,-3.155025,978168.1
14.83,-3.17205,-10.34633,1.034633,0,0,0,0,0,3.17205,3.17205,10.34633,3.223449,-3.17205,1001814
14.93,-3.188475,-10.45395,1.045395,0,0,0,0,0,3.188475,3.188475,10.45395,3.240414,-3.188475,1012063
15.03,-3.206025,-9.474747,0.9474747,0,0,0,0,0,3.206025,3.206025,9.474747,3.258544,-3.206025,917098.4
15.13,-3.2214,-9.753868,0.9753868,0,0,0,0,0,3.2214,3.2214,9.753868,3.274429,-3.2214,943965.7
15.23,-3.239775,-10.02336,1.002336,0,0,0,0,0,3.239775,3.239775,10.02336,3.293418,-3.239775,969862.9
15.33,-3.2547,-10.32556,1.032556,0,0,0,0,0,3.2547,3.2547,10.32556,3.308844,-3.2547,998949.3
15.43,-3.2727,-10.58238,1.058238,0,0,0,0,0,3.2727,3.2727,10.58238,3.327451,-3.2727,1023605
15.53,-3.287775,-11.00527,1.100527,0,0,0,0,0,3.287775,3.287775,11.00527,3.343037,-3.287775,1064344
15.63,-3.3057,-11.75006,1.175006,0,0,0,0,0,3.3057,3.3057,11.75006,3.361573,-3.3057,1136164
15.73,-3.321675,-12.23177,1.223177,0,0,0,0,0,3.321675,3.321675,12.23177,3.378096,-3.321675,1182547
15.83,-3.338625,-12.6384,1.26384,0,0,0,0,0,3.338625,3.338625,12.6384,3.39563,-3.338625,1221646
15.93,-3.35505,-11.81047,1.181047,0,0,0,0,0,3.35505,3.35505,11.81047,3.412623,-3.35505,1141422
16.03,-3.372825,-12.53755,1.253755,0,0,0,0,0,3.372825,3.372825,12.53755,3.431017,-3.372825,1211468
16.13,-3.387975,-12.85274,1.285274,0,0,0,0,0,3.387975,3.387975,12.85274,3.446697,-3.387975,1241730
16.23,-3.406875,-13.36279,1.336279,0,0,0,0,0,3.406875,3.406875,13.36279,3.466262,-3.406875,1290753
16.33,-3.42135,-13.55044,1.355044,0,0,0,0,0,3.42135,3.42135,13.55044,3.481249,-3.42135,1308683
16.43,-3.4392,-12.8001,1.28001,0,0,0,0,0,3.4392,3.4392,12.8001,3.499733,-3.4392,1235988
16.53,-3.455175,-12.25853,1.225853,0,0,0,0,0,3.455175,3.455175,12.25853,3.516278,-3.455175,1183498
16.63,-3.4728,-11.97717,1.197717,0,0,0,0,0,3.4728,3.4728,11.97717,3.534535,-3.4728,1156123
16.73,-3.488475,-11.96583,1.196583,0,0,0,0,0,3.488475,3.488475,11.96583,3.550776,-3.488475,1154841
16.83,-3.5055,-12.20801,1.220801,0,0,0,0,0,3.5055,3.5055,12.20801,3.568417,-3.5055,1178006
16.93,-3.52155,-12.16698,1.216698,0,0,0,0,0,3.52155,3.52155,12.16698,3.585052,-3.52155,1173852
17.03,-3.53985,-12.57771,1.257771,0,0,0,0,0,3.53985,3.53985,12.57771,3.604022,-3.53985,1213248
17.13,-3.5544,-12.08018,1.208018,0,0,0,0,0,3.5544,3.5544,12.08018,3.619107,-3.5544,1165080
17.23,-3.572925,-12.40961,1.24096,0,0,0,0,0,3.572925,3.572925,12.40961,3.638317,-3.572925,1196622
17.33,-3.588,-12.48342,1.248342,0,0,0,0,0,3.588,3.588,12.48342,3.653951,-3.588,1203551
17.43,-3.60555,-12.69572,1.269572,0,0,0,0,0,3.60555,3.60555,12.69572,3.672156,-3.60555,1223797
17.53,-3.621675,-12.74955,1.274955,0,0,0,0,0,3.621675,3.621675,12.74955,3.688885,-3.621675,1228780
17.63,-3.6393,-12.44531,1.244531,0,0,0,0,0,3.6393,3.6393,12.44531,3.707175,-3.6393,1199239
17.73,-3.6549,-12.72681,1.272681,0,0,0,0,0,3.6549,3.6549,12.72681,3.723365,-3.6549,1226166
17.83,-3.67275,-12.9616,1.29616,0,0,0,0,0,3.67275,3.67275,12.9616,3.741894,-3.67275,1248556
17.93,-3.68805,-13.06646,1.306646,0,0,0,0,0,3.68805,3.68805,13.06646,3.757779,-3.68805,1258457
18.03,-3.706425,-13.61076,1.361076,0,0,0,0,0,3.706425,3.706425,13.61076,3.776859,-3.706425,1310629
18.13,-3.7209,-13.5392,1.35392,0,0,0,0,0,3.7209,3.7209,13.5392,3.791892,-3.7209,1303542
18.23,-3.7395,-13.54901,1.354901,0,0,0,0,0,3.7395,3.7395,13.54901,3.811213,-3.7395,1304234
18.33,-3.755025,-13.33942,1.333942,0,0,0,0,0,3.755025,3.755025,13.33942,3.827342,-3.755025,1283852
18.43,-3.772275,-13.4601,1.34601,0,0,0,0,0,3.772275,3.772275,13.4601,3.845267,-3.772275,1295235
18.53,-3.7884,-13.56147,1.356147,0,0,0,0,0,3.7884,3.7884,13.56147,3.862026,-3.7884,1304771
18.63,-3.806175,-13.64431,1.364431,0,0,0,0,0,3.806175,3.806175,13.64431,3.880502,-3.806175,1312498
18.73,-3.8214,-13.57304,1.357304,0,0,0,0,0,3.8214,3.8214,13.57304,3.896331,-3.8214,1305436
18.83,-3.83985,-13.67087,1.367087,0,0,0,0,0,3.83985,3.83985,13.67087,3.915516,-3.83985,1314593
18.93,-3.8547,-13.76865,1.376865,0,0,0,0,0,3.8547,3.8547,13.76865,3.93096,-3.8547,1323791
19.03,-3.8727,-14.02449,1.402449,0,0,0,0,0,3.8727,3.8727,14.02449,3.949683,-3.8727,1348136
19.13,-3.887625,-14.15969,1.415969,0,0,0,0,0,3.887625,3.887625,14.15969,3.965211,-3.887625,1360922
19.185,-3.898275,-11.62202,1.162202,0,0,0,0,0,3.898275,3.898275,11.62202,3.976292,-3.898275,1116896
19.203,-3.901425,-9.113744,0.9113744,0,0,0,0,0,3.901425,3.901425,9.113744,3.97957,-3.901425,875817.8
19.303,-3.91695,-9.167843,0.9167843,0,0,0,0,0,3.91695,3.91695,9.167843,3.995726,-3.91695,880874.3
19.403,-3.9339,-9.785958,0.9785957,0,0,0,0,0,3.9339,3.9339,9.785957,4.013369,-3.9339,940098.8
19.503,-3.950625,-9.725362,0.9725362,0,0,0,0,0,3.950625,3.950625,9.725362,4.030781,-3.950625,934114.9
19.603,-3.967575,-10.11983,1.011983,0,0,0,0,0,3.967575,3.967575,10.11983,4.048429,-3.967575,971832.1
19.703,-3.98385,-10.4572,1.04572,0,0,0,0,0,3.98385,3.98385,10.4572,4.065378,-3.98385,1004060
19.803,-4.0014,-10.68158,1.068158,0,0,0,0,0,4.0014,4.0014,10.68158,4.083658,-4.0014,1025416
19.804,-4.001625,-10.67267,1.067267,0,0,0,0,0,4.001626,4.001626,10.67267,4.083893,-4.001625,1024559
"Specimen",2
"Specimen label",""
"Width",10.000000,"mm"
"Thickness",1.000000,"mm"
"Anvil height",100.000000,"mm"
"Diameter",10.000000,"mm"
"Inner diameter",8.000000,"mm"
"Outer diameter",10.000000,"mm"
"Wall thickness",1.000000,"mm"
"Area",0.100000,"cm^2"
"Linear density",100.000000,"tex"
"Sled weight",10.000000,"N"
"Loading span",10.000000,"mm"
"Support span",100.000000,"mm"
"Span ratio","2"
"Fixture type","4-point"
"Included"
"Final width",10.000000,"mm"
"Final thickness",1.000000,"mm"
"Final anvil height",100.000000,"mm"
"Final diameter",10.000000,"mm"
"Final Inner diameter",8.000000,"mm"
"Final outer diameter",10.000000,"mm"
"Final wall thickness",1.000000,"mm"
"Final area",0.100000,"cm^2"
"Final linear density",100.000000,"tex"
"Custom text input  1",""
"Custom text input  2",""
"Custom text input  3",""
"Custom text input  4",""
"Custom text input  5",""
"Custom text input  6",""
"Custom text input  7",""
"Custom text input  8",""
"Custom text input  9",""
"Custom text input 10",""
"Custom text input 11",""
"Custom text input 12",""
"Custom text input 13",""
"Custom text input 14",""
"Custom text input 15",""
"Custom text input 16",""
"Custom text input 17",""
"Custom text input 18",""
"Custom text input 19",""
"Custom text input 20",""
"Custom text input 21",""
"Custom text input 22",""
"Custom text input 23",""
"Custom text input 24",""
"Custom text input 25",""
"Custom text input 26",""
"Custom text input 27",""
"Custom text input 28",""
"Custom text input 29",""
"Custom text input 30",""
"Custom text input 31",""
"Custom text input 32",""
"Custom text input 33",""
"Custom text input 34",""
"Custom text input 35",""
"Custom text input 36",""
"Custom text input 37",""
"Custom text input 38",""
"Custom text input 39",""
"Custom text input 40",""
"Custom text input 41",""
"Custom text input 42",""
"Custom text input 43",""
"Custom text input 44",""
"Custom text input 45",""
"Custom text input 46",""
"Custom text input 47",""
"Custom text input 48",""
"Custom text input 49",""
"Custom text input 50",""
"Custom number input  1",0.000000,""
"Custom number input  2",0.000000,""
"Custom number input  3",0.000000,""
"Custom number input  4",0.000000,""
"Custom number input  5",0.000000,""
"Custom number input  6",0.000000,""
"Custom number input  7",0.000000,""
"Custom number input  8",0.000000,""
"Custom number input  9",0.000000,""
"Custom number input 10",0.000000,""
"Time sec","Extension mm","Load N","Compressive stress MPa","Cycle Count ","Total Cycle Count ","Repetitions Count ","Marked Data ","PIP Count ","Compressive extension mm","Compressive strain %","Compressive load N","True strain %","Corrected Position mm","True stress Pa"
0,-0.550425,-0.5784556,0.05784556,0,0,0,0,0,0.5504251,0.5504251,0.5784556,0.5519454,-0.550425,57527.17
0.061,-0.555,-3.08004,0.308004,0,0,0,0,0,0.555,0.555,3.08004,0.5565459,-0.555,306294.6
0.153,-0.5703,-5.610839,0.5610839,0,0,0,0,0,0.5703,0.5703,5.610838,0.5719325,-0.5703,557884
0.181,-0.576375,-8.173876,0.8173876,0,0,0,0,0,0.576375,0.576375,8.173876,0.5780424,-0.576375,812676.3
0.221,-0.5838,-10.69713,1.069713,0,0,0,0,0,0.5838,0.5838,10.69713,0.5855108,-0.5838,1063468
0.27,-0.59295,-13.23233,1.323233,0,0,0,0,0,0.59295,0.59295,13.23233,0.594715,-0.59295,1315387
0.322,-0.601725,-15.77533,1.577533,0,0,0,0,0,0.601725,0.601725,15.77533,0.6035427,-0.601725,1568041
0.379,-0.611025,-18.29204,1.829204,0,0,0,0,0,0.611025,0.611025,18.29204,0.6128994,-0.611025,1818027
0.435,-0.62115,-20.83553,2.083553,0,0,0,0,0,0.62115,0.62115,20.83553,0.6230872,-0.62115,2070611
0.486,-0.62985,-23.36892,2.336893,0,0,0,0,0,0.62985,0.62985,23.36893,0.6318419,-0.62985,2322174
0.5530001,-0.639975,-25.90141,2.590142,0,0,0,0,0,0.639975,0.639975,25.90141,0.6420316,-0.639975,2573565
0.615,-0.650475,-28.40555,2.840555,0,0,0,0,0,0.650475,0.650475,28.40555,0.6525998,-0.650475,2822078
0.68,-0.662475,-30.91244,3.091244,0,0,0,0,0,0.662475,0.662475,30.91244,0.6646791,-0.662475,3070765
0.748,-0.6726,-33.43746,3.343746,0,0,0,0,0,0.6726,0.6726,33.43746,0.6748721,-0.6726,3321256
0.8030001,-0.6825,-35.95106,3.595106,0,0,0,0,0,0.6825,0.6825,35.95106,0.6848397,-0.6825,3570570
0.8570001,-0.691725,-38.46216,3.846216,0,0,0,0,0,0.691725,0.691725,38.46216,0.6941285,-0.691725,3819611
0.9250001,-0.70155,-40.99898,4.099898,0,0,0,0,0,0.7015501,0.7015501,40.99898,0.7040225,-0.70155,4071135
0.9790001,-0.71145,-43.50207,4.350207,0,0,0,0,0,0.71145,0.71145,43.50207,0.7139929,-0.71145,4319257
1.009,-0.716775,-40.88744,4.088744,0,0,0,0,0,0.716775,0.716775,40.88744,0.7193562,-0.716775,4059437
1.013,-0.7176001,-37.76075,3.776075,0,0,0,0,0,0.7176,0.7176,37.76075,0.7201872,-0.7176001,3748978
1.016,-0.718275,-35.19026,3.519026,0,0,0,0,0,0.718275,0.718275,35.19026,0.720867,-0.718275,3493750
1.019,-0.718875,-32.54192,3.254192,0,0,0,0,0,0.7188751,0.7188751,32.54192,0.7214714,-0.718875,3230799
1.022,-0.71955,-29.93212,2.993212,0,0,0,0,0,0.71955,0.71955,29.93212,0.7221513,-0.71955,2971674
1.026,-0.720375,-26.64159,2.664159,0,0,0,0,0,0.7203751,0.7203751,26.64159,0.7229823,-0.720375,2644967
1.03,-0.7212,-23.6635,2.36635,0,0,0,0,0,0.7212,0.7212,23.6635,0.7238132,-0.7212,2349284
1.034,-0.72195,-21.06233,2.106233,0,0,0,0,0,0.7219501,0.7219501,21.06233,0.7245687,-0.72195,2091027
1.039,-0.722925,-18.38489,1.838489,0,0,0,0,0,0.722925,0.722925,18.38489,0.7255508,-0.722925,1825198
1.046,-0.7242,-15.6052,1.56052,0,0,0,0,0,0.7242001,0.7242001,15.6052,0.7268351,-0.7242,1549219
1.057,-0.72585,-13.10231,1.310231,0,0,0,0,0,0.72585,0.72585,13.10231,0.7284971,-0.72585,1300720
1.157,-0.741075,-12.95711,1.295711,0,0,0,0,0,0.741075,0.741075,12.95711,0.7438346,-0.741075,1286109
1.257,-0.75795,-13.0579,1.305789,0,0,0,0,0,0.75795,0.75795,13.05789,0.760837,-0.75795,1295892
1.357,-0.774075,-14.05443,1.405443,0,0,0,0,0,0.774075,0.774075,14.05443,0.7770866,-0.774075,1394564
1.457,-0.792225,-14.57906,1.457906,0,0,0,0,0,0.792225,0.792225,14.57906,0.7953798,-0.792225,1446356
1.549,-0.8058,-12.02426,1.202426,0,0,0,0,0,0.8058,0.8058,12.02426,0.8090641,-0.8058,1192737
1.649,-0.8241,-11.0819,1.10819,0,0,0,0,0,0.8241,0.8241,11.0819,0.8275145,-0.8241,1099057
1.749,-0.83925,-11.544,1.1544,0,0,0,0,0,0.83925,0.83925,11.544,0.8427916,-0.83925,1144711
1.849,-0.85695,-12.68616,1.268616,0,0,0,0,0,0.85695,0.85695,12.68616,0.8606429,-0.85695,1257745
1.949,-0.873,-13.45098,1.345098,0,0,0,0,0,0.873,0.873,13.45098,0.876833,-0.873,1333355
2.049,-0.89055,-14.11208,1.411208,0,0,0,0,0,0.89055,0.89055,14.11208,0.8945391,-0.89055,1398640
2.149,-0.9062251,-15.00878,1.500878,0,0,0,0,0,0.9062251,0.9062251,15.00879,0.9103563,-0.9062251,1487277
2.249,-0.92355,-16.21978,1.621978,0,0,0,0,0,0.9235501,0.9235501,16.21978,0.9278412,-0.92355,1606998
2.349,-0.9393001,-17.07011,1.707011,0,0,0,0,0,0.9393001,0.9393001,17.07011,0.9437393,-0.9393001,1690977
2.449,-0.9576,-18.08036,1.808036,0,0,0,0,0,0.9576,0.9576,18.08036,0.9622145,-0.9576,1790722
2.549,-0.9723,-18.60324,1.860324,0,0,0,0,0,0.9723,0.9723,18.60324,0.9770577,-0.9723,1842236
2.604,-0.9829501,-15.99193,1.599193,0,0,0,0,0,0.9829501,0.9829501,15.99193,0.9878129,-0.9829501,1583473
2.618,-0.98565,-13.34903,1.334903,0,0,0,0,0,0.98565,0.98565,13.34903,0.9905397,-0.98565,1321745
2.639,-0.9894001,-10.80077,1.080077,0,0,0,0,0,0.9894001,0.9894001,10.80077,0.9943272,-0.9894001,1069391
2.739,-1.004475,-9.109125,0.9109125,0,0,0,0,0,1.004475,1.004475,9.109124,1.009554,-1.004475,901762.6
2.839,-1.0218,-9.836644,0.9836644,0,0,0,0,0,1.0218,1.0218,9.836644,1.027056,-1.0218,973613.3
2.939,-1.03815,-10.99754,1.099754,0,0,0,0,0,1.03815,1.03815,10.99754,1.043576,-1.03815,1088337
3.039,-1.055475,-12.27141,1.227141,0,0,0,0,0,1.055475,1.055475,12.27141,1.061085,-1.055475,1214189
3.139,-1.07115,-11.67665,1.167665,0,0,0,0,0,1.07115,1.07115,11.67665,1.076928,-1.07115,1155157
3.239,-1.088625,-11.98169,1.198169,0,0,0,0,0,1.088625,1.088625,11.98169,1.094594,-1.088625,1185125
3.339,-1.104375,-10.03064,1.003064,0,0,0,0,0,1.104375,1.104375,10.03064,1.110518,-1.104375,991986.6
3.439,-1.12245,-8.665264,0.8665265,0,0,0,0,0,1.12245,1.12245,8.665264,1.128797,-1.12245,856800.1
3.539,-1.137075,-9.188086,0.9188086,0,0,0,0,0,1.137075,1.137075,9.188086,1.143589,-1.137075,908361
3.639,-1.155525,-10.49555,1.049555,0,0,0,0,0,1.155525,1.155525,10.49555,1.162253,-1.155525,1037427
3.739,-1.171125,-11.46451,1.146451,0,0,0,0,0,1.171125,1.171125,11.46451,1.178037,-1.171125,1133024
3.839,-1.188225,-12.44934,1.244934,0,0,0,0,0,1.188225,1.188225,12.44934,1.195341,-1.188225,1230141
3.939,-1.2045,-13.19019,1.319019,0,0,0,0,0,1.2045,1.2045,13.19019,1.211813,-1.2045,1303131
4.039,-1.221975,-12.93449,1.293449,0,0,0,0,0,1.221975,1.221975,12.93449,1.229503,-1.221975,1277643
4.139,-1.23765,-12.30632,1.230632,0,0,0,0,0,1.23765,1.23765,12.30632,1.245373,-1.23765,1215401
4.239,-1.25565,-13.51514,1.351514,0,0,0,0,0,1.25565,1.25565,13.51514,1.2636,-1.25565,1334543
4.339,-1.27095,-14.66753,1.466753,0,0,0,0,0,1.27095,1.27095,14.66753,1.279096,-1.27095,1448111
4.439,-1.28895,-15.68522,1.568521,0,0,0,0,0,1.28895,1.28895,15.68522,1.297329,-1.28895,1548304
4.539,-1.304175,-15.52492,1.552492,0,0,0,0,0,1.304175,1.304175,15.52492,1.312754,-1.304175,1532245
4.639,-1.322175,-14.87218,1.487218,0,0,0,0,0,1.322175,1.322175,14.87218,1.330994,-1.322175,1467554
4.739,-1.337925,-15.69331,1.569331,0,0,0,0,0,1.337925,1.337925,15.69331,1.346956,-1.337925,1548334
4.768,-1.34265,-13.16737,1.316737,0,0,0,0,0,1.34265,1.34265,13.16737,1.351745,-1.34265,1299057
4.868,-1.3605,-11.58594,1.158594,0,0,0,0,0,1.3605,1.3605,11.58594,1.36984,-1.3605,1142832
4.968,-1.3758,-11.83289,1.183289,0,0,0,0,0,1.3758,1.3758,11.83289,1.385352,-1.3758,1167009
5.068,-1.394025,-12.71623,1.271623,0,0,0,0,0,1.394025,1.394025,12.71623,1.403833,-1.394025,1253896
5.168,-1.4085,-13.43518,1.343518,0,0,0,0,0,1.4085,1.4085,13.43518,1.418513,-1.4085,1324595
5.268,-1.4271,-14.74687,1.474687,0,0,0,0,0,1.4271,1.4271,14.74687,1.437381,-1.4271,1453642
5.368,-1.4427,-15.60775,1.560775,0,0,0,0,0,1.4427,1.4427,15.60775,1.453208,-1.4427,1538258
5.468,-1.459875,-16.81048,1.681048,0,0,0,0,0,1.459875,1.459875,16.81048,1.470636,-1.459875,1656507
5.568,-1.476075,-18.05712,1.805712,0,0,0,0,0,1.476075,1.476075,18.05712,1.487077,-1.476075,1779058
5.668,-1.4937,-18.60029,1.860029,0,0,0,0,0,1.4937,1.4937,18.60028,1.504968,-1.4937,1832245
5.768,-1.50945,-19.49704,1.949704,0,0,0,0,0,1.50945,1.50945,19.49704,1.520958,-1.50945,1920275
5.868,-1.5276,-20.3392,2.03392,0,0,0,0,0,1.5276,1.5276,20.3392,1.539388,-1.5276,2002850
5.968,-1.5426,-21.11088,2.111089,0,0,0,0,0,1.5426,1.5426,21.11089,1.554622,-1.5426,2078523
6.068,-1.560675,-20.76334,2.076334,0,0,0,0,0,1.560675,1.560675,20.76334,1.572982,-1.560675,2043929
6.104,-1.565925,-18.24839,1.824839,0,0,0,0,0,1.565925,1.565925,18.24839,1.578315,-1.565925,1796264
6.204,-1.582725,-19.12594,1.912594,0,0,0,0,0,1.582725,1.582725,19.12594,1.595384,-1.582725,1882323
6.299,-1.598475,-16.56277,1.656277,0,0,0,0,0,1.598475,1.598475,16.56277,1.611388,-1.598475,1629802
6.362,-1.6086,-14.03008,1.403008,0,0,0,0,0,1.6086,1.6086,14.03008,1.621678,-1.6086,1380440
6.372,-1.610325,-11.31064,1.131064,0,0,0,0,0,1.610325,1.610325,11.31064,1.623432,-1.610325,1112850
6.382,-1.612125,-8.793987,0.8793987,0,0,0,0,0,1.612125,1.612125,8.793987,1.625261,-1.612125,865221.7
6.399,-1.61505,-6.254576,0.6254576,0,0,0,0,0,1.61505,1.61505,6.254576,1.628234,-1.61505,615356.2
6.499,-1.631775,-6.585352,0.6585352,0,0,0,0,0,1.631775,1.631775,6.585352,1.645235,-1.631775,647789.4
6.599,-1.647825,-7.021919,0.7021919,0,0,0,0,0,1.647825,1.647825,7.021919,1.661553,-1.647825,690621
6.699,-1.665675,-7.703453,0.7703453,0,0,0,0,0,1.665675,1.665675,7.703453,1.679703,-1.665675,757513.8
6.799,-1.680675,-8.261994,0.8261994,0,0,0,0,0,1.680675,1.680675,8.261993,1.694959,-1.680675,812313.6
6.899,-1.69845,-8.889809,0.8889809,0,0,0,0,0,1.69845,1.69845,8.88981,1.713039,-1.69845,873882
6.999,-1.714725,-9.416461,0.9416461,0,0,0,0,0,1.714725,1.714725,9.416461,1.729597,-1.714725,925499.5
7.099,-1.73115,-10.02709,1.002709,0,0,0,0,0,1.73115,1.73115,10.02709,1.74631,-1.73115,985350.4
7.199,-1.74855,-10.64168,1.064168,0,0,0,0,0,1.74855,1.74855,10.64168,1.764018,-1.74855,1045560
7.299,-1.7646,-11.05617,1.105617,0,0,0,0,0,1.7646,1.7646,11.05617,1.780355,-1.7646,1086107
7.399,-1.78125,-11.40149,1.140149,0,0,0,0,0,1.78125,1.78125,11.40149,1.797305,-1.78125,1119840
7.499,-1.79865,-11.85065,1.185065,0,0,0,0,0,1.79865,1.79865,11.85065,1.815022,-1.79865,1163750
7.599,-1.814625,-10.75625,1.075625,0,0,0,0,0,1.814625,1.814625,10.75625,1.831291,-1.814625,1056107
7.699,-1.832025,-10.96823,1.096823,0,0,0,0,0,1.832025,1.832025,10.96823,1.849014,-1.832025,1076729
7.799,-1.847475,-11.7043,1.17043,0,0,0,0,0,1.847475,1.847475,11.7043,1.864754,-1.847475,1148806
7.899,-1.86525,-12.43077,1.243077,0,0,0,0,0,1.86525,1.86525,12.43077,1.882865,-1.86525,1219891
7.999,-1.88205,-13.06023,1.306023,0,0,0,0,0,1.88205,1.88205,13.06023,1.899986,-1.88205,1281443
8.081,-1.8954,-10.43459,1.043459,0,0,0,0,0,1.8954,1.8954,10.43459,1.913593,-1.8954,1023681
8.109,-1.89945,-7.918857,0.7918857,0,0,0,0,0,1.89945,1.89945,7.918857,1.917721,-1.89945,776844.2
8.209001,-1.916475,-8.660972,0.8660973,0,0,0,0,0,1.916475,1.916475,8.660973,1.935077,-1.916475,849498.8
8.309,-1.93365,-7.543005,0.7543005,0,0,0,0,0,1.93365,1.93365,7.543005,1.95259,-1.93365,739715
8.409,-1.9494,-8.279525,0.8279525,0,0,0,0,0,1.9494,1.9494,8.279525,1.968651,-1.9494,811812.4
8.509001,-1.967025,-8.879274,0.8879274,0,0,0,0,0,1.967025,1.967025,8.879274,1.986628,-1.967025,870461.7
8.609,-1.98285,-9.432711,0.943271,0,0,0,0,0,1.98285,1.98285,9.432711,2.002772,-1.98285,924567.4
8.709001,-2.0001,-9.681106,0.9681106,0,0,0,0,0,2.0001,2.0001,9.681106,2.020373,-2.0001,948747.4
8.809,-2.016525,-9.465963,0.9465963,0,0,0,0,0,2.016525,2.016525,9.465962,2.037134,-2.016525,927507.9
8.909,-2.032875,-9.419441,0.9419441,0,0,0,0,0,2.032875,2.032875,9.419441,2.053822,-2.032875,922795.6
9.009001,-2.05005,-9.943187,0.9943188,0,0,0,0,0,2.05005,2.05005,9.943188,2.071355,-2.05005,973934.8
9.109,-2.065725,-11.09383,1.109383,0,0,0,0,0,2.065725,2.065725,11.09383,2.08736,-2.065725,1086466
9.209001,-2.082825,-11.79352,1.179352,0,0,0,0,0,2.082825,2.082825,11.79352,2.104822,-2.082825,1154789
9.309,-2.100075,-12.37839,1.23784,0,0,0,0,0,2.100075,2.100075,12.3784,2.12244,-2.100075,1211844
9.409,-2.1159,-12.71071,1.27107,0,0,0,0,0,2.1159,2.1159,12.71071,2.138606,-2.1159,1244176
9.509001,-2.133375,-13.70745,1.370745,0,0,0,0,0,2.133375,2.133375,13.70745,2.15646,-2.133375,1341502
9.609,-2.1501,-14.51951,1.451951,0,0,0,0,0,2.1501,2.1501,14.51951,2.173552,-2.1501,1420732
9.709001,-2.16645,-15.09916,1.509916,0,0,0,0,0,2.16645,2.16645,15.09916,2.190262,-2.16645,1477204
9.809,-2.18385,-15.29001,1.529001,0,0,0,0,0,2.18385,2.18385,15.29001,2.208049,-2.18385,1495610
9.909,-2.19975,-15.74109,1.57411,0,0,0,0,0,2.19975,2.19975,15.74109,2.224305,-2.19975,1539483
10.009,-2.2167,-16.07331,1.607331,0,0,0,0,0,2.2167,2.2167,16.07331,2.241638,-2.2167,1571701
10.109,-2.2332,-14.14895,1.414895,0,0,0,0,0,2.2332,2.2332,14.14895,2.258513,-2.2332,1383298
10.209,-2.25,-15.24612,1.524612,0,0,0,0,0,2.25,2.25,15.24612,2.275699,-2.25,1490309
[...]
"Final Inner diameter",8.000000,"mm"
"Final outer diameter",10.000000,"mm"
"Final wall thickness",1.000000,"mm"
"Final area",0.100000,"cm^2"
"Final linear density",100.000000,"tex"
"Custom text input  1",""
"Custom text input  2",""
"Custom text input  3",""
"Custom text input  4",""
"Custom text input  5",""
"Custom text input  6",""
"Custom text input  7",""
"Custom text input  8",""
"Custom text input  9",""
"Custom text input 10",""
"Custom text input 11",""
"Custom text input 12",""
"Custom text input 13",""
"Custom text input 14",""
"Custom text input 15",""
"Custom text input 16",""
"Custom text input 17",""
"Custom text input 18",""
"Custom text input 19",""
"Custom text input 20",""
"Custom text input 21",""
"Custom text input 22",""
"Custom text input 23",""
"Custom text input 24",""
"Custom text input 25",""
"Custom text input 26",""
"Custom text input 27",""
"Custom text input 28",""
"Custom text input 29",""
"Custom text input 30",""
"Custom text input 31",""
"Custom text input 32",""
"Custom text input 33",""
"Custom text input 34",""
"Custom text input 35",""
"Custom text input 36",""
"Custom text input 37",""
"Custom text input 38",""
"Custom text input 39",""
"Custom text input 40",""
"Custom text input 41",""
"Custom text input 42",""
"Custom text input 43",""
"Custom text input 44",""
"Custom text input 45",""
"Custom text input 46",""
"Custom text input 47",""
"Custom text input 48",""
"Custom text input 49",""
"Custom text input 50",""
"Custom number input  1",0.000000,""
"Custom number input  2",0.000000,""
"Custom number input  3",0.000000,""
"Custom number input  4",0.000000,""
"Custom number input  5",0.000000,""
"Custom number input  6",0.000000,""
"Custom number input  7",0.000000,""
"Custom number input  8",0.000000,""
"Custom number input  9",0.000000,""
"Custom number input 10",0.000000,""
"Time sec","Extension mm","Load N","Compressive stress MPa","Cycle Count ","Total Cycle Count ","Repetitions Count ","Marked Data ","PIP Count ","Compressive extension mm","Compressive strain %","Compressive load N","True strain %","Corrected Position mm","True stress Pa"
0,-0.381975,-0.5486906,0.05486906,0,0,0,0,0,0.381975,0.381975,0.5486906,0.3827064,-0.381975,54659.47
0.1,-0.386475,-2.509646,0.2509646,0,0,0,0,0,0.386475,0.386475,2.509646,0.3872237,-0.386475,249994.7
0.162,-0.404475,-5.07585,0.5075849,0,0,0,0,0,0.404475,0.404475,5.07585,0.4052952,-0.404475,505531.9
0.2,-0.41145,-7.611118,0.7611119,0,0,0,0,0,0.41145,0.41145,7.611118,0.4122988,-0.41145,757980.2
0.261,-0.422475,-10.11914,1.011914,0,0,0,0,0,0.422475,0.422475,10.11914,0.42337,-0.422475,1007639
0.325,-0.433275,-12.62933,1.262933,0,0,0,0,0,0.433275,0.433275,12.62933,0.4342164,-0.433275,1257461
0.386,-0.44445,-15.13225,1.513225,0,0,0,0,0,0.44445,0.44445,15.13225,0.4454406,-0.44445,1506499
0.457,-0.4551,-17.63245,1.763245,0,0,0,0,0,0.4551,0.4551,17.63245,0.4561387,-0.4551,1755221
0.527,-0.466875,-20.17,2.016999,0,0,0,0,0,0.466875,0.466875,20.17,0.4679683,-0.466875,2007583
0.586,-0.47775,-22.70968,2.270968,0,0,0,0,0,0.47775,0.47775,22.70968,0.4788949,-0.47775,2260119
0.656,-0.488325,-25.2374,2.52374,0,0,0,0,0,0.488325,0.488325,25.2374,0.4895212,-0.488325,2511416
0.72,-0.4995,-27.74873,2.774873,0,0,0,0,0,0.4995,0.4995,27.74873,0.5007517,-0.4995,2761012
0.777,-0.5094,-30.25025,3.025025,0,0,0,0,0,0.5094,0.5094,30.25025,0.5107019,-0.5094,3009616
0.8470001,-0.519675,-32.75418,3.275418,0,0,0,0,0,0.519675,0.519675,32.75418,0.52103,-0.519675,3258396
0.9070001,-0.53055,-35.27144,3.527143,0,0,0,0,0,0.53055,0.53055,35.27143,0.5319624,-0.53055,3508430
0.9650001,-0.54075,-37.79452,3.779452,0,0,0,0,0,0.54075,0.54075,37.79452,0.5422174,-0.54075,3759015
1.027,-0.550125,-40.309,4.0309,0,0,0,0,0,0.550125,0.550125,40.309,0.5516438,-0.550125,4008725
1.09,-0.560625,-42.81396,4.281396,0,0,0,0,0,0.5606251,0.5606251,42.81396,0.5622024,-0.560625,4257394
1.15,-0.570825,-45.35137,4.535137,0,0,0,0,0,0.570825,0.570825,45.35137,0.5724604,-0.570825,4509249
1.21,-0.58095,-47.86192,4.786192,0,0,0,0,0,0.58095,0.58095,47.86192,0.5826441,-0.58095,4758387
1.273,-0.59145,-50.39588,5.039587,0,0,0,0,0,0.59145,0.59145,50.39588,0.593206,-0.59145,5009781
1.336,-0.6021,-52.93028,5.293028,0,0,0,0,0,0.6021,0.6021,52.93028,0.6039199,-0.6021,5261159
1.346,-0.6042,-49.82693,4.982693,0,0,0,0,0,0.6042,0.6042,49.82693,0.6060327,-0.6042,4952587
1.349,-0.60495,-47.06462,4.706462,0,0,0,0,0,0.60495,0.60495,47.06462,0.6067872,-0.60495,4677990
1.352,-0.6057,-43.86123,4.386123,0,0,0,0,0,0.6057,0.6057,43.86123,0.6075418,-0.6057,4359556
1.355,-0.606375,-40.44144,4.044144,0,0,0,0,0,0.606375,0.606375,40.44144,0.608221,-0.606375,4019621
1.358,-0.607125,-36.91318,3.691318,0,0,0,0,0,0.607125,0.607125,36.91318,0.6089755,-0.607125,3668907
1.361,-0.607875,-33.43801,3.343801,0,0,0,0,0,0.607875,0.607875,33.43801,0.6097301,-0.607875,3323475
1.364,-0.60855,-30.1212,3.01212,0,0,0,0,0,0.60855,0.60855,30.1212,0.6104092,-0.60855,2993790
1.367,-0.60915,-26.99845,2.699845,0,0,0,0,0,0.6091501,0.6091501,26.99845,0.6110129,-0.60915,2683399
1.37,-0.60975,-24.15915,2.415915,0,0,0,0,0,0.60975,0.60975,24.15915,0.6116166,-0.60975,2401184
1.373,-0.61035,-21.61167,2.161167,0,0,0,0,0,0.6103501,0.6103501,21.61167,0.6122203,-0.61035,2147976
1.377,-0.611025,-18.67122,1.867122,0,0,0,0,0,0.611025,0.611025,18.67122,0.6128994,-0.611025,1855714
1.382,-0.611775,-15.7468,1.57468,0,0,0,0,0,0.611775,0.611775,15.7468,0.613654,-0.611775,1565047
1.388,-0.6126,-13.23725,1.323725,0,0,0,0,0,0.6126,0.6126,13.23725,0.6144841,-0.6126,1315615
1.401,-0.6141,-10.6573,1.06573,0,0,0,0,0,0.6141,0.6141,10.6573,0.6159934,-0.6141,1059185
1.501,-0.629025,-12.47044,1.247044,0,0,0,0,0,0.629025,0.629025,12.47044,0.6310117,-0.629025,1239200
1.601,-0.64695,-12.83237,1.283237,0,0,0,0,0,0.6469501,0.6469501,12.83237,0.6490519,-0.64695,1274935
1.701,-0.663,-12.95856,1.295856,0,0,0,0,0,0.663,0.663,12.95856,0.6652077,-0.663,1287265
1.801,-0.6795001,-13.12607,1.312607,0,0,0,0,0,0.6795,0.6795,13.12607,0.6818192,-0.6795001,1303688
1.901,-0.696225,-12.62884,1.262884,0,0,0,0,0,0.696225,0.696225,12.62884,0.69866,-0.696225,1254091
2.001,-0.71355,-12.91653,1.291653,0,0,0,0,0,0.71355,0.71355,12.91653,0.716108,-0.71355,1282436
2.101,-0.72915,-13.07716,1.307716,0,0,0,0,0,0.72915,0.72915,13.07716,0.7318213,-0.72915,1298181
2.201,-0.746775,-13.10825,1.310825,0,0,0,0,0,0.746775,0.746775,13.10825,0.7495773,-0.746775,1301036
2.301,-0.7626,-13.08991,1.308991,0,0,0,0,0,0.7626001,0.7626001,13.08991,0.7655227,-0.7626,1299009
2.381,-0.777,-10.51287,1.051287,0,0,0,0,0,0.777,0.777,10.51287,0.7800344,-0.777,1043118
2.481,-0.792,-8.895151,0.8895152,0,0,0,0,0,0.7920001,0.7920001,8.895151,0.795153,-0.792,882470.2
2.581,-0.809925,-9.278409,0.9278409,0,0,0,0,0,0.809925,0.809925,9.278409,0.8132227,-0.809925,920326.1
2.681,-0.825975,-9.492882,0.9492881,0,0,0,0,0,0.8259751,0.8259751,9.492882,0.8294051,-0.825975,941447.3
2.781,-0.843225,-9.738401,0.9738401,0,0,0,0,0,0.8432251,0.8432251,9.7384,0.8468003,-0.843225,965628.4
2.881,-0.8595751,-9.027541,0.9027539,0,0,0,0,0,0.859575,0.859575,9.02754,0.8632907,-0.8595751,894994.1
2.981,-0.8769,-8.849397,0.8849397,0,0,0,0,0,0.8769,0.8769,8.849398,0.8807674,-0.8769,877179.7
3.081,-0.89295,-9.17314,0.917314,0,0,0,0,0,0.8929501,0.8929501,9.17314,0.8969607,-0.89295,909122.8
3.181,-0.910425,-9.186871,0.9186871,0,0,0,0,0,0.910425,0.910425,9.186872,0.9145947,-0.910425,910323.2
3.281,-0.92595,-9.00539,0.900539,0,0,0,0,0,0.92595,0.92595,9.00539,0.9302636,-0.92595,892200.5
3.381,-0.94365,-8.895323,0.8895323,0,0,0,0,0,0.94365,0.94365,8.895323,0.9481306,-0.94365,881138.2
3.481,-0.9591,-8.808471,0.8808471,0,0,0,0,0,0.9591,0.9591,8.808472,0.963729,-0.9591,872398.9
3.581,-0.976725,-9.045407,0.9045407,0,0,0,0,0,0.976725,0.976725,9.045407,0.9815263,-0.976725,895705.8
3.681,-0.9927,-8.933321,0.8933321,0,0,0,0,0,0.9927,0.9927,8.933321,0.9976601,-0.9927,884464
3.781,-1.009575,-9.063557,0.9063557,0,0,0,0,0,1.009575,1.009575,9.063557,1.014706,-1.009575,897205.3
3.881,-1.026225,-9.054758,0.9054757,0,0,0,0,0,1.026225,1.026225,9.054758,1.031527,-1.026225,896183.5
3.981,-1.04385,-9.154364,0.9154364,0,0,0,0,0,1.04385,1.04385,9.154365,1.049336,-1.04385,905880.7
4.081,-1.059075,-9.09809,0.909809,0,0,0,0,0,1.059075,1.059075,9.09809,1.064723,-1.059075,900173.5
4.181,-1.077075,-9.20777,0.920777,0,0,0,0,0,1.077075,1.077075,9.20777,1.082917,-1.077075,910859.6
4.281,-1.092525,-9.10648,0.910648,0,0,0,0,0,1.092525,1.092525,9.10648,1.098537,-1.092525,900698.9
4.381,-1.109925,-9.249851,0.9249851,0,0,0,0,0,1.109925,1.109925,9.249851,1.116131,-1.109925,914718.5
4.481,-1.125825,-9.228669,0.9228669,0,0,0,0,0,1.125825,1.125825,9.228669,1.13221,-1.125825,912477
4.581,-1.143375,-9.320058,0.9320058,0,0,0,0,0,1.143375,1.143375,9.320058,1.149962,-1.143375,921349.5
4.681,-1.1592,-9.189755,0.9189755,0,0,0,0,0,1.1592,1.1592,9.189754,1.165971,-1.1592,908322.7
4.781,-1.176225,-9.269215,0.9269215,0,0,0,0,0,1.176225,1.176225,9.269216,1.183197,-1.176225,916018.8
4.881,-1.19295,-9.021059,0.9021059,0,0,0,0,0,1.19295,1.19295,9.021059,1.200123,-1.19295,891344.2
4.981,-1.210425,-8.779176,0.8779175,0,0,0,0,0,1.210425,1.210425,8.779176,1.21781,-1.210425,867291
5.081,-1.225725,-9.096444,0.9096442,0,0,0,0,0,1.225725,1.225725,9.096443,1.233299,-1.225725,898494.5
5.181,-1.24395,-9.207554,0.9207554,0,0,0,0,0,1.24395,1.24395,9.207554,1.251752,-1.24395,909301.7
5.281,-1.2594,-9.340659,0.9340659,0,0,0,0,0,1.2594,1.2594,9.340659,1.267398,-1.2594,922302.3
5.381,-1.276425,-9.431288,0.9431288,0,0,0,0,0,1.276425,1.276425,9.431288,1.284641,-1.276425,931090.4
5.481,-1.292775,-9.461232,0.9461231,0,0,0,0,0,1.292775,1.292775,9.461231,1.301204,-1.292775,933891.9
5.581,-1.31025,-9.613357,0.9613358,0,0,0,0,0,1.31025,1.31025,9.613358,1.31891,-1.31025,948739.8
5.681,-1.326075,-9.568088,0.9568088,0,0,0,0,0,1.326075,1.326075,9.568088,1.334946,-1.326075,944120.8
5.781,-1.34325,-9.628586,0.9628587,0,0,0,0,0,1.34325,1.34325,9.628587,1.352353,-1.34325,949925
5.881,-1.35915,-9.698145,0.9698145,0,0,0,0,0,1.35915,1.35915,9.698145,1.368471,-1.35915,956633.3
5.981,-1.377,-9.754054,0.9754055,0,0,0,0,0,1.377,1.377,9.754054,1.386569,-1.377,961974.1
6.081,-1.39215,-9.838492,0.9838492,0,0,0,0,0,1.39215,1.39215,9.838491,1.401931,-1.39215,970152.5
6.181,-1.41,-9.897277,0.9897277,0,0,0,0,0,1.41,1.41,9.897277,1.420035,-1.41,975772.5
6.281,-1.42605,-9.906955,0.9906955,0,0,0,0,0,1.42605,1.42605,9.906955,1.436316,-1.42605,976567.7
6.381,-1.443225,-10.02848,1.002848,0,0,0,0,0,1.443225,1.443225,10.02848,1.453741,-1.443225,988374.8
6.481,-1.4595,-10.01539,1.001539,0,0,0,0,0,1.4595,1.4595,10.01539,1.470256,-1.4595,986921.6
6.581,-1.476675,-9.794742,0.9794742,0,0,0,0,0,1.476675,1.476675,9.794742,1.487686,-1.476675,965010.5
6.681,-1.49295,-9.705402,0.9705402,0,0,0,0,0,1.49295,1.49295,9.705402,1.504207,-1.49295,956050.5
6.781,-1.510575,-9.528197,0.9528197,0,0,0,0,0,1.510575,1.510575,9.528197,1.5221,-1.510575,938426.7
6.881,-1.5261,-9.466052,0.9466052,0,0,0,0,0,1.5261,1.5261,9.466052,1.537865,-1.5261,932159.1
6.981,-1.543725,-9.479649,0.9479649,0,0,0,0,0,1.543725,1.543725,9.47965,1.555765,-1.543725,933331
7.081,-1.559025,-9.489581,0.9489581,0,0,0,0,0,1.559025,1.559025,9.489581,1.571306,-1.559025,934163.6
7.181,-1.5768,-9.628281,0.9628281,0,0,0,0,0,1.5768,1.5768,9.628281,1.589364,-1.5768,947646.2
7.281,-1.592775,-9.486243,0.9486243,0,0,0,0,0,1.592775,1.592775,9.486243,1.605596,-1.592775,933514.9
7.381,-1.60965,-9.319469,0.9319469,0,0,0,0,0,1.60965,1.60965,9.319469,1.622746,-1.60965,916945.8
7.481,-1.626225,-9.176381,0.9176381,0,0,0,0,0,1.626225,1.626225,9.176381,1.639593,-1.626225,902715.2
7.581,-1.64385,-9.171255,0.9171255,0,0,0,0,0,1.64385,1.64385,9.171255,1.657511,-1.64385,902049.3
7.681,-1.658925,-9.155035,0.9155035,0,0,0,0,0,1.658925,1.658925,9.155035,1.672839,-1.658925,900316
7.781,-1.677,-9.217471,0.9217471,0,0,0,0,0,1.677,1.677,9.217471,1.691221,-1.677,906289.4
7.881,-1.692525,-9.332679,0.933268,0,0,0,0,0,1.692525,1.692525,9.332679,1.707012,-1.692525,917472.1
7.981,-1.70985,-8.824535,0.8824534,0,0,0,0,0,1.70985,1.70985,8.824534,1.724637,-1.70985,867364.8
8.081,-1.725825,-8.839339,0.8839339,0,0,0,0,0,1.725825,1.725825,8.839339,1.740891,-1.725825,868678.7
8.181,-1.74315,-8.93268,0.893268,0,0,0,0,0,1.74315,1.74315,8.93268,1.758522,-1.74315,877697
8.281,-1.7592,-9.017266,0.9017266,0,0,0,0,0,1.7592,1.7592,9.017266,1.774858,-1.7592,885863.5
8.381001,-1.77615,-9.121574,0.9121574,0,0,0,0,0,1.77615,1.77615,9.121574,1.792113,-1.77615,895956.2
8.481,-1.79265,-9.21578,0.9215779,0,0,0,0,0,1.79265,1.79265,9.215779,1.808913,-1.79265,905057.3
8.581,-1.810425,-9.301543,0.9301543,0,0,0,0,0,1.810425,1.810425,9.301543,1.827014,-1.810425,913314.6
8.681001,-1.8258,-9.388126,0.9388126,0,0,0,0,0,1.8258,1.8258,9.388126,1.842673,-1.8258,921671.8
8.781,-1.843875,-9.514116,0.9514116,0,0,0,0,0,1.843875,1.843875,9.514115,1.861086,-1.843875,933868.7
8.881001,-1.859475,-9.562284,0.9562284,0,0,0,0,0,1.859475,1.859475,9.562284,1.876981,-1.859475,938447.5
8.981001,-1.876425,-9.580232,0.9580232,0,0,0,0,0,1.876425,1.876425,9.580233,1.894253,-1.876425,940046.6
9.081,-1.89285,-9.641394,0.9641394,0,0,0,0,0,1.89285,1.89285,9.641394,1.910994,-1.89285,945889.7
9.181001,-1.9101,-9.711511,0.9711511,0,0,0,0,0,1.9101,1.9101,9.711512,1.928578,-1.9101,952601.2
9.281,-1.926075,-9.747818,0.9747818,0,0,0,0,0,1.926075,1.926075,9.747818,1.944866,-1.926075,956006.8
9.381001,-1.943475,-9.788387,0.9788387,0,0,0,0,0,1.943475,1.943475,9.788386,1.962609,-1.943475,959815.2
9.481001,-1.95915,-9.809256,0.9809256,0,0,0,0,0,1.95915,1.95915,9.809256,1.978596,-1.95915,961707.8
9.581,-1.977,-9.817772,0.9817772,0,0,0,0,0,1.977,1.977,9.817772,1.996804,-1.977,962367.4
9.681001,-1.99215,-9.868562,0.9868563,0,0,0,0,0,1.99215,1.99215,9.868563,2.012261,-1.99215,967196.7
9.781,-2.00985,-9.945907,0.9945906,0,0,0,0,0,2.00985,2.00985,9.945907,2.030322,-2.00985,974600.9
9.881001,-2.02605,-9.936854,0.9936854,0,0,0,0,0,2.02605,2.02605,9.936854,2.046856,-2.02605,973552.9
9.981001,-2.043,-9.996913,0.9996914,0,0,0,0,0,2.043,2.043,9.996913,2.064158,-2.043,979267.6
10.081,-2.059425,-9.958088,0.9958087,0,0,0,0,0,2.059425,2.059425,9.958088,2.080927,-2.059425,975300.8
10.181,-2.076975,-9.794228,0.9794228,0,0,0,0,0,2.076975,2.076975,9.794228,2.098848,-2.076975,959080.4
10.281,-2.092725,-9.556867,0.9556867,0,0,0,0,0,2.092725,2.092725,9.556868,2.114933,-2.092725,935686.8
10.381,-2.110575,-9.531714,0.9531714,0,0,0,0,0,2.110575,2.110575,9.531714,2.133166,-2.110575,933054
10.481,-2.125875,-9.512961,0.951296,0,0,0,0,0,2.125875,2.125875,9.51296,2.148797,-2.125875,931072.6
10.581,-2.1438,-9.570211,0.9570211,0,0,0,0,0,2.1438,2.1438,9.570211,2.167113,-2.1438,936504.5
10.681,-2.15895,-9.60499,0.9604989,0,0,0,0,0,2.15895,2.15895,9.60499,2.182596,-2.15895,939762.3
10.781,-2.176725,-9.723954,0.9723954,0,0,0,0,0,2.176725,2.176725,9.723954,2.200765,-2.176725,951229
10.881,-2.193,-9.802707,0.9802706,0,0,0,0,0,2.193,2.193,9.802707,2.217404,-2.193,958773.3
10.981,-2.2095,-9.074166,0.9074166,0,0,0,0,0,2.2095,2.2095,9.074166,2.234275,-2.2095,887367.3
11.081,-2.226225,-8.423895,0.8423895,0,0,0,0,0,2.226225,2.226225,8.423895,2.25138,-2.226225,823636
11.181,-2.243775,-7.533669,0.7533669,0,0,0,0,0,2.243775,2.243775,7.533669,2.269331,-2.243775,736463.1
11.233,-2.251575,-4.995547,0.4995547,0,0,0,0,0,2.251575,2.251575,4.995547,2.27731,-2.251575,488306.9
11.333,-2.268,-4.15922,0.415922,0,0,0,0,0,2.268,2.268,4.15922,2.294115,-2.268,406488.8
11.433,-2.284575,-4.131109,0.4131108,0,0,0,0,0,2.284575,2.284575,4.131108,2.311076,-2.284575,403673
11.533,-2.30205,-4.173458,0.4173458,0,0,0,0,0,2.30205,2.30205,4.173458,2.328961,-2.30205,407738.3
11.633,-2.317425,-4.186481,0.4186482,0,0,0,0,0,2.317425,2.317425,4.186481,2.3447,-2.317425,408946.3
11.733,-2.3349,-4.175104,0.4175104,0,0,0,0,0,2.3349,2.3349,4.175104,2.362591,-2.3349,407762
11.833,-2.351175,-4.152328,0.4152327,0,0,0,0,0,2.351175,2.351175,4.152328,2.379256,-2.351175,405469.9
11.933,-2.368125,-4.276089,0.4276089,0,0,0,0,0,2.368125,2.368125,4.276089,2.396616,-2.368125,417482.6
12.033,-2.38485,-4.35143,0.435143,0,0,0,0,0,2.38485,2.38485,4.351429,2.413748,-2.38485,424765.5
12.133,-2.401425,-4.329041,0.4329041,0,0,0,0,0,2.401425,2.401425,4.329041,2.430729,-2.401425,422508.2
12.233,-2.418075,-4.328154,0.4328154,0,0,0,0,0,2.418075,2.418075,4.328154,2.44779,-2.418075,422349.6
12.333,-2.4348,-4.148588,0.4148588,0,0,0,0,0,2.4348,2.4348,4.148588,2.464932,-2.4348,404757.8
12.433,-2.451525,-4.262552,0.4262552,0,0,0,0,0,2.451525,2.451525,4.262552,2.482075,-2.451525,415805.4
12.533,-2.468625,-4.484557,0.4484557,0,0,0,0,0,2.468625,2.468625,4.484557,2.499607,-2.468625,437385
12.633,-2.4843,-4.509211,0.4509211,0,0,0,0,0,2.4843,2.4843,4.509211,2.51568,-2.4843,439718.8
12.733,-2.501625,-4.547559,0.4547559,0,0,0,0,0,2.501625,2.501625,4.547559,2.533448,-2.501625,443379.6
12.833,-2.5185,-4.724294,0.4724293,0,0,0,0,0,2.5185,2.5185,4.724294,2.550757,-2.5185,460531.2
12.933,-2.534475,-4.868969,0.4868969,0,0,0,0,0,2.534475,2.534475,4.868969,2.567146,-2.534475,474556.7
13.033,-2.551725,-5.007863,0.5007863,0,0,0,0,0,2.551725,2.551725,5.007863,2.584846,-2.551725,488007.6
13.133,-2.568375,-4.540481,0.4540481,0,0,0,0,0,2.568375,2.568375,4.540481,2.601934,-2.568375,442386.4
13.233,-2.58465,-4.709169,0.4709169,0,0,0,0,0,2.58465,2.58465,4.709169,2.618639,-2.58465,458745.4
13.333,-2.601825,-4.94425,0.494425,0,0,0,0,0,2.601825,2.601825,4.94425,2.636271,-2.601825,481560.9
13.433,-2.617875,-5.166009,0.5166009,0,0,0,0,0,2.617875,2.617875,5.166009,2.652751,-2.617875,503076.9
13.533,-2.6349,-5.367078,0.5367078,0,0,0,0,0,2.6349,2.6349,5.367078,2.670236,-2.6349,522566.1
13.633,-2.65095,-5.574837,0.5574837,0,0,0,0,0,2.65095,2.65095,5.574837,2.686721,-2.65095,542705.1
13.733,-2.667825,-5.76435,0.576435,0,0,0,0,0,2.667825,2.667825,5.76435,2.704058,-2.667825,561056.8
13.833,-2.6844,-5.959034,0.5959034,0,0,0,0,0,2.6844,2.6844,5.959034,2.721088,-2.6844,579907
13.933,-2.701125,-6.140888,0.6140888,0,0,0,0,0,2.701125,2.701125,6.140888,2.738276,-2.701125,597501.5
14.033,-2.718075,-6.355226,0.6355226,0,0,0,0,0,2.718075,2.718075,6.355226,2.755698,-2.718075,618248.6
14.133,-2.735475,-6.552964,0.6552964,0,0,0,0,0,2.735475,2.735475,6.552964,2.773586,-2.735475,637370.9
14.233,-2.75115,-6.694034,0.6694034,0,0,0,0,0,2.75115,2.75115,6.694034,2.789703,-2.75115,650987.1
14.333,-2.768925,-6.834969,0.6834969,0,0,0,0,0,2.768925,2.768925,6.834969,2.807983,-2.768925,664571.4
14.433,-2.7846,-6.99988,0.6999879,0,0,0,0,0,2.7846,2.7846,6.99988,2.824105,-2.7846,680496.1
14.533,-2.801625,-7.20375,0.7203751,0,0,0,0,0,2.801625,2.801625,7.20375,2.841619,-2.801625,700192.8
14.633,-2.818275,-7.395178,0.7395177,0,0,0,0,0,2.818275,2.818275,7.395178,2.858751,-2.818275,718676.1
14.733,-2.83485,-7.567562,0.7567562,0,0,0,0,0,2.83485,2.83485,7.567562,2.875808,-2.83485,735303.3
14.833,-2.851425,-7.734843,0.7734842,0,0,0,0,0,2.851425,2.851425,7.734843,2.892868,-2.851425,751428.9
14.933,-2.867925,-7.894896,0.7894896,0,0,0,0,0,2.867925,2.867925,7.894896,2.909854,-2.867925,766847.6
15.033,-2.884575,-8.00541,0.800541,0,0,0,0,0,2.884575,2.884575,8.00541,2.926997,-2.884575,777448.8
15.133,-2.902125,-8.149602,0.8149601,0,0,0,0,0,2.902125,2.902125,8.149602,2.94507,-2.902125,791309
15.233,-2.91735,-8.2798,0.82798,0,0,0,0,0,2.91735,2.91735,8.2798,2.960751,-2.91735,803825
15.333,-2.9352,-8.332513,0.8332514,0,0,0,0,0,2.9352,2.9352,8.332513,2.979139,-2.9352,808793.7
15.433,-2.9511,-8.518063,0.8518063,0,0,0,0,0,2.9511,2.9511,8.518063,2.995521,-2.9511,826668.6
15.533,-2.96805,-8.695789,0.8695788,0,0,0,0,0,2.96805,2.96805,8.695788,3.012988,-2.96805,843769.3
15.633,-2.984775,-8.852817,0.8852817,0,0,0,0,0,2.984775,2.984775,8.852818,3.030226,-2.984775,858858
15.733,-3.00165,-9.007484,0.9007484,0,0,0,0,0,3.00165,3.00165,9.007483,3.047622,-3.00165,873711.1
15.833,-3.01785,-9.042829,0.9042829,0,0,0,0,0,3.01785,3.01785,9.04283,3.064325,-3.01785,876993
15.933,-3.03495,-8.368336,0.8368336,0,0,0,0,0,3.03495,3.03495,8.368336,3.081958,-3.03495,811436.1
15.993,-3.04575,-8.334197,0.8334197,0,0,0,0,0,3.04575,3.04575,8.334197,3.093097,-3.04575,808035.8